Workbook
Name ChartCFADS: 决策看板!$E$121:INDEX(决策看板!$E$121:$E$151,核心参数输入!$B$9+1)
Name ChartCum: 决策看板!$G$121:INDEX(决策看板!$G$121:$G$151,核心参数输入!$B$9+1)
Name ChartDebt: 决策看板!$F$121:INDEX(决策看板!$F$121:$F$151,核心参数输入!$B$9+1)
Name ChartDiscounted: 决策看板!$H$121:INDEX(决策看板!$H$121:$H$151,核心参数输入!$B$9+1)
Name ChartOther: 决策看板!$D$121:INDEX(决策看板!$D$121:$D$151,核心参数输入!$B$9+1)
Name ChartRent: 决策看板!$C$121:INDEX(决策看板!$C$121:$C$151,核心参数输入!$B$9+1)
Name ChartSales: 决策看板!$B$121:INDEX(决策看板!$B$121:$B$151,核心参数输入!$B$9+1)
Name ChartYear: 决策看板!$A$121:INDEX(决策看板!$A$121:$A$151,核心参数输入!$B$9+1)

Sheet 使用说明
A2: 使用说明 · 模拟数据
A5: 模型用途 | B5: 拿地前的租售结合产业园学习测算。所有默认数据及投资阈值均为模拟值。年度模型覆盖第0年、第1—N年，最多30年；后续年末现金流，建设投资及运营作年度简化。
A9: 使用步骤 | B9: 1 在“核心参数输入”修改黄色单元格；2 同步调整建设和销售年度计划；3 在Excel中自动重算；4 查看“决策看板”的校验、指标及原因；5 在计算表核对各年变化。
A13: 工作表结构 | B13: 使用说明 → 核心参数输入 → 建筑面积与开发计划 → 投资与资金安排 → 销售与出租收入 → 运营成本与税费 → 融资与还本付息 → 利润与现金流 → 指标与情景测算 → 决策看板。
A17: 颜色与编辑 | B17: 浅黄色底蓝色文字＝手动输入；中性色＝公式及结果；绿色＝通过，红色＝未通过或待判断，灰色＝不适用。所有公式可查看编辑，无保护、宏和外部链接。
A21: 单位 | B21: 金额万元；面积平方米；地价、建安及售价元/平方米；租金元/平方米/月。面积×单价÷10000；年租金＝面积×月租金×12÷10000。百分比输入10%=0.10；出租率压力10个百分点输入10。
A25: 收益与资金条件 | B25: IRR越高越好，NPV≥0，回收期越短越好，DSCR越高越好。收益达标不代表资金充足：资本金总额度、资金缺口和到期本金也必须满足。NPV第0年不折现。
A29: 两类现金流 | B29: 项目投资现金流排除贷款、股东出资及全部本息、建设期融资费用，所得税按无融资利润；资本金现金流＝完整出资下留存后股东分配－按需股东投入。项目总投资另包含建设期融资费用。
A33: 状态说明 | B33: “无法计算”＝IRR无解或必要条件不足，不用0冒充；“测算期内未回收”＝对应累计现金流在期内没有由负转非负，视为未达标；“不适用”＝无贷款或未覆盖辅助稳定观察年等。必要收益指标无解时待判断。
A37: 建设与分摊 | B37: 土地第0年支付；其余非土地支出第1—K年按输入比例分配。建安、配套、前期、管理各范围不重叠；预备费以非土地上述成本为基数。共同开发成本按销售/持有经营面积比例分摊，非经营面积及地下成本一起分摊。
A41: 收入与免租 | B41: 销售部分出售前也不出租，出售后不再贡献租金；持有部分出租。年度销售占总可售面积比例，当年收款。出租年内面积视为全年占用，只对本年增加的出租面积扣一次免租，不模拟租户更替，故爬坡率不得下降。租金按收缴后现金口径确认收入，其他收入按实收租金比例。
A45: 税务与成本简化 | B45: 收入均为简化含税实收口径，销售及运营综合税费也按该口径；不建立增值税抵扣、土地增值税及复杂税制。所得税＝max(年度利润,0)×税率，不结转亏损。固定成本由持有部分承担，自K+1年即支付，空置不豁免；变动成本仅按持有收入；维护更新当年费用化并税前扣除，不重复资本化或折旧。
A49: 非现金成本 | B49: 销售成本按年度销售比例结转，未售保留存货；建设期间在建及存货按累计已支付成本显示。持有建筑非土地成本直线折旧，土地不折旧。融资利润将建设利息分摊至销售成本及持有折旧；项目口径剔除融资利息。建设成本只在支付年扣现金，结转与折旧不再次扣现金。
... A81: 生成与重算 | B81: 代码仅初始化默认示例；重新运行不读取或保留旧Excel中手改参数，同名文件自动加时间标识。Excel设置打开自动重算。可在Windows安装Excel后运行--recalculate；未实际重算的新文件有完整公式但缓存初始值不代表结果。验证详情见同目录“验证说明.md”。

Sheet 核心参数输入
A2: 核心参数输入 · 模拟数据
A5: 参数名称 | B5: 输入值 | C5: 单位 | D5: 说明
A6: 基础与建筑参数
A7: 项目名称 | B7: 模拟产业园 · 租售结合 | C7: 文本 | D7: 全部数据为虚构模拟数据
A8: 测算起始年份 | B8: 2026 | C8: 年 | D8: 第0年的日历年份；年度支出采用年末时点
A9: 测算期限 | B9: 20 | C9: 年 | D9: 实际范围第0年至第N年，预留至30年；须覆盖贷款到期
A10: 土地面积 | B10: 100000 | C10: 平方米 | D10: 地上面积＝土地面积×容积率
A11: 容积率 | B11: 1.5 | C11: 倍 | D11: 地上总建筑面积口径
A12: 地上可经营面积占比 | B12: 0.9 | C12: % | D12: 其余为公共及非经营空间；共同成本仍计入
A13: 地下建筑面积 | B13: 15000 | C13: 平方米 | D13: 地下空间不独立产生收入
A14: 可经营面积销售占比 | B14: 0.55 | C14: % | D14: 严格大于0且小于100%；销售部分出售前也不出租
A15: 出租占比（自动） | B15: =1-核心参数输入!$B$14 -> 0.45 | C15: % | D15: 自动＝1－销售占比
A16: 建设年限 | B16: 3 | C16: 年 | D16: 第1年至第K年；土地在第0年支付
A17: 销售开始年份 | B17: 4 | C17: 项目第几年 | D17: 必须晚于建设完成年；年度销售比例在下方输入
A18: 出租开始年份 | B18: 4 | C18: 项目第几年 | D18: 必须晚于建设完成年；运营固定成本从K+1年开始
A20: 投资参数
A21: 土地单价 | B21: 800 | C21: 元/平方米 | D21: 仅土地取得价款；不计入建筑折旧
A22: 地上单方建安成本 | B22: 2400 | C22: 元/平方米 | D22: 不含下列配套、前期、管理费用
A23: 地下单方建安成本 | B23: 3000 | C23: 元/平方米 | D23: 地下工程；不与地上重复
A24: 园区配套工程费用 | B24: 4500 | C24: 万元 | D24: 园区道路、管网、公共配套；不含建安主体
A25: 勘察设计咨询前期费用 | B25: 1800 | C25: 万元 | D25: 不含建安及管理费用
A26: 管理及其他建设费用 | B26: 2200 | C26: 万元 | D26: 建设管理等；不含融资利息和运营成本
A27: 预备费比例 | B27: 0.08 | C27: % | D27: 基数＝全部非土地建设费用（建安、配套、前期、管理）
A28: 初始运营周转资金 | B28: 500 | C28: 万元 | D28: K+1年投入，期末全额回收；不计入费用及折旧
A30: 销售参数
A31: 销售均价 | B31: 6500 | C31: 元/平方米 | D31: 简化含税成交/实收口径；销售当年全额收款
A32: 销售费用率 | B32: 0.025 | C32: % | D32: 销售回款×费用率
A33: 简化销售相关税费率 | B33: 0.08 | C33: % | D33: 含税回款×综合率；不另行建立增值税抵扣
A35: 出租参数
A36: 初始月租金 | B36: 26 | C36: 元/平方米/月 | D36: 出租首年价格；按12个月换算后除10000为万元
A37: 年租金增长率 | B37: 0.015 | C37: % | D37: 从出租开始年递增
A38: 出租第1年出租率 | B38: 0.5 | C38: % | D38: 全年占用面积比例；新增面积仅当年一次免租
A39: 出租第2年出租率 | B39: 0.7 | C39: % | D39: 前期爬坡参数集中输入
A40: 出租第3年出租率 | B40: 0.85 | C40: % | D40: 出租率须不下降；不模拟租户更替
A41: 第4年起稳定出租率 | B41: 0.9 | C41: % | D41: 稳定出租率直接驱动第4个出租年度以后
A42: 新增出租面积平均免租月数 | B42: 3 | C42: 月 | D42: 0—12月；同一面积不重复免租
A43: 租金收缴率 | B43: 0.98 | C43: % | D43: 实收租金，同时作为简化收入确认口径
A44: 其他经营收入比例 | B44: 0.05 | C44: % | D44: 实收租金×比例；属于持有经营收入
A46: 运营与税费参数
A47: 运营首年固定成本 | B47: 300 | C47: 万元/年 | D47: 仅持有部分：人员、管理、保险等；K+1年即承担
...

Sheet 建筑面积与开发计划
A2: 建筑面积与开发计划 · 模拟数据
A4: 项目年度 / 日历年份 | D4: =核心参数输入!D87 -> 0 | E4: =核心参数输入!E87 -> 1 | F4: =核心参数输入!F87 -> 2 | G4: =核心参数输入!G87 -> 3 | H4: =核心参数输入!H87 -> 4 | I4: =核心参数输入!I87 -> 5 | J4: =核心参数输入!J87 -> 6 | K4: =核心参数输入!K87 -> 7 | ... AH4: =核心参数输入!AH87 -> 30
D5: =核心参数输入!$B$8+D4 -> 2026 | E5: =核心参数输入!$B$8+E4 -> 2027 | F5: =核心参数输入!$B$8+F4 -> 2028 | G5: =核心参数输入!$B$8+G4 -> 2029 | H5: =核心参数输入!$B$8+H4 -> 2030 | I5: =核心参数输入!$B$8+I4 -> 2031 | J5: =核心参数输入!$B$8+J4 -> 2032 | K5: =核心参数输入!$B$8+K4 -> 2033 | ... AH5: =核心参数输入!$B$8+AH4 -> 2056
A6: 土地面积 | B6: =核心参数输入!$B$10 -> 100000 | C6: 平方米
A7: 地上建筑面积 | B7: =核心参数输入!$B$10*核心参数输入!$B$11 -> 150000 | C7: 平方米
A8: 地上可经营面积 | B8: =$B$7*核心参数输入!$B$12 -> 135000 | C8: 平方米
A9: 总可售面积 | B9: =$B$8*核心参数输入!$B$14 -> 74250 | C9: 平方米
A10: 总持有出租面积 | B10: =$B$8*核心参数输入!$B$15 -> 60750 | C10: 平方米
A11: 地下建筑面积 | B11: =核心参数输入!$B$13 -> 15000 | C11: 平方米
A18: 基准情景 · 年度开发与租售计划
A20: 建设分配比例 | B20: % | D20: =IF(D$4<=核心参数输入!$B$9,IF(AND(D$4>=1,D$4<=核心参数输入!$B$16),核心参数输入!D88,0),0) -> 0 | E20: =IF(E$4<=核心参数输入!$B$9,IF(AND(E$4>=1,E$4<=核心参数输入!$B$16),核心参数输入!E88,0),0) -> 0.3 | F20: =IF(F$4<=核心参数输入!$B$9,IF(AND(F$4>=1,F$4<=核心参数输入!$B$16),核心参数输入!F88,0),0) -> 0.4 | G20: =IF(G$4<=核心参数输入!$B$9,IF(AND(G$4>=1,G$4<=核心参数输入!$B$16),核心参数输入!G88,0),0) -> 0.3 | H20: =IF(H$4<=核心参数输入!$B$9,IF(AND(H$4>=1,H$4<=核心参数输入!$B$16),核心参数输入!H88,0),0) -> 0 | I20: =IF(I$4<=核心参数输入!$B$9,IF(AND(I$4>=1,I$4<=核心参数输入!$B$16),核心参数输入!I88,0),0) -> 0 | J20: =IF(J$4<=核心参数输入!$B$9,IF(AND(J$4>=1,J$4<=核心参数输入!$B$16),核心参数输入!J88,0),0) -> 0 | K20: =IF(K$4<=核心参数输入!$B$9,IF(AND(K$4>=1,K$4<=核心参数输入!$B$16),核心参数输入!K88,0),0) -> 0 | ... AH20: =IF(AH$4<=核心参数输入!$B$9,IF(AND(AH$4>=1,AH$4<=核心参数输入!$B$16),核心参数输入!AH88,0),0) -> 0
A21: 销售比例 | B21: % | D21: =IF(D$4<=核心参数输入!$B$9,IF(D$4>=核心参数输入!$B$17,核心参数输入!D89,0),0) -> 0 | E21: =IF(E$4<=核心参数输入!$B$9,IF(E$4>=核心参数输入!$B$17,核心参数输入!E89,0),0) -> 0 | F21: =IF(F$4<=核心参数输入!$B$9,IF(F$4>=核心参数输入!$B$17,核心参数输入!F89,0),0) -> 0 | G21: =IF(G$4<=核心参数输入!$B$9,IF(G$4>=核心参数输入!$B$17,核心参数输入!G89,0),0) -> 0 | H21: =IF(H$4<=核心参数输入!$B$9,IF(H$4>=核心参数输入!$B$17,核心参数输入!H89,0),0) -> 0.3 | I21: =IF(I$4<=核心参数输入!$B$9,IF(I$4>=核心参数输入!$B$17,核心参数输入!I89,0),0) -> 0.4 | J21: =IF(J$4<=核心参数输入!$B$9,IF(J$4>=核心参数输入!$B$17,核心参数输入!J89,0),0) -> 0.3 | K21: =IF(K$4<=核心参数输入!$B$9,IF(K$4>=核心参数输入!$B$17,核心参数输入!K89,0),0) -> 0 | ... AH21: =IF(AH$4<=核心参数输入!$B$9,IF(AH$4>=核心参数输入!$B$17,核心参数输入!AH89,0),0) -> 0
A22: 累计销售去化率 | B22: % | D22: =IF(D$4<=核心参数输入!$B$9,SUM($D21:D21),0) -> 0 | E22: =IF(E$4<=核心参数输入!$B$9,SUM($D21:E21),0) -> 0 | F22: =IF(F$4<=核心参数输入!$B$9,SUM($D21:F21),0) -> 0 | G22: =IF(G$4<=核心参数输入!$B$9,SUM($D21:G21),0) -> 0 | H22: =IF(H$4<=核心参数输入!$B$9,SUM($D21:H21),0) -> 0.3 | I22: =IF(I$4<=核心参数输入!$B$9,SUM($D21:I21),0) -> 0.7 | J22: =IF(J$4<=核心参数输入!$B$9,SUM($D21:J21),0) -> 1 | K22: =IF(K$4<=核心参数输入!$B$9,SUM($D21:K21),0) -> 1 | ... AH22: =IF(AH$4<=核心参数输入!$B$9,SUM($D21:AH21),0) -> 0
A23: 当年出售面积 | B23: 平方米 | D23: =IF(D$4<=核心参数输入!$B$9,D21*$B$9,0) -> 0 | E23: =IF(E$4<=核心参数输入!$B$9,E21*$B$9,0) -> 0 | F23: =IF(F$4<=核心参数输入!$B$9,F21*$B$9,0) -> 0 | G23: =IF(G$4<=核心参数输入!$B$9,G21*$B$9,0) -> 0 | H23: =IF(H$4<=核心参数输入!$B$9,H21*$B$9,0) -> 22275 | I23: =IF(I$4<=核心参数输入!$B$9,I21*$B$9,0) -> 29700 | J23: =IF(J$4<=核心参数输入!$B$9,J21*$B$9,0) -> 22275 | K23: =IF(K$4<=核心参数输入!$B$9,K21*$B$9,0) -> 0 | ... AH23: =IF(AH$4<=核心参数输入!$B$9,AH21*$B$9,0) -> 0
A24: 期末未售面积 | B24: 平方米 | D24: =IF(D$4<=核心参数输入!$B$9,$B$9*(1-D22),0) -> 74250 | E24: =IF(E$4<=核心参数输入!$B$9,$B$9*(1-E22),0) -> 74250 | F24: =IF(F$4<=核心参数输入!$B$9,$B$9*(1-F22),0) -> 74250 | G24: =IF(G$4<=核心参数输入!$B$9,$B$9*(1-G22),0) -> 74250 | H24: =IF(H$4<=核心参数输入!$B$9,$B$9*(1-H22),0) -> 51975 | I24: =IF(I$4<=核心参数输入!$B$9,$B$9*(1-I22),0) -> 22275 | J24: =IF(J$4<=核心参数输入!$B$9,$B$9*(1-J22),0) -> 0 | K24: =IF(K$4<=核心参数输入!$B$9,$B$9*(1-K22),0) -> 0 | ... AH24: =IF(AH$4<=核心参数输入!$B$9,$B$9*(1-AH22),0) -> 0
A25: 出租第几个年度 | B25: 年 | D25: =IF(D$4<=核心参数输入!$B$9,IF(D$4>=核心参数输入!$B$18,D$4-核心参数输入!$B$18+1,0),0) -> 0 | E25: =IF(E$4<=核心参数输入!$B$9,IF(E$4>=核心参数输入!$B$18,E$4-核心参数输入!$B$18+1,0),0) -> 0 | F25: =IF(F$4<=核心参数输入!$B$9,IF(F$4>=核心参数输入!$B$18,F$4-核心参数输入!$B$18+1,0),0) -> 0 | G25: =IF(G$4<=核心参数输入!$B$9,IF(G$4>=核心参数输入!$B$18,G$4-核心参数输入!$B$18+1,0),0) -> 0 | H25: =IF(H$4<=核心参数输入!$B$9,IF(H$4>=核心参数输入!$B$18,H$4-核心参数输入!$B$18+1,0),0) -> 1 | I25: =IF(I$4<=核心参数输入!$B$9,IF(I$4>=核心参数输入!$B$18,I$4-核心参数输入!$B$18+1,0),0) -> 2 | J25: =IF(J$4<=核心参数输入!$B$9,IF(J$4>=核心参数输入!$B$18,J$4-核心参数输入!$B$18+1,0),0) -> 3 | K25: =IF(K$4<=核心参数输入!$B$9,IF(K$4>=核心参数输入!$B$18,K$4-核心参数输入!$B$18+1,0),0) -> 4 | ... AH25: =IF(AH$4<=核心参数输入!$B$9,IF(AH$4>=核心参数输入!$B$18,AH$4-核心参数输入!$B$18+1,0),0) -> 0
A26: 实际出租率 | B26: % | D26: =IF(D$4<=核心参数输入!$B$9,IF(D25=0,0,MAX(0,IF(D25=1,核心参数输入!$B$38,IF(D25=2,核心参数输入!$B$39,IF(D25=3,核心参数输入!$B$40,核心参数输入!$B$41)))-0)),0) -> 0 | E26: =IF(E$4<=核心参数输入!$B$9,IF(E25=0,0,MAX(0,IF(E25=1,核心参数输入!$B$38,IF(E25=2,核心参数输入!$B$39,IF(E25=3,核心参数输入!$B$40,核心参数输入!$B$41)))-0)),0) -> 0 | F26: =IF(F$4<=核心参数输入!$B$9,IF(F25=0,0,MAX(0,IF(F25=1,核心参数输入!$B$38,IF(F25=2,核心参数输入!$B$39,IF(F25=3,核心参数输入!$B$40,核心参数输入!$B$41)))-0)),0) -> 0 | G26: =IF(G$4<=核心参数输入!$B$9,IF(G25=0,0,MAX(0,IF(G25=1,核心参数输入!$B$38,IF(G25=2,核心参数输入!$B$39,IF(G25=3,核心参数输入!$B$40,核心参数输入!$B$41)))-0)),0) -> 0 | H26: =IF(H$4<=核心参数输入!$B$9,IF(H25=0,0,MAX(0,IF(H25=1,核心参数输入!$B$38,IF(H25=2,核心参数输入!$B$39,IF(H25=3,核心参数输入!$B$40,核心参数输入!$B$41)))-0)),0) -> 0.5 | I26: =IF(I$4<=核心参数输入!$B$9,IF(I25=0,0,MAX(0,IF(I25=1,核心参数输入!$B$38,IF(I25=2,核心参数输入!$B$39,IF(I25=3,核心参数输入!$B$40,核心参数输入!$B$41)))-0)),0) -> 0.7 | J26: =IF(J$4<=核心参数输入!$B$9,IF(J25=0,0,MAX(0,IF(J25=1,核心参数输入!$B$38,IF(J25=2,核心参数输入!$B$39,IF(J25=3,核心参数输入!$B$40,核心参数输入!$B$41)))-0)),0) -> 0.85 | K26: =IF(K$4<=核心参数输入!$B$9,IF(K25=0,0,MAX(0,IF(K25=1,核心参数输入!$B$38,IF(K25=2,核心参数输入!$B$39,IF(K25=3,核心参数输入!$B$40,核心参数输入!$B$41)))-0)),0) -> 0.9 | ... AH26: =IF(AH$4<=核心参数输入!$B$9,IF(AH25=0,0,MAX(0,IF(AH25=1,核心参数输入!$B$38,IF(AH25=2,核心参数输入!$B$39,IF(AH25=3,核心参数输入!$B$40,核心参数输入!$B$41)))-0)),0) -> 0
A27: 已出租面积 | B27: 平方米 | D27: =IF(D$4<=核心参数输入!$B$9,$B$10*D26,0) -> 0 | E27: =IF(E$4<=核心参数输入!$B$9,$B$10*E26,0) -> 0 | F27: =IF(F$4<=核心参数输入!$B$9,$B$10*F26,0) -> 0 | G27: =IF(G$4<=核心参数输入!$B$9,$B$10*G26,0) -> 0 | H27: =IF(H$4<=核心参数输入!$B$9,$B$10*H26,0) -> 30375 | I27: =IF(I$4<=核心参数输入!$B$9,$B$10*I26,0) -> 42525 | J27: =IF(J$4<=核心参数输入!$B$9,$B$10*J26,0) -> 51637.5 | K27: =IF(K$4<=核心参数输入!$B$9,$B$10*K26,0) -> 54675 | ... AH27: =IF(AH$4<=核心参数输入!$B$9,$B$10*AH26,0) -> 0
A28: 新增出租面积 | B28: 平方米 | D28: =IF(D$4<=核心参数输入!$B$9,MAX(0,D27-0),0) -> 0 | E28: =IF(E$4<=核心参数输入!$B$9,MAX(0,E27-D27),0) -> 0 | F28: =IF(F$4<=核心参数输入!$B$9,MAX(0,F27-E27),0) -> 0 | G28: =IF(G$4<=核心参数输入!$B$9,MAX(0,G27-F27),0) -> 0 | H28: =IF(H$4<=核心参数输入!$B$9,MAX(0,H27-G27),0) -> 30375 | I28: =IF(I$4<=核心参数输入!$B$9,MAX(0,I27-H27),0) -> 12150 | J28: =IF(J$4<=核心参数输入!$B$9,MAX(0,J27-I27),0) -> 9112.5 | K28: =IF(K$4<=核心参数输入!$B$9,MAX(0,K27-J27),0) -> 3037.5 | L28: =IF(L$4<=核心参数输入!$B$9,MAX(0,L27-K27),0) -> 0 | ... AH28: =IF(AH$4<=核心参数输入!$B$9,MAX(0,AH27-AG27),0) -> 0
A29: 累计销售完成标记 | B29: 0/1 | D29: =IF(D$4<=核心参数输入!$B$9,IF(D22>=0.999999,1,0),0) -> 0 | E29: =IF(E$4<=核心参数输入!$B$9,IF(E22>=0.999999,1,0),0) -> 0 | F29: =IF(F$4<=核心参数输入!$B$9,IF(F22>=0.999999,1,0),0) -> 0 | G29: =IF(G$4<=核心参数输入!$B$9,IF(G22>=0.999999,1,0),0) -> 0 | H29: =IF(H$4<=核心参数输入!$B$9,IF(H22>=0.999999,1,0),0) -> 0 | I29: =IF(I$4<=核心参数输入!$B$9,IF(I22>=0.999999,1,0),0) -> 0 | J29: =IF(J$4<=核心参数输入!$B$9,IF(J22>=0.999999,1,0),0) -> 1 | K29: =IF(K$4<=核心参数输入!$B$9,IF(K22>=0.999999,1,0),0) -> 1 | ... AH29: =IF(AH$4<=核心参数输入!$B$9,IF(AH22>=0.999999,1,0),0) -> 0
A98: 组合压力情景 · 年度开发与租售计划（共用面积及销售比例）
A100: 建设分配比例 | B100: % | D100: =IF(D$4<=核心参数输入!$B$9,IF(AND(D$4>=1,D$4<=核心参数输入!$B$16),核心参数输入!D88,0),0) -> 0 | E100: =IF(E$4<=核心参数输入!$B$9,IF(AND(E$4>=1,E$4<=核心参数输入!$B$16),核心参数输入!E88,0),0) -> 0.3 | F100: =IF(F$4<=核心参数输入!$B$9,IF(AND(F$4>=1,F$4<=核心参数输入!$B$16),核心参数输入!F88,0),0) -> 0.4 | G100: =IF(G$4<=核心参数输入!$B$9,IF(AND(G$4>=1,G$4<=核心参数输入!$B$16),核心参数输入!G88,0),0) -> 0.3 | H100: =IF(H$4<=核心参数输入!$B$9,IF(AND(H$4>=1,H$4<=核心参数输入!$B$16),核心参数输入!H88,0),0) -> 0 | I100: =IF(I$4<=核心参数输入!$B$9,IF(AND(I$4>=1,I$4<=核心参数输入!$B$16),核心参数输入!I88,0),0) -> 0 | J100: =IF(J$4<=核心参数输入!$B$9,IF(AND(J$4>=1,J$4<=核心参数输入!$B$16),核心参数输入!J88,0),0) -> 0 | K100: =IF(K$4<=核心参数输入!$B$9,IF(AND(K$4>=1,K$4<=核心参数输入!$B$16),核心参数输入!K88,0),0) -> 0 | ... AH100: =IF(AH$4<=核心参数输入!$B$9,IF(AND(AH$4>=1,AH$4<=核心参数输入!$B$16),核心参数输入!AH88,0),0) -> 0
A101: 销售比例 | B101: % | D101: =IF(D$4<=核心参数输入!$B$9,IF(D$4>=核心参数输入!$B$17,核心参数输入!D89,0),0) -> 0 | E101: =IF(E$4<=核心参数输入!$B$9,IF(E$4>=核心参数输入!$B$17,核心参数输入!E89,0),0) -> 0 | F101: =IF(F$4<=核心参数输入!$B$9,IF(F$4>=核心参数输入!$B$17,核心参数输入!F89,0),0) -> 0 | G101: =IF(G$4<=核心参数输入!$B$9,IF(G$4>=核心参数输入!$B$17,核心参数输入!G89,0),0) -> 0 | H101: =IF(H$4<=核心参数输入!$B$9,IF(H$4>=核心参数输入!$B$17,核心参数输入!H89,0),0) -> 0.3 | I101: =IF(I$4<=核心参数输入!$B$9,IF(I$4>=核心参数输入!$B$17,核心参数输入!I89,0),0) -> 0.4 | J101: =IF(J$4<=核心参数输入!$B$9,IF(J$4>=核心参数输入!$B$17,核心参数输入!J89,0),0) -> 0.3 | K101: =IF(K$4<=核心参数输入!$B$9,IF(K$4>=核心参数输入!$B$17,核心参数输入!K89,0),0) -> 0 | ... AH101: =IF(AH$4<=核心参数输入!$B$9,IF(AH$4>=核心参数输入!$B$17,核心参数输入!AH89,0),0) -> 0
A102: 累计销售去化率 | B102: % | D102: =IF(D$4<=核心参数输入!$B$9,SUM($D101:D101),0) -> 0 | E102: =IF(E$4<=核心参数输入!$B$9,SUM($D101:E101),0) -> 0 | F102: =IF(F$4<=核心参数输入!$B$9,SUM($D101:F101),0) -> 0 | G102: =IF(G$4<=核心参数输入!$B$9,SUM($D101:G101),0) -> 0 | H102: =IF(H$4<=核心参数输入!$B$9,SUM($D101:H101),0) -> 0.3 | I102: =IF(I$4<=核心参数输入!$B$9,SUM($D101:I101),0) -> 0.7 | J102: =IF(J$4<=核心参数输入!$B$9,SUM($D101:J101),0) -> 1 | K102: =IF(K$4<=核心参数输入!$B$9,SUM($D101:K101),0) -> 1 | ... AH102: =IF(AH$4<=核心参数输入!$B$9,SUM($D101:AH101),0) -> 0
A103: 当年出售面积 | B103: 平方米 | D103: =IF(D$4<=核心参数输入!$B$9,D101*$B$9,0) -> 0 | E103: =IF(E$4<=核心参数输入!$B$9,E101*$B$9,0) -> 0 | F103: =IF(F$4<=核心参数输入!$B$9,F101*$B$9,0) -> 0 | G103: =IF(G$4<=核心参数输入!$B$9,G101*$B$9,0) -> 0 | H103: =IF(H$4<=核心参数输入!$B$9,H101*$B$9,0) -> 22275 | I103: =IF(I$4<=核心参数输入!$B$9,I101*$B$9,0) -> 29700 | J103: =IF(J$4<=核心参数输入!$B$9,J101*$B$9,0) -> 22275 | K103: =IF(K$4<=核心参数输入!$B$9,K101*$B$9,0) -> 0 | ... AH103: =IF(AH$4<=核心参数输入!$B$9,AH101*$B$9,0) -> 0
A104: 期末未售面积 | B104: 平方米 | D104: =IF(D$4<=核心参数输入!$B$9,$B$9*(1-D102),0) -> 74250 | E104: =IF(E$4<=核心参数输入!$B$9,$B$9*(1-E102),0) -> 74250 | F104: =IF(F$4<=核心参数输入!$B$9,$B$9*(1-F102),0) -> 74250 | G104: =IF(G$4<=核心参数输入!$B$9,$B$9*(1-G102),0) -> 74250 | H104: =IF(H$4<=核心参数输入!$B$9,$B$9*(1-H102),0) -> 51975 | I104: =IF(I$4<=核心参数输入!$B$9,$B$9*(1-I102),0) -> 22275 | J104: =IF(J$4<=核心参数输入!$B$9,$B$9*(1-J102),0) -> 0 | K104: =IF(K$4<=核心参数输入!$B$9,$B$9*(1-K102),0) -> 0 | ... AH104: =IF(AH$4<=核心参数输入!$B$9,$B$9*(1-AH102),0) -> 0
A105: 出租第几个年度 | B105: 年 | D105: =IF(D$4<=核心参数输入!$B$9,IF(D$4>=核心参数输入!$B$18,D$4-核心参数输入!$B$18+1,0),0) -> 0 | E105: =IF(E$4<=核心参数输入!$B$9,IF(E$4>=核心参数输入!$B$18,E$4-核心参数输入!$B$18+1,0),0) -> 0 | F105: =IF(F$4<=核心参数输入!$B$9,IF(F$4>=核心参数输入!$B$18,F$4-核心参数输入!$B$18+1,0),0) -> 0 | G105: =IF(G$4<=核心参数输入!$B$9,IF(G$4>=核心参数输入!$B$18,G$4-核心参数输入!$B$18+1,0),0) -> 0 | H105: =IF(H$4<=核心参数输入!$B$9,IF(H$4>=核心参数输入!$B$18,H$4-核心参数输入!$B$18+1,0),0) -> 1 | I105: =IF(I$4<=核心参数输入!$B$9,IF(I$4>=核心参数输入!$B$18,I$4-核心参数输入!$B$18+1,0),0) -> 2 | J105: =IF(J$4<=核心参数输入!$B$9,IF(J$4>=核心参数输入!$B$18,J$4-核心参数输入!$B$18+1,0),0) -> 3 | K105: =IF(K$4<=核心参数输入!$B$9,IF(K$4>=核心参数输入!$B$18,K$4-核心参数输入!$B$18+1,0),0) -> 4 | ... AH105: =IF(AH$4<=核心参数输入!$B$9,IF(AH$4>=核心参数输入!$B$18,AH$4-核心参数输入!$B$18+1,0),0) -> 0
A106: 实际出租率 | B106: % | D106: =IF(D$4<=核心参数输入!$B$9,IF(D105=0,0,MAX(0,IF(D105=1,核心参数输入!$B$38,IF(D105=2,核心参数输入!$B$39,IF(D105=3,核心参数输入!$B$40,核心参数输入!$B$41)))-核心参数输入!$B$80/100)),0) -> 0 | E106: =IF(E$4<=核心参数输入!$B$9,IF(E105=0,0,MAX(0,IF(E105=1,核心参数输入!$B$38,IF(E105=2,核心参数输入!$B$39,IF(E105=3,核心参数输入!$B$40,核心参数输入!$B$41)))-核心参数输入!$B$80/100)),0) -> 0 | F106: =IF(F$4<=核心参数输入!$B$9,IF(F105=0,0,MAX(0,IF(F105=1,核心参数输入!$B$38,IF(F105=2,核心参数输入!$B$39,IF(F105=3,核心参数输入!$B$40,核心参数输入!$B$41)))-核心参数输入!$B$80/100)),0) -> 0 | G106: =IF(G$4<=核心参数输入!$B$9,IF(G105=0,0,MAX(0,IF(G105=1,核心参数输入!$B$38,IF(G105=2,核心参数输入!$B$39,IF(G105=3,核心参数输入!$B$40,核心参数输入!$B$41)))-核心参数输入!$B$80/100)),0) -> 0 | H106: =IF(H$4<=核心参数输入!$B$9,IF(H105=0,0,MAX(0,IF(H105=1,核心参数输入!$B$38,IF(H105=2,核心参数输入!$B$39,IF(H105=3,核心参数输入!$B$40,核心参数输入!$B$41)))-核心参数输入!$B$80/100)),0) -> 0.4 | I106: =IF(I$4<=核心参数输入!$B$9,IF(I105=0,0,MAX(0,IF(I105=1,核心参数输入!$B$38,IF(I105=2,核心参数输入!$B$39,IF(I105=3,核心参数输入!$B$40,核心参数输入!$B$41)))-核心参数输入!$B$80/100)),0) -> 0.6 | J106: =IF(J$4<=核心参数输入!$B$9,IF(J105=0,0,MAX(0,IF(J105=1,核心参数输入!$B$38,IF(J105=2,核心参数输入!$B$39,IF(J105=3,核心参数输入!$B$40,核心参数输入!$B$41)))-核心参数输入!$B$80/100)),0) -> 0.75 | K106: =IF(K$4<=核心参数输入!$B$9,IF(K105=0,0,MAX(0,IF(K105=1,核心参数输入!$B$38,IF(K105=2,核心参数输入!$B$39,IF(K105=3,核心参数输入!$B$40,核心参数输入!$B$41)))-核心参数输入!$B$80/100)),0) -> 0.8 | ... AH106: =IF(AH$4<=核心参数输入!$B$9,IF(AH105=0,0,MAX(0,IF(AH105=1,核心参数输入!$B$38,IF(AH105=2,核心参数输入!$B$39,IF(AH105=3,核心参数输入!$B$40,核心参数输入!$B$41)))-核心参数输入!$B$80/100)),0) -> 0
A107: 已出租面积 | B107: 平方米 | D107: =IF(D$4<=核心参数输入!$B$9,$B$10*D106,0) -> 0 | E107: =IF(E$4<=核心参数输入!$B$9,$B$10*E106,0) -> 0 | F107: =IF(F$4<=核心参数输入!$B$9,$B$10*F106,0) -> 0 | G107: =IF(G$4<=核心参数输入!$B$9,$B$10*G106,0) -> 0 | H107: =IF(H$4<=核心参数输入!$B$9,$B$10*H106,0) -> 24300 | I107: =IF(I$4<=核心参数输入!$B$9,$B$10*I106,0) -> 36450 | J107: =IF(J$4<=核心参数输入!$B$9,$B$10*J106,0) -> 45562.5 | K107: =IF(K$4<=核心参数输入!$B$9,$B$10*K106,0) -> 48600 | ... AH107: =IF(AH$4<=核心参数输入!$B$9,$B$10*AH106,0) -> 0
A108: 新增出租面积 | B108: 平方米 | D108: =IF(D$4<=核心参数输入!$B$9,MAX(0,D107-0),0) -> 0 | E108: =IF(E$4<=核心参数输入!$B$9,MAX(0,E107-D107),0) -> 0 | F108: =IF(F$4<=核心参数输入!$B$9,MAX(0,F107-E107),0) -> 0 | G108: =IF(G$4<=核心参数输入!$B$9,MAX(0,G107-F107),0) -> 0 | H108: =IF(H$4<=核心参数输入!$B$9,MAX(0,H107-G107),0) -> 24300 | I108: =IF(I$4<=核心参数输入!$B$9,MAX(0,I107-H107),0) -> 12150 | J108: =IF(J$4<=核心参数输入!$B$9,MAX(0,J107-I107),0) -> 9112.5 | K108: =IF(K$4<=核心参数输入!$B$9,MAX(0,K107-J107),0) -> 3037.5 | L108: =IF(L$4<=核心参数输入!$B$9,MAX(0,L107-K107),0) -> 0 | ... AH108: =IF(AH$4<=核心参数输入!$B$9,MAX(0,AH107-AG107),0) -> 0
A109: 累计销售完成标记 | B109: 0/1 | D109: =IF(D$4<=核心参数输入!$B$9,IF(D102>=0.999999,1,0),0) -> 0 | E109: =IF(E$4<=核心参数输入!$B$9,IF(E102>=0.999999,1,0),0) -> 0 | F109: =IF(F$4<=核心参数输入!$B$9,IF(F102>=0.999999,1,0),0) -> 0 | G109: =IF(G$4<=核心参数输入!$B$9,IF(G102>=0.999999,1,0),0) -> 0 | H109: =IF(H$4<=核心参数输入!$B$9,IF(H102>=0.999999,1,0),0) -> 0 | I109: =IF(I$4<=核心参数输入!$B$9,IF(I102>=0.999999,1,0),0) -> 0 | J109: =IF(J$4<=核心参数输入!$B$9,IF(J102>=0.999999,1,0),0) -> 1 | K109: =IF(K$4<=核心参数输入!$B$9,IF(K102>=0.999999,1,0),0) -> 1 | ... AH109: =IF(AH$4<=核心参数输入!$B$9,IF(AH102>=0.999999,1,0),0) -> 0

Sheet 投资与资金安排
A2: 投资与资金安排 · 模拟数据
A3: 基准情景
A4: 项目年度 / 日历年份 | D4: =核心参数输入!D87 -> 0 | E4: =核心参数输入!E87 -> 1 | F4: =核心参数输入!F87 -> 2 | G4: =核心参数输入!G87 -> 3 | H4: =核心参数输入!H87 -> 4 | I4: =核心参数输入!I87 -> 5 | J4: =核心参数输入!J87 -> 6 | K4: =核心参数输入!K87 -> 7 | ... AH4: =核心参数输入!AH87 -> 30
D5: =核心参数输入!$B$8+D4 -> 2026 | E5: =核心参数输入!$B$8+E4 -> 2027 | F5: =核心参数输入!$B$8+F4 -> 2028 | G5: =核心参数输入!$B$8+G4 -> 2029 | H5: =核心参数输入!$B$8+H4 -> 2030 | I5: =核心参数输入!$B$8+I4 -> 2031 | J5: =核心参数输入!$B$8+J4 -> 2032 | K5: =核心参数输入!$B$8+K4 -> 2033 | ... AH5: =核心参数输入!$B$8+AH4 -> 2056
A6: 土地取得费用 | B6: =核心参数输入!$B$10*核心参数输入!$B$21/10000 -> 8000 | C6: 万元
A7: 地上建安费用 | B7: =建筑面积与开发计划!$B$7*核心参数输入!$B$22/10000*1 -> 36000 | C7: 万元
A8: 地下建安费用 | B8: =核心参数输入!$B$13*核心参数输入!$B$23/10000*1 -> 4500 | C8: 万元
A9: 配套工程费用 | B9: =核心参数输入!$B$24*1 -> 4500 | C9: 万元
A10: 前期费用 | B10: =核心参数输入!$B$25*1 -> 1800 | C10: 万元
A11: 管理及其他建设费用 | B11: =核心参数输入!$B$26*1 -> 2200 | C11: 万元
A12: 非土地建设费用小计 | B12: =SUM(B7:B11) -> 49000 | C12: 万元
A13: 预备费 | B13: =B12*核心参数输入!$B$27 -> 3920 | C13: 万元
A14: 非土地建设费用含预备费 | B14: =SUM(B12:B13) -> 52920 | C14: 万元
A15: 建设期融资费用（资本金支付） | B15: =SUM(融资与还本付息!$D$16:$AH$16) -> 1890 | C15: 万元
A16: 开发总成本含融资费用 | B16: =B6+B14+B15 -> 62810 | C16: 万元
A17: 初始运营周转资金 | B17: =核心参数输入!$B$28 -> 500 | C17: 万元
A18: 项目总投资含建设期融资费用 | B18: =SUM(B16:B17) -> 63310 | C18: 万元
A19: 销售成本基数（项目口径） | B19: =(B6+B14)*核心参数输入!$B$14 -> 33506 | C19: 万元
A20: 持有折旧基数（项目口径） | B20: =B14*核心参数输入!$B$15 -> 23814 | C20: 万元
A21: 持有分摊土地成本 | B21: =B6*核心参数输入!$B$15 -> 3600 | C21: 万元
A22: 销售成本基数（融资口径） | B22: =B16*核心参数输入!$B$14 -> 34545.5 | C22: 万元
A23: 持有折旧基数（融资口径） | B23: =(B14+B15)*核心参数输入!$B$15 -> 24664.5 | C23: 万元
A24: 持有分摊总投资含周转资金 | B24: =B16*核心参数输入!$B$15+B17 -> 28764.5 | C24: 万元
A26: 年度现金支出（成本结转与折旧不在此再次支付）
A28: 土地款 | B28: 万元 | D28: =IF(D$4<=核心参数输入!$B$9,IF(D$4=0,$B$6,0),0) -> 8000 | E28: =IF(E$4<=核心参数输入!$B$9,IF(E$4=0,$B$6,0),0) -> 0 | F28: =IF(F$4<=核心参数输入!$B$9,IF(F$4=0,$B$6,0),0) -> 0 | G28: =IF(G$4<=核心参数输入!$B$9,IF(G$4=0,$B$6,0),0) -> 0 | H28: =IF(H$4<=核心参数输入!$B$9,IF(H$4=0,$B$6,0),0) -> 0 | I28: =IF(I$4<=核心参数输入!$B$9,IF(I$4=0,$B$6,0),0) -> 0 | J28: =IF(J$4<=核心参数输入!$B$9,IF(J$4=0,$B$6,0),0) -> 0 | K28: =IF(K$4<=核心参数输入!$B$9,IF(K$4=0,$B$6,0),0) -> 0 | ... AH28: =IF(AH$4<=核心参数输入!$B$9,IF(AH$4=0,$B$6,0),0) -> 0
A29: 非土地建设现金支出 | B29: 万元 | D29: =IF(D$4<=核心参数输入!$B$9,$B$14*建筑面积与开发计划!D20,0) -> 0 | E29: =IF(E$4<=核心参数输入!$B$9,$B$14*建筑面积与开发计划!E20,0) -> 15876 | F29: =IF(F$4<=核心参数输入!$B$9,$B$14*建筑面积与开发计划!F20,0) -> 21168 | G29: =IF(G$4<=核心参数输入!$B$9,$B$14*建筑面积与开发计划!G20,0) -> 15876 | H29: =IF(H$4<=核心参数输入!$B$9,$B$14*建筑面积与开发计划!H20,0) -> 0 | I29: =IF(I$4<=核心参数输入!$B$9,$B$14*建筑面积与开发计划!I20,0) -> 0 | J29: =IF(J$4<=核心参数输入!$B$9,$B$14*建筑面积与开发计划!J20,0) -> 0 | K29: =IF(K$4<=核心参数输入!$B$9,$B$14*建筑面积与开发计划!K20,0) -> 0 | ... AH29: =IF(AH$4<=核心参数输入!$B$9,$B$14*建筑面积与开发计划!AH20,0) -> 0
A30: 年度建设支出合计 | B30: 万元 | D30: =IF(D$4<=核心参数输入!$B$9,SUM(D28:D29),0) -> 8000 | E30: =IF(E$4<=核心参数输入!$B$9,SUM(E28:E29),0) -> 15876 | F30: =IF(F$4<=核心参数输入!$B$9,SUM(F28:F29),0) -> 21168 | G30: =IF(G$4<=核心参数输入!$B$9,SUM(G28:G29),0) -> 15876 | H30: =IF(H$4<=核心参数输入!$B$9,SUM(H28:H29),0) -> 0 | I30: =IF(I$4<=核心参数输入!$B$9,SUM(I28:I29),0) -> 0 | J30: =IF(J$4<=核心参数输入!$B$9,SUM(J28:J29),0) -> 0 | K30: =IF(K$4<=核心参数输入!$B$9,SUM(K28:K29),0) -> 0 | ... AH30: =IF(AH$4<=核心参数输入!$B$9,SUM(AH28:AH29),0) -> 0
A31: 运营周转资金投入 | B31: 万元 | D31: =IF(D$4<=核心参数输入!$B$9,IF(D$4=核心参数输入!$B$16+1,核心参数输入!$B$28,0),0) -> 0 | E31: =IF(E$4<=核心参数输入!$B$9,IF(E$4=核心参数输入!$B$16+1,核心参数输入!$B$28,0),0) -> 0 | F31: =IF(F$4<=核心参数输入!$B$9,IF(F$4=核心参数输入!$B$16+1,核心参数输入!$B$28,0),0) -> 0 | G31: =IF(G$4<=核心参数输入!$B$9,IF(G$4=核心参数输入!$B$16+1,核心参数输入!$B$28,0),0) -> 0 | H31: =IF(H$4<=核心参数输入!$B$9,IF(H$4=核心参数输入!$B$16+1,核心参数输入!$B$28,0),0) -> 500 | I31: =IF(I$4<=核心参数输入!$B$9,IF(I$4=核心参数输入!$B$16+1,核心参数输入!$B$28,0),0) -> 0 | J31: =IF(J$4<=核心参数输入!$B$9,IF(J$4=核心参数输入!$B$16+1,核心参数输入!$B$28,0),0) -> 0 | K31: =IF(K$4<=核心参数输入!$B$9,IF(K$4=核心参数输入!$B$16+1,核心参数输入!$B$28,0),0) -> 0 | ... AH31: =IF(AH$4<=核心参数输入!$B$9,IF(AH$4=核心参数输入!$B$16+1,核心参数输入!$B$28,0),0) -> 0
A32: 运营周转资金收回 | B32: 万元 | D32: =IF(D$4<=核心参数输入!$B$9,IF(AND(D$4=核心参数输入!$B$9,核心参数输入!$B$9>核心参数输入!$B$16),核心参数输入!$B$28,0),0) -> 0 | E32: =IF(E$4<=核心参数输入!$B$9,IF(AND(E$4=核心参数输入!$B$9,核心参数输入!$B$9>核心参数输入!$B$16),核心参数输入!$B$28,0),0) -> 0 | F32: =IF(F$4<=核心参数输入!$B$9,IF(AND(F$4=核心参数输入!$B$9,核心参数输入!$B$9>核心参数输入!$B$16),核心参数输入!$B$28,0),0) -> 0 | G32: =IF(G$4<=核心参数输入!$B$9,IF(AND(G$4=核心参数输入!$B$9,核心参数输入!$B$9>核心参数输入!$B$16),核心参数输入!$B$28,0),0) -> 0 | H32: =IF(H$4<=核心参数输入!$B$9,IF(AND(H$4=核心参数输入!$B$9,核心参数输入!$B$9>核心参数输入!$B$16),核心参数输入!$B$28,0),0) -> 0 | I32: =IF(I$4<=核心参数输入!$B$9,IF(AND(I$4=核心参数输入!$B$9,核心参数输入!$B$9>核心参数输入!$B$16),核心参数输入!$B$28,0),0) -> 0 | J32: =IF(J$4<=核心参数输入!$B$9,IF(AND(J$4=核心参数输入!$B$9,核心参数输入!$B$9>核心参数输入!$B$16),核心参数输入!$B$28,0),0) -> 0 | K32: =IF(K$4<=核心参数输入!$B$9,IF(AND(K$4=核心参数输入!$B$9,核心参数输入!$B$9>核心参数输入!$B$16),核心参数输入!$B$28,0),0) -> 0 | ... AH32: =IF(AH$4<=核心参数输入!$B$9,IF(AND(AH$4=核心参数输入!$B$9,核心参数输入!$B$9>核心参数输入!$B$16),核心参数输入!$B$28,0),0) -> 0
A33: 项目口径年度投资支出 | B33: 万元 | D33: =IF(D$4<=核心参数输入!$B$9,D30+D31,0) -> 8000 | E33: =IF(E$4<=核心参数输入!$B$9,E30+E31,0) -> 15876 | F33: =IF(F$4<=核心参数输入!$B$9,F30+F31,0) -> 21168 | G33: =IF(G$4<=核心参数输入!$B$9,G30+G31,0) -> 15876 | H33: =IF(H$4<=核心参数输入!$B$9,H30+H31,0) -> 500 | I33: =IF(I$4<=核心参数输入!$B$9,I30+I31,0) -> 0 | J33: =IF(J$4<=核心参数输入!$B$9,J30+J31,0) -> 0 | K33: =IF(K$4<=核心参数输入!$B$9,K30+K31,0) -> 0 | ... AH33: =IF(AH$4<=核心参数输入!$B$9,AH30+AH31,0) -> 0
A34: 建设期利息现金支付 | B34: 万元 | D34: =IF(D$4<=核心参数输入!$B$9,融资与还本付息!D16,0) -> 0 | E34: =IF(E$4<=核心参数输入!$B$9,融资与还本付息!E16,0) -> 189 | F34: =IF(F$4<=核心参数输入!$B$9,融资与还本付息!F16,0) -> 630 | G34: =IF(G$4<=核心参数输入!$B$9,融资与还本付息!G16,0) -> 1071 | H34: =IF(H$4<=核心参数输入!$B$9,融资与还本付息!H16,0) -> 0 | I34: =IF(I$4<=核心参数输入!$B$9,融资与还本付息!I16,0) -> 0 | J34: =IF(J$4<=核心参数输入!$B$9,融资与还本付息!J16,0) -> 0 | K34: =IF(K$4<=核心参数输入!$B$9,融资与还本付息!K16,0) -> 0 | ... AH34: =IF(AH$4<=核心参数输入!$B$9,融资与还本付息!AH16,0) -> 0
A35: 含融资费用年度投资支出 | B35: 万元 | D35: =IF(D$4<=核心参数输入!$B$9,D33+D34,0) -> 8000 | E35: =IF(E$4<=核心参数输入!$B$9,E33+E34,0) -> 16065 | F35: =IF(F$4<=核心参数输入!$B$9,F33+F34,0) -> 21798 | G35: =IF(G$4<=核心参数输入!$B$9,G33+G34,0) -> 16947 | H35: =IF(H$4<=核心参数输入!$B$9,H33+H34,0) -> 500 | I35: =IF(I$4<=核心参数输入!$B$9,I33+I34,0) -> 0 | J35: =IF(J$4<=核心参数输入!$B$9,J33+J34,0) -> 0 | K35: =IF(K$4<=核心参数输入!$B$9,K33+K34,0) -> 0 | ... AH35: =IF(AH$4<=核心参数输入!$B$9,AH33+AH34,0) -> 0
A83: 组合压力情景
A86: 土地取得费用 | B86: =核心参数输入!$B$10*核心参数输入!$B$21/10000 -> 8000 | C86: 万元
A87: 地上建安费用 | B87: =建筑面积与开发计划!$B$7*核心参数输入!$B$22/10000*(1+核心参数输入!$B$81) -> 39600 | C87: 万元
A88: 地下建安费用 | B88: =核心参数输入!$B$13*核心参数输入!$B$23/10000*(1+核心参数输入!$B$81) -> 4950 | C88: 万元
A89: 配套工程费用 | B89: =核心参数输入!$B$24*(1+核心参数输入!$B$81) -> 4950 | C89: 万元
A90: 前期费用 | B90: =核心参数输入!$B$25*(1+核心参数输入!$B$81) -> 1980 | C90: 万元
A91: 管理及其他建设费用 | B91: =核心参数输入!$B$26*(1+核心参数输入!$B$81) -> 2420 | C91: 万元
A92: 非土地建设费用小计 | B92: =SUM(B87:B91) -> 53900 | C92: 万元
...

Sheet 销售与出租收入
A2: 销售与出租收入 · 模拟数据
A4: 项目年度 / 日历年份 | D4: =核心参数输入!D87 -> 0 | E4: =核心参数输入!E87 -> 1 | F4: =核心参数输入!F87 -> 2 | G4: =核心参数输入!G87 -> 3 | H4: =核心参数输入!H87 -> 4 | I4: =核心参数输入!I87 -> 5 | J4: =核心参数输入!J87 -> 6 | K4: =核心参数输入!K87 -> 7 | ... AH4: =核心参数输入!AH87 -> 30
D5: =核心参数输入!$B$8+D4 -> 2026 | E5: =核心参数输入!$B$8+E4 -> 2027 | F5: =核心参数输入!$B$8+F4 -> 2028 | G5: =核心参数输入!$B$8+G4 -> 2029 | H5: =核心参数输入!$B$8+H4 -> 2030 | I5: =核心参数输入!$B$8+I4 -> 2031 | J5: =核心参数输入!$B$8+J4 -> 2032 | K5: =核心参数输入!$B$8+K4 -> 2033 | ... AH5: =核心参数输入!$B$8+AH4 -> 2056
A7: 基准情景 · 销售与持有分别核算
A10: 年度销售比例 | B10: % | D10: =IF(D$4<=核心参数输入!$B$9,建筑面积与开发计划!D21,0) -> 0 | E10: =IF(E$4<=核心参数输入!$B$9,建筑面积与开发计划!E21,0) -> 0 | F10: =IF(F$4<=核心参数输入!$B$9,建筑面积与开发计划!F21,0) -> 0 | G10: =IF(G$4<=核心参数输入!$B$9,建筑面积与开发计划!G21,0) -> 0 | H10: =IF(H$4<=核心参数输入!$B$9,建筑面积与开发计划!H21,0) -> 0.3 | I10: =IF(I$4<=核心参数输入!$B$9,建筑面积与开发计划!I21,0) -> 0.4 | J10: =IF(J$4<=核心参数输入!$B$9,建筑面积与开发计划!J21,0) -> 0.3 | K10: =IF(K$4<=核心参数输入!$B$9,建筑面积与开发计划!K21,0) -> 0 | ... AH10: =IF(AH$4<=核心参数输入!$B$9,建筑面积与开发计划!AH21,0) -> 0
A11: 当年销售面积 | B11: 平方米 | D11: =IF(D$4<=核心参数输入!$B$9,建筑面积与开发计划!D23,0) -> 0 | E11: =IF(E$4<=核心参数输入!$B$9,建筑面积与开发计划!E23,0) -> 0 | F11: =IF(F$4<=核心参数输入!$B$9,建筑面积与开发计划!F23,0) -> 0 | G11: =IF(G$4<=核心参数输入!$B$9,建筑面积与开发计划!G23,0) -> 0 | H11: =IF(H$4<=核心参数输入!$B$9,建筑面积与开发计划!H23,0) -> 22275 | I11: =IF(I$4<=核心参数输入!$B$9,建筑面积与开发计划!I23,0) -> 29700 | J11: =IF(J$4<=核心参数输入!$B$9,建筑面积与开发计划!J23,0) -> 22275 | K11: =IF(K$4<=核心参数输入!$B$9,建筑面积与开发计划!K23,0) -> 0 | ... AH11: =IF(AH$4<=核心参数输入!$B$9,建筑面积与开发计划!AH23,0) -> 0
A12: 销售价格 | B12: 元/平方米 | D12: =IF(D$4<=核心参数输入!$B$9,核心参数输入!$B$31,0) -> 6500 | E12: =IF(E$4<=核心参数输入!$B$9,核心参数输入!$B$31,0) -> 6500 | F12: =IF(F$4<=核心参数输入!$B$9,核心参数输入!$B$31,0) -> 6500 | G12: =IF(G$4<=核心参数输入!$B$9,核心参数输入!$B$31,0) -> 6500 | H12: =IF(H$4<=核心参数输入!$B$9,核心参数输入!$B$31,0) -> 6500 | I12: =IF(I$4<=核心参数输入!$B$9,核心参数输入!$B$31,0) -> 6500 | J12: =IF(J$4<=核心参数输入!$B$9,核心参数输入!$B$31,0) -> 6500 | K12: =IF(K$4<=核心参数输入!$B$9,核心参数输入!$B$31,0) -> 6500 | ... AH12: =IF(AH$4<=核心参数输入!$B$9,核心参数输入!$B$31,0) -> 0
A13: 销售回款 | B13: 万元 | D13: =IF(D$4<=核心参数输入!$B$9,D11*D12/10000,0) -> 0 | E13: =IF(E$4<=核心参数输入!$B$9,E11*E12/10000,0) -> 0 | F13: =IF(F$4<=核心参数输入!$B$9,F11*F12/10000,0) -> 0 | G13: =IF(G$4<=核心参数输入!$B$9,G11*G12/10000,0) -> 0 | H13: =IF(H$4<=核心参数输入!$B$9,H11*H12/10000,0) -> 14478.75 | I13: =IF(I$4<=核心参数输入!$B$9,I11*I12/10000,0) -> 19305 | J13: =IF(J$4<=核心参数输入!$B$9,J11*J12/10000,0) -> 14478.75 | K13: =IF(K$4<=核心参数输入!$B$9,K11*K12/10000,0) -> 0 | ... AH13: =IF(AH$4<=核心参数输入!$B$9,AH11*AH12/10000,0) -> 0
A14: 实际出租率 | B14: % | D14: =IF(D$4<=核心参数输入!$B$9,建筑面积与开发计划!D26,0) -> 0 | E14: =IF(E$4<=核心参数输入!$B$9,建筑面积与开发计划!E26,0) -> 0 | F14: =IF(F$4<=核心参数输入!$B$9,建筑面积与开发计划!F26,0) -> 0 | G14: =IF(G$4<=核心参数输入!$B$9,建筑面积与开发计划!G26,0) -> 0 | H14: =IF(H$4<=核心参数输入!$B$9,建筑面积与开发计划!H26,0) -> 0.5 | I14: =IF(I$4<=核心参数输入!$B$9,建筑面积与开发计划!I26,0) -> 0.7 | J14: =IF(J$4<=核心参数输入!$B$9,建筑面积与开发计划!J26,0) -> 0.85 | K14: =IF(K$4<=核心参数输入!$B$9,建筑面积与开发计划!K26,0) -> 0.9 | ... AH14: =IF(AH$4<=核心参数输入!$B$9,建筑面积与开发计划!AH26,0) -> 0
A15: 已出租面积 | B15: 平方米 | D15: =IF(D$4<=核心参数输入!$B$9,建筑面积与开发计划!D27,0) -> 0 | E15: =IF(E$4<=核心参数输入!$B$9,建筑面积与开发计划!E27,0) -> 0 | F15: =IF(F$4<=核心参数输入!$B$9,建筑面积与开发计划!F27,0) -> 0 | G15: =IF(G$4<=核心参数输入!$B$9,建筑面积与开发计划!G27,0) -> 0 | H15: =IF(H$4<=核心参数输入!$B$9,建筑面积与开发计划!H27,0) -> 30375 | I15: =IF(I$4<=核心参数输入!$B$9,建筑面积与开发计划!I27,0) -> 42525 | J15: =IF(J$4<=核心参数输入!$B$9,建筑面积与开发计划!J27,0) -> 51637.5 | K15: =IF(K$4<=核心参数输入!$B$9,建筑面积与开发计划!K27,0) -> 54675 | ... AH15: =IF(AH$4<=核心参数输入!$B$9,建筑面积与开发计划!AH27,0) -> 0
A16: 新增出租面积 | B16: 平方米 | D16: =IF(D$4<=核心参数输入!$B$9,建筑面积与开发计划!D28,0) -> 0 | E16: =IF(E$4<=核心参数输入!$B$9,建筑面积与开发计划!E28,0) -> 0 | F16: =IF(F$4<=核心参数输入!$B$9,建筑面积与开发计划!F28,0) -> 0 | G16: =IF(G$4<=核心参数输入!$B$9,建筑面积与开发计划!G28,0) -> 0 | H16: =IF(H$4<=核心参数输入!$B$9,建筑面积与开发计划!H28,0) -> 30375 | I16: =IF(I$4<=核心参数输入!$B$9,建筑面积与开发计划!I28,0) -> 12150 | J16: =IF(J$4<=核心参数输入!$B$9,建筑面积与开发计划!J28,0) -> 9112.5 | K16: =IF(K$4<=核心参数输入!$B$9,建筑面积与开发计划!K28,0) -> 3037.5 | ... AH16: =IF(AH$4<=核心参数输入!$B$9,建筑面积与开发计划!AH28,0) -> 0
A17: 出租第几个年度 | B17: 年 | D17: =IF(D$4<=核心参数输入!$B$9,建筑面积与开发计划!D25,0) -> 0 | E17: =IF(E$4<=核心参数输入!$B$9,建筑面积与开发计划!E25,0) -> 0 | F17: =IF(F$4<=核心参数输入!$B$9,建筑面积与开发计划!F25,0) -> 0 | G17: =IF(G$4<=核心参数输入!$B$9,建筑面积与开发计划!G25,0) -> 0 | H17: =IF(H$4<=核心参数输入!$B$9,建筑面积与开发计划!H25,0) -> 1 | I17: =IF(I$4<=核心参数输入!$B$9,建筑面积与开发计划!I25,0) -> 2 | J17: =IF(J$4<=核心参数输入!$B$9,建筑面积与开发计划!J25,0) -> 3 | K17: =IF(K$4<=核心参数输入!$B$9,建筑面积与开发计划!K25,0) -> 4 | ... AH17: =IF(AH$4<=核心参数输入!$B$9,建筑面积与开发计划!AH25,0) -> 0
A18: 月租金 | B18: 元/平方米/月 | D18: =IF(D$4<=核心参数输入!$B$9,IF(D17>0,核心参数输入!$B$36*(1+核心参数输入!$B$37)^MAX(0,D17-1),0),0) -> 0 | E18: =IF(E$4<=核心参数输入!$B$9,IF(E17>0,核心参数输入!$B$36*(1+核心参数输入!$B$37)^MAX(0,E17-1),0),0) -> 0 | F18: =IF(F$4<=核心参数输入!$B$9,IF(F17>0,核心参数输入!$B$36*(1+核心参数输入!$B$37)^MAX(0,F17-1),0),0) -> 0 | G18: =IF(G$4<=核心参数输入!$B$9,IF(G17>0,核心参数输入!$B$36*(1+核心参数输入!$B$37)^MAX(0,G17-1),0),0) -> 0 | H18: =IF(H$4<=核心参数输入!$B$9,IF(H17>0,核心参数输入!$B$36*(1+核心参数输入!$B$37)^MAX(0,H17-1),0),0) -> 26 | I18: =IF(I$4<=核心参数输入!$B$9,IF(I17>0,核心参数输入!$B$36*(1+核心参数输入!$B$37)^MAX(0,I17-1),0),0) -> 26.39 | J18: =IF(J$4<=核心参数输入!$B$9,IF(J17>0,核心参数输入!$B$36*(1+核心参数输入!$B$37)^MAX(0,J17-1),0),0) -> 26.78585 | K18: =IF(K$4<=核心参数输入!$B$9,IF(K17>0,核心参数输入!$B$36*(1+核心参数输入!$B$37)^MAX(0,K17-1),0),0) -> 27.187638 | ... AH18: =IF(AH$4<=核心参数输入!$B$9,IF(AH17>0,核心参数输入!$B$36*(1+核心参数输入!$B$37)^MAX(0,AH17-1),0),0) -> 0
A19: 新增面积一次免租损失 | B19: 万元 | D19: =IF(D$4<=核心参数输入!$B$9,D16*D18*核心参数输入!$B$42/10000,0) -> 0 | E19: =IF(E$4<=核心参数输入!$B$9,E16*E18*核心参数输入!$B$42/10000,0) -> 0 | F19: =IF(F$4<=核心参数输入!$B$9,F16*F18*核心参数输入!$B$42/10000,0) -> 0 | G19: =IF(G$4<=核心参数输入!$B$9,G16*G18*核心参数输入!$B$42/10000,0) -> 0 | H19: =IF(H$4<=核心参数输入!$B$9,H16*H18*核心参数输入!$B$42/10000,0) -> 236.925 | I19: =IF(I$4<=核心参数输入!$B$9,I16*I18*核心参数输入!$B$42/10000,0) -> 96.19155 | J19: =IF(J$4<=核心参数输入!$B$9,J16*J18*核心参数输入!$B$42/10000,0) -> 73.225817 | K19: =IF(K$4<=核心参数输入!$B$9,K16*K18*核心参数输入!$B$42/10000,0) -> 24.774735 | ... AH19: =IF(AH$4<=核心参数输入!$B$9,AH16*AH18*核心参数输入!$B$42/10000,0) -> 0
A20: 实收租金 | B20: 万元 | D20: =IF(D$4<=核心参数输入!$B$9,(D15*D18*12/10000-D19)*核心参数输入!$B$43,0) -> 0 | E20: =IF(E$4<=核心参数输入!$B$9,(E15*E18*12/10000-E19)*核心参数输入!$B$43,0) -> 0 | F20: =IF(F$4<=核心参数输入!$B$9,(F15*F18*12/10000-F19)*核心参数输入!$B$43,0) -> 0 | G20: =IF(G$4<=核心参数输入!$B$9,(G15*G18*12/10000-G19)*核心参数输入!$B$43,0) -> 0 | H20: =IF(H$4<=核心参数输入!$B$9,(H15*H18*12/10000-H19)*核心参数输入!$B$43,0) -> 696.5595 | I20: =IF(I$4<=核心参数输入!$B$9,(I15*I18*12/10000-I19)*核心参数输入!$B$43,0) -> 1225.4803 | J20: =IF(J$4<=核心参数输入!$B$9,(J15*J18*12/10000-J19)*核心参数输入!$B$43,0) -> 1554.8282 | K20: =IF(K$4<=核心参数输入!$B$9,(K15*K18*12/10000-K19)*核心参数输入!$B$43,0) -> 1723.8261 | ... AH20: =IF(AH$4<=核心参数输入!$B$9,(AH15*AH18*12/10000-AH19)*核心参数输入!$B$43,0) -> 0
A21: 其他经营收入 | B21: 万元 | D21: =IF(D$4<=核心参数输入!$B$9,D20*核心参数输入!$B$44,0) -> 0 | E21: =IF(E$4<=核心参数输入!$B$9,E20*核心参数输入!$B$44,0) -> 0 | F21: =IF(F$4<=核心参数输入!$B$9,F20*核心参数输入!$B$44,0) -> 0 | G21: =IF(G$4<=核心参数输入!$B$9,G20*核心参数输入!$B$44,0) -> 0 | H21: =IF(H$4<=核心参数输入!$B$9,H20*核心参数输入!$B$44,0) -> 34.827975 | I21: =IF(I$4<=核心参数输入!$B$9,I20*核心参数输入!$B$44,0) -> 61.274017 | J21: =IF(J$4<=核心参数输入!$B$9,J20*核心参数输入!$B$44,0) -> 77.74141 | K21: =IF(K$4<=核心参数输入!$B$9,K20*核心参数输入!$B$44,0) -> 86.191303 | ... AH21: =IF(AH$4<=核心参数输入!$B$9,AH20*核心参数输入!$B$44,0) -> 0
A22: 持有经营收入合计 | B22: 万元 | D22: =IF(D$4<=核心参数输入!$B$9,SUM(D20:D21),0) -> 0 | E22: =IF(E$4<=核心参数输入!$B$9,SUM(E20:E21),0) -> 0 | F22: =IF(F$4<=核心参数输入!$B$9,SUM(F20:F21),0) -> 0 | G22: =IF(G$4<=核心参数输入!$B$9,SUM(G20:G21),0) -> 0 | H22: =IF(H$4<=核心参数输入!$B$9,SUM(H20:H21),0) -> 731.38747 | I22: =IF(I$4<=核心参数输入!$B$9,SUM(I20:I21),0) -> 1286.7544 | J22: =IF(J$4<=核心参数输入!$B$9,SUM(J20:J21),0) -> 1632.5696 | K22: =IF(K$4<=核心参数输入!$B$9,SUM(K20:K21),0) -> 1810.0174 | ... AH22: =IF(AH$4<=核心参数输入!$B$9,SUM(AH20:AH21),0) -> 0
A23: 营业收入合计 | B23: 万元 | D23: =IF(D$4<=核心参数输入!$B$9,D13+D22,0) -> 0 | E23: =IF(E$4<=核心参数输入!$B$9,E13+E22,0) -> 0 | F23: =IF(F$4<=核心参数输入!$B$9,F13+F22,0) -> 0 | G23: =IF(G$4<=核心参数输入!$B$9,G13+G22,0) -> 0 | H23: =IF(H$4<=核心参数输入!$B$9,H13+H22,0) -> 15210.137 | I23: =IF(I$4<=核心参数输入!$B$9,I13+I22,0) -> 20591.754 | J23: =IF(J$4<=核心参数输入!$B$9,J13+J22,0) -> 16111.32 | K23: =IF(K$4<=核心参数输入!$B$9,K13+K22,0) -> 1810.0174 | ... AH23: =IF(AH$4<=核心参数输入!$B$9,AH13+AH22,0) -> 0
A24: 期末持有物业处置价 | B24: 万元 | D24: =IF(D$4<=核心参数输入!$B$9,IF(AND(核心参数输入!$B$64=1,D$4=核心参数输入!$B$9),核心参数输入!$B$65,0),0) -> 0 | E24: =IF(E$4<=核心参数输入!$B$9,IF(AND(核心参数输入!$B$64=1,E$4=核心参数输入!$B$9),核心参数输入!$B$65,0),0) -> 0 | F24: =IF(F$4<=核心参数输入!$B$9,IF(AND(核心参数输入!$B$64=1,F$4=核心参数输入!$B$9),核心参数输入!$B$65,0),0) -> 0 | G24: =IF(G$4<=核心参数输入!$B$9,IF(AND(核心参数输入!$B$64=1,G$4=核心参数输入!$B$9),核心参数输入!$B$65,0),0) -> 0 | H24: =IF(H$4<=核心参数输入!$B$9,IF(AND(核心参数输入!$B$64=1,H$4=核心参数输入!$B$9),核心参数输入!$B$65,0),0) -> 0 | I24: =IF(I$4<=核心参数输入!$B$9,IF(AND(核心参数输入!$B$64=1,I$4=核心参数输入!$B$9),核心参数输入!$B$65,0),0) -> 0 | J24: =IF(J$4<=核心参数输入!$B$9,IF(AND(核心参数输入!$B$64=1,J$4=核心参数输入!$B$9),核心参数输入!$B$65,0),0) -> 0 | K24: =IF(K$4<=核心参数输入!$B$9,IF(AND(核心参数输入!$B$64=1,K$4=核心参数输入!$B$9),核心参数输入!$B$65,0),0) -> 0 | ... AH24: =IF(AH$4<=核心参数输入!$B$9,IF(AND(核心参数输入!$B$64=1,AH$4=核心参数输入!$B$9),核心参数输入!$B$65,0),0) -> 0
A25: 处置交易费用含简税 | B25: 万元 | D25: =IF(D$4<=核心参数输入!$B$9,D24*核心参数输入!$B$66,0) -> 0 | E25: =IF(E$4<=核心参数输入!$B$9,E24*核心参数输入!$B$66,0) -> 0 | F25: =IF(F$4<=核心参数输入!$B$9,F24*核心参数输入!$B$66,0) -> 0 | G25: =IF(G$4<=核心参数输入!$B$9,G24*核心参数输入!$B$66,0) -> 0 | H25: =IF(H$4<=核心参数输入!$B$9,H24*核心参数输入!$B$66,0) -> 0 | I25: =IF(I$4<=核心参数输入!$B$9,I24*核心参数输入!$B$66,0) -> 0 | J25: =IF(J$4<=核心参数输入!$B$9,J24*核心参数输入!$B$66,0) -> 0 | K25: =IF(K$4<=核心参数输入!$B$9,K24*核心参数输入!$B$66,0) -> 0 | ... AH25: =IF(AH$4<=核心参数输入!$B$9,AH24*核心参数输入!$B$66,0) -> 0
A26: 期末处置净收入（所得税前） | B26: 万元 | D26: =IF(D$4<=核心参数输入!$B$9,D24-D25,0) -> 0 | E26: =IF(E$4<=核心参数输入!$B$9,E24-E25,0) -> 0 | F26: =IF(F$4<=核心参数输入!$B$9,F24-F25,0) -> 0 | G26: =IF(G$4<=核心参数输入!$B$9,G24-G25,0) -> 0 | H26: =IF(H$4<=核心参数输入!$B$9,H24-H25,0) -> 0 | I26: =IF(I$4<=核心参数输入!$B$9,I24-I25,0) -> 0 | J26: =IF(J$4<=核心参数输入!$B$9,J24-J25,0) -> 0 | K26: =IF(K$4<=核心参数输入!$B$9,K24-K25,0) -> 0 | ... AH26: =IF(AH$4<=核心参数输入!$B$9,AH24-AH25,0) -> 0
A87: 组合压力情景 · 同时降低售价、租金和出租率
A90: 年度销售比例 | B90: % | D90: =IF(D$4<=核心参数输入!$B$9,建筑面积与开发计划!D101,0) -> 0 | E90: =IF(E$4<=核心参数输入!$B$9,建筑面积与开发计划!E101,0) -> 0 | F90: =IF(F$4<=核心参数输入!$B$9,建筑面积与开发计划!F101,0) -> 0 | G90: =IF(G$4<=核心参数输入!$B$9,建筑面积与开发计划!G101,0) -> 0 | H90: =IF(H$4<=核心参数输入!$B$9,建筑面积与开发计划!H101,0) -> 0.3 | I90: =IF(I$4<=核心参数输入!$B$9,建筑面积与开发计划!I101,0) -> 0.4 | J90: =IF(J$4<=核心参数输入!$B$9,建筑面积与开发计划!J101,0) -> 0.3 | K90: =IF(K$4<=核心参数输入!$B$9,建筑面积与开发计划!K101,0) -> 0 | ... AH90: =IF(AH$4<=核心参数输入!$B$9,建筑面积与开发计划!AH101,0) -> 0
A91: 当年销售面积 | B91: 平方米 | D91: =IF(D$4<=核心参数输入!$B$9,建筑面积与开发计划!D103,0) -> 0 | E91: =IF(E$4<=核心参数输入!$B$9,建筑面积与开发计划!E103,0) -> 0 | F91: =IF(F$4<=核心参数输入!$B$9,建筑面积与开发计划!F103,0) -> 0 | G91: =IF(G$4<=核心参数输入!$B$9,建筑面积与开发计划!G103,0) -> 0 | H91: =IF(H$4<=核心参数输入!$B$9,建筑面积与开发计划!H103,0) -> 22275 | I91: =IF(I$4<=核心参数输入!$B$9,建筑面积与开发计划!I103,0) -> 29700 | J91: =IF(J$4<=核心参数输入!$B$9,建筑面积与开发计划!J103,0) -> 22275 | K91: =IF(K$4<=核心参数输入!$B$9,建筑面积与开发计划!K103,0) -> 0 | ... AH91: =IF(AH$4<=核心参数输入!$B$9,建筑面积与开发计划!AH103,0) -> 0
A92: 销售价格 | B92: 元/平方米 | D92: =IF(D$4<=核心参数输入!$B$9,核心参数输入!$B$31*(1-核心参数输入!$B$78),0) -> 5850 | E92: =IF(E$4<=核心参数输入!$B$9,核心参数输入!$B$31*(1-核心参数输入!$B$78),0) -> 5850 | F92: =IF(F$4<=核心参数输入!$B$9,核心参数输入!$B$31*(1-核心参数输入!$B$78),0) -> 5850 | G92: =IF(G$4<=核心参数输入!$B$9,核心参数输入!$B$31*(1-核心参数输入!$B$78),0) -> 5850 | H92: =IF(H$4<=核心参数输入!$B$9,核心参数输入!$B$31*(1-核心参数输入!$B$78),0) -> 5850 | I92: =IF(I$4<=核心参数输入!$B$9,核心参数输入!$B$31*(1-核心参数输入!$B$78),0) -> 5850 | J92: =IF(J$4<=核心参数输入!$B$9,核心参数输入!$B$31*(1-核心参数输入!$B$78),0) -> 5850 | K92: =IF(K$4<=核心参数输入!$B$9,核心参数输入!$B$31*(1-核心参数输入!$B$78),0) -> 5850 | ... AH92: =IF(AH$4<=核心参数输入!$B$9,核心参数输入!$B$31*(1-核心参数输入!$B$78),0) -> 0
A93: 销售回款 | B93: 万元 | D93: =IF(D$4<=核心参数输入!$B$9,D91*D92/10000,0) -> 0 | E93: =IF(E$4<=核心参数输入!$B$9,E91*E92/10000,0) -> 0 | F93: =IF(F$4<=核心参数输入!$B$9,F91*F92/10000,0) -> 0 | G93: =IF(G$4<=核心参数输入!$B$9,G91*G92/10000,0) -> 0 | H93: =IF(H$4<=核心参数输入!$B$9,H91*H92/10000,0) -> 13030.875 | I93: =IF(I$4<=核心参数输入!$B$9,I91*I92/10000,0) -> 17374.5 | J93: =IF(J$4<=核心参数输入!$B$9,J91*J92/10000,0) -> 13030.875 | K93: =IF(K$4<=核心参数输入!$B$9,K91*K92/10000,0) -> 0 | ... AH93: =IF(AH$4<=核心参数输入!$B$9,AH91*AH92/10000,0) -> 0
A94: 实际出租率 | B94: % | D94: =IF(D$4<=核心参数输入!$B$9,建筑面积与开发计划!D106,0) -> 0 | E94: =IF(E$4<=核心参数输入!$B$9,建筑面积与开发计划!E106,0) -> 0 | F94: =IF(F$4<=核心参数输入!$B$9,建筑面积与开发计划!F106,0) -> 0 | G94: =IF(G$4<=核心参数输入!$B$9,建筑面积与开发计划!G106,0) -> 0 | H94: =IF(H$4<=核心参数输入!$B$9,建筑面积与开发计划!H106,0) -> 0.4 | I94: =IF(I$4<=核心参数输入!$B$9,建筑面积与开发计划!I106,0) -> 0.6 | J94: =IF(J$4<=核心参数输入!$B$9,建筑面积与开发计划!J106,0) -> 0.75 | K94: =IF(K$4<=核心参数输入!$B$9,建筑面积与开发计划!K106,0) -> 0.8 | ... AH94: =IF(AH$4<=核心参数输入!$B$9,建筑面积与开发计划!AH106,0) -> 0
A95: 已出租面积 | B95: 平方米 | D95: =IF(D$4<=核心参数输入!$B$9,建筑面积与开发计划!D107,0) -> 0 | E95: =IF(E$4<=核心参数输入!$B$9,建筑面积与开发计划!E107,0) -> 0 | F95: =IF(F$4<=核心参数输入!$B$9,建筑面积与开发计划!F107,0) -> 0 | G95: =IF(G$4<=核心参数输入!$B$9,建筑面积与开发计划!G107,0) -> 0 | H95: =IF(H$4<=核心参数输入!$B$9,建筑面积与开发计划!H107,0) -> 24300 | I95: =IF(I$4<=核心参数输入!$B$9,建筑面积与开发计划!I107,0) -> 36450 | J95: =IF(J$4<=核心参数输入!$B$9,建筑面积与开发计划!J107,0) -> 45562.5 | K95: =IF(K$4<=核心参数输入!$B$9,建筑面积与开发计划!K107,0) -> 48600 | ... AH95: =IF(AH$4<=核心参数输入!$B$9,建筑面积与开发计划!AH107,0) -> 0
A96: 新增出租面积 | B96: 平方米 | D96: =IF(D$4<=核心参数输入!$B$9,建筑面积与开发计划!D108,0) -> 0 | E96: =IF(E$4<=核心参数输入!$B$9,建筑面积与开发计划!E108,0) -> 0 | F96: =IF(F$4<=核心参数输入!$B$9,建筑面积与开发计划!F108,0) -> 0 | G96: =IF(G$4<=核心参数输入!$B$9,建筑面积与开发计划!G108,0) -> 0 | H96: =IF(H$4<=核心参数输入!$B$9,建筑面积与开发计划!H108,0) -> 24300 | I96: =IF(I$4<=核心参数输入!$B$9,建筑面积与开发计划!I108,0) -> 12150 | J96: =IF(J$4<=核心参数输入!$B$9,建筑面积与开发计划!J108,0) -> 9112.5 | K96: =IF(K$4<=核心参数输入!$B$9,建筑面积与开发计划!K108,0) -> 3037.5 | ... AH96: =IF(AH$4<=核心参数输入!$B$9,建筑面积与开发计划!AH108,0) -> 0
A97: 出租第几个年度 | B97: 年 | D97: =IF(D$4<=核心参数输入!$B$9,建筑面积与开发计划!D105,0) -> 0 | E97: =IF(E$4<=核心参数输入!$B$9,建筑面积与开发计划!E105,0) -> 0 | F97: =IF(F$4<=核心参数输入!$B$9,建筑面积与开发计划!F105,0) -> 0 | G97: =IF(G$4<=核心参数输入!$B$9,建筑面积与开发计划!G105,0) -> 0 | H97: =IF(H$4<=核心参数输入!$B$9,建筑面积与开发计划!H105,0) -> 1 | I97: =IF(I$4<=核心参数输入!$B$9,建筑面积与开发计划!I105,0) -> 2 | J97: =IF(J$4<=核心参数输入!$B$9,建筑面积与开发计划!J105,0) -> 3 | K97: =IF(K$4<=核心参数输入!$B$9,建筑面积与开发计划!K105,0) -> 4 | ... AH97: =IF(AH$4<=核心参数输入!$B$9,建筑面积与开发计划!AH105,0) -> 0
A98: 月租金 | B98: 元/平方米/月 | D98: =IF(D$4<=核心参数输入!$B$9,IF(D97>0,核心参数输入!$B$36*(1+核心参数输入!$B$37)^MAX(0,D97-1)*(1-核心参数输入!$B$79),0),0) -> 0 | E98: =IF(E$4<=核心参数输入!$B$9,IF(E97>0,核心参数输入!$B$36*(1+核心参数输入!$B$37)^MAX(0,E97-1)*(1-核心参数输入!$B$79),0),0) -> 0 | F98: =IF(F$4<=核心参数输入!$B$9,IF(F97>0,核心参数输入!$B$36*(1+核心参数输入!$B$37)^MAX(0,F97-1)*(1-核心参数输入!$B$79),0),0) -> 0 | G98: =IF(G$4<=核心参数输入!$B$9,IF(G97>0,核心参数输入!$B$36*(1+核心参数输入!$B$37)^MAX(0,G97-1)*(1-核心参数输入!$B$79),0),0) -> 0 | H98: =IF(H$4<=核心参数输入!$B$9,IF(H97>0,核心参数输入!$B$36*(1+核心参数输入!$B$37)^MAX(0,H97-1)*(1-核心参数输入!$B$79),0),0) -> 23.4 | I98: =IF(I$4<=核心参数输入!$B$9,IF(I97>0,核心参数输入!$B$36*(1+核心参数输入!$B$37)^MAX(0,I97-1)*(1-核心参数输入!$B$79),0),0) -> 23.751 | J98: =IF(J$4<=核心参数输入!$B$9,IF(J97>0,核心参数输入!$B$36*(1+核心参数输入!$B$37)^MAX(0,J97-1)*(1-核心参数输入!$B$79),0),0) -> 24.107265 | K98: =IF(K$4<=核心参数输入!$B$9,IF(K97>0,核心参数输入!$B$36*(1+核心参数输入!$B$37)^MAX(0,K97-1)*(1-核心参数输入!$B$79),0),0) -> 24.468874 | ... AH98: =IF(AH$4<=核心参数输入!$B$9,IF(AH97>0,核心参数输入!$B$36*(1+核心参数输入!$B$37)^MAX(0,AH97-1)*(1-核心参数输入!$B$79),0),0) -> 0
A99: 新增面积一次免租损失 | B99: 万元 | D99: =IF(D$4<=核心参数输入!$B$9,D96*D98*核心参数输入!$B$42/10000,0) -> 0 | E99: =IF(E$4<=核心参数输入!$B$9,E96*E98*核心参数输入!$B$42/10000,0) -> 0 | F99: =IF(F$4<=核心参数输入!$B$9,F96*F98*核心参数输入!$B$42/10000,0) -> 0 | G99: =IF(G$4<=核心参数输入!$B$9,G96*G98*核心参数输入!$B$42/10000,0) -> 0 | H99: =IF(H$4<=核心参数输入!$B$9,H96*H98*核心参数输入!$B$42/10000,0) -> 170.586 | I99: =IF(I$4<=核心参数输入!$B$9,I96*I98*核心参数输入!$B$42/10000,0) -> 86.572395 | J99: =IF(J$4<=核心参数输入!$B$9,J96*J98*核心参数输入!$B$42/10000,0) -> 65.903236 | K99: =IF(K$4<=核心参数输入!$B$9,K96*K98*核心参数输入!$B$42/10000,0) -> 22.297261 | ... AH99: =IF(AH$4<=核心参数输入!$B$9,AH96*AH98*核心参数输入!$B$42/10000,0) -> 0
A100: 实收租金 | B100: 万元 | D100: =IF(D$4<=核心参数输入!$B$9,(D95*D98*12/10000-D99)*核心参数输入!$B$43,0) -> 0 | E100: =IF(E$4<=核心参数输入!$B$9,(E95*E98*12/10000-E99)*核心参数输入!$B$43,0) -> 0 | F100: =IF(F$4<=核心参数输入!$B$9,(F95*F98*12/10000-F99)*核心参数输入!$B$43,0) -> 0 | G100: =IF(G$4<=核心参数输入!$B$9,(G95*G98*12/10000-G99)*核心参数输入!$B$43,0) -> 0 | H100: =IF(H$4<=核心参数输入!$B$9,(H95*H98*12/10000-H99)*核心参数输入!$B$43,0) -> 501.52284 | I100: =IF(I$4<=核心参数输入!$B$9,(I95*I98*12/10000-I99)*核心参数输入!$B$43,0) -> 933.25042 | J100: =IF(J$4<=核心参数输入!$B$9,(J95*J98*12/10000-J99)*核心参数输入!$B$43,0) -> 1227.1182 | K100: =IF(K$4<=核心参数输入!$B$9,(K95*K98*12/10000-K99)*核心参数输入!$B$43,0) -> 1376.6329 | ... AH100: =IF(AH$4<=核心参数输入!$B$9,(AH95*AH98*12/10000-AH99)*核心参数输入!$B$43,0) -> 0
A101: 其他经营收入 | B101: 万元 | D101: =IF(D$4<=核心参数输入!$B$9,D100*核心参数输入!$B$44,0) -> 0 | E101: =IF(E$4<=核心参数输入!$B$9,E100*核心参数输入!$B$44,0) -> 0 | F101: =IF(F$4<=核心参数输入!$B$9,F100*核心参数输入!$B$44,0) -> 0 | G101: =IF(G$4<=核心参数输入!$B$9,G100*核心参数输入!$B$44,0) -> 0 | H101: =IF(H$4<=核心参数输入!$B$9,H100*核心参数输入!$B$44,0) -> 25.076142 | I101: =IF(I$4<=核心参数输入!$B$9,I100*核心参数输入!$B$44,0) -> 46.662521 | J101: =IF(J$4<=核心参数输入!$B$9,J100*核心参数输入!$B$44,0) -> 61.355912 | K101: =IF(K$4<=核心参数输入!$B$9,K100*核心参数输入!$B$44,0) -> 68.831646 | ... AH101: =IF(AH$4<=核心参数输入!$B$9,AH100*核心参数输入!$B$44,0) -> 0
A102: 持有经营收入合计 | B102: 万元 | D102: =IF(D$4<=核心参数输入!$B$9,SUM(D100:D101),0) -> 0 | E102: =IF(E$4<=核心参数输入!$B$9,SUM(E100:E101),0) -> 0 | F102: =IF(F$4<=核心参数输入!$B$9,SUM(F100:F101),0) -> 0 | G102: =IF(G$4<=核心参数输入!$B$9,SUM(G100:G101),0) -> 0 | H102: =IF(H$4<=核心参数输入!$B$9,SUM(H100:H101),0) -> 526.59898 | I102: =IF(I$4<=核心参数输入!$B$9,SUM(I100:I101),0) -> 979.91294 | J102: =IF(J$4<=核心参数输入!$B$9,SUM(J100:J101),0) -> 1288.4742 | K102: =IF(K$4<=核心参数输入!$B$9,SUM(K100:K101),0) -> 1445.4646 | ... AH102: =IF(AH$4<=核心参数输入!$B$9,SUM(AH100:AH101),0) -> 0
A103: 营业收入合计 | B103: 万元 | D103: =IF(D$4<=核心参数输入!$B$9,D93+D102,0) -> 0 | E103: =IF(E$4<=核心参数输入!$B$9,E93+E102,0) -> 0 | F103: =IF(F$4<=核心参数输入!$B$9,F93+F102,0) -> 0 | G103: =IF(G$4<=核心参数输入!$B$9,G93+G102,0) -> 0 | H103: =IF(H$4<=核心参数输入!$B$9,H93+H102,0) -> 13557.474 | I103: =IF(I$4<=核心参数输入!$B$9,I93+I102,0) -> 18354.413 | J103: =IF(J$4<=核心参数输入!$B$9,J93+J102,0) -> 14319.349 | K103: =IF(K$4<=核心参数输入!$B$9,K93+K102,0) -> 1445.4646 | ... AH103: =IF(AH$4<=核心参数输入!$B$9,AH93+AH102,0) -> 0
A104: 期末持有物业处置价 | B104: 万元 | D104: =IF(D$4<=核心参数输入!$B$9,IF(AND(核心参数输入!$B$64=1,D$4=核心参数输入!$B$9),核心参数输入!$B$65,0),0) -> 0 | E104: =IF(E$4<=核心参数输入!$B$9,IF(AND(核心参数输入!$B$64=1,E$4=核心参数输入!$B$9),核心参数输入!$B$65,0),0) -> 0 | F104: =IF(F$4<=核心参数输入!$B$9,IF(AND(核心参数输入!$B$64=1,F$4=核心参数输入!$B$9),核心参数输入!$B$65,0),0) -> 0 | G104: =IF(G$4<=核心参数输入!$B$9,IF(AND(核心参数输入!$B$64=1,G$4=核心参数输入!$B$9),核心参数输入!$B$65,0),0) -> 0 | H104: =IF(H$4<=核心参数输入!$B$9,IF(AND(核心参数输入!$B$64=1,H$4=核心参数输入!$B$9),核心参数输入!$B$65,0),0) -> 0 | I104: =IF(I$4<=核心参数输入!$B$9,IF(AND(核心参数输入!$B$64=1,I$4=核心参数输入!$B$9),核心参数输入!$B$65,0),0) -> 0 | J104: =IF(J$4<=核心参数输入!$B$9,IF(AND(核心参数输入!$B$64=1,J$4=核心参数输入!$B$9),核心参数输入!$B$65,0),0) -> 0 | K104: =IF(K$4<=核心参数输入!$B$9,IF(AND(核心参数输入!$B$64=1,K$4=核心参数输入!$B$9),核心参数输入!$B$65,0),0) -> 0 | ... AH104: =IF(AH$4<=核心参数输入!$B$9,IF(AND(核心参数输入!$B$64=1,AH$4=核心参数输入!$B$9),核心参数输入!$B$65,0),0) -> 0
A105: 处置交易费用含简税 | B105: 万元 | D105: =IF(D$4<=核心参数输入!$B$9,D104*核心参数输入!$B$66,0) -> 0 | E105: =IF(E$4<=核心参数输入!$B$9,E104*核心参数输入!$B$66,0) -> 0 | F105: =IF(F$4<=核心参数输入!$B$9,F104*核心参数输入!$B$66,0) -> 0 | G105: =IF(G$4<=核心参数输入!$B$9,G104*核心参数输入!$B$66,0) -> 0 | H105: =IF(H$4<=核心参数输入!$B$9,H104*核心参数输入!$B$66,0) -> 0 | I105: =IF(I$4<=核心参数输入!$B$9,I104*核心参数输入!$B$66,0) -> 0 | J105: =IF(J$4<=核心参数输入!$B$9,J104*核心参数输入!$B$66,0) -> 0 | K105: =IF(K$4<=核心参数输入!$B$9,K104*核心参数输入!$B$66,0) -> 0 | ... AH105: =IF(AH$4<=核心参数输入!$B$9,AH104*核心参数输入!$B$66,0) -> 0
A106: 期末处置净收入（所得税前） | B106: 万元 | D106: =IF(D$4<=核心参数输入!$B$9,D104-D105,0) -> 0 | E106: =IF(E$4<=核心参数输入!$B$9,E104-E105,0) -> 0 | F106: =IF(F$4<=核心参数输入!$B$9,F104-F105,0) -> 0 | G106: =IF(G$4<=核心参数输入!$B$9,G104-G105,0) -> 0 | H106: =IF(H$4<=核心参数输入!$B$9,H104-H105,0) -> 0 | I106: =IF(I$4<=核心参数输入!$B$9,I104-I105,0) -> 0 | J106: =IF(J$4<=核心参数输入!$B$9,J104-J105,0) -> 0 | K106: =IF(K$4<=核心参数输入!$B$9,K104-K105,0) -> 0 | ... AH106: =IF(AH$4<=核心参数输入!$B$9,AH104-AH105,0) -> 0

Sheet 运营成本与税费
A2: 运营成本与税费 · 模拟数据
A4: 项目年度 / 日历年份 | D4: =核心参数输入!D87 -> 0 | E4: =核心参数输入!E87 -> 1 | F4: =核心参数输入!F87 -> 2 | G4: =核心参数输入!G87 -> 3 | H4: =核心参数输入!H87 -> 4 | I4: =核心参数输入!I87 -> 5 | J4: =核心参数输入!J87 -> 6 | K4: =核心参数输入!K87 -> 7 | ... AH4: =核心参数输入!AH87 -> 30
D5: =核心参数输入!$B$8+D4 -> 2026 | E5: =核心参数输入!$B$8+E4 -> 2027 | F5: =核心参数输入!$B$8+F4 -> 2028 | G5: =核心参数输入!$B$8+G4 -> 2029 | H5: =核心参数输入!$B$8+H4 -> 2030 | I5: =核心参数输入!$B$8+I4 -> 2031 | J5: =核心参数输入!$B$8+J4 -> 2032 | K5: =核心参数输入!$B$8+K4 -> 2033 | ... AH5: =核心参数输入!$B$8+AH4 -> 2056
A7: 基准情景 · 现金成本与非现金成本分开
A10: 销售费用现金支出 | B10: 万元 | D10: =IF(D$4<=核心参数输入!$B$9,销售与出租收入!D13*核心参数输入!$B$32,0) -> 0 | E10: =IF(E$4<=核心参数输入!$B$9,销售与出租收入!E13*核心参数输入!$B$32,0) -> 0 | F10: =IF(F$4<=核心参数输入!$B$9,销售与出租收入!F13*核心参数输入!$B$32,0) -> 0 | G10: =IF(G$4<=核心参数输入!$B$9,销售与出租收入!G13*核心参数输入!$B$32,0) -> 0 | H10: =IF(H$4<=核心参数输入!$B$9,销售与出租收入!H13*核心参数输入!$B$32,0) -> 361.96875 | I10: =IF(I$4<=核心参数输入!$B$9,销售与出租收入!I13*核心参数输入!$B$32,0) -> 482.625 | J10: =IF(J$4<=核心参数输入!$B$9,销售与出租收入!J13*核心参数输入!$B$32,0) -> 361.96875 | K10: =IF(K$4<=核心参数输入!$B$9,销售与出租收入!K13*核心参数输入!$B$32,0) -> 0 | ... AH10: =IF(AH$4<=核心参数输入!$B$9,销售与出租收入!AH13*核心参数输入!$B$32,0) -> 0
A11: 销售相关税费现金支出 | B11: 万元 | D11: =IF(D$4<=核心参数输入!$B$9,销售与出租收入!D13*核心参数输入!$B$33,0) -> 0 | E11: =IF(E$4<=核心参数输入!$B$9,销售与出租收入!E13*核心参数输入!$B$33,0) -> 0 | F11: =IF(F$4<=核心参数输入!$B$9,销售与出租收入!F13*核心参数输入!$B$33,0) -> 0 | G11: =IF(G$4<=核心参数输入!$B$9,销售与出租收入!G13*核心参数输入!$B$33,0) -> 0 | H11: =IF(H$4<=核心参数输入!$B$9,销售与出租收入!H13*核心参数输入!$B$33,0) -> 1158.3 | I11: =IF(I$4<=核心参数输入!$B$9,销售与出租收入!I13*核心参数输入!$B$33,0) -> 1544.4 | J11: =IF(J$4<=核心参数输入!$B$9,销售与出租收入!J13*核心参数输入!$B$33,0) -> 1158.3 | K11: =IF(K$4<=核心参数输入!$B$9,销售与出租收入!K13*核心参数输入!$B$33,0) -> 0 | ... AH11: =IF(AH$4<=核心参数输入!$B$9,销售与出租收入!AH13*核心参数输入!$B$33,0) -> 0
A12: 持有固定运营成本 | B12: 万元 | D12: =IF(D$4<=核心参数输入!$B$9,IF(D$4-核心参数输入!$B$16>0,核心参数输入!$B$47*(1+核心参数输入!$B$48)^MAX(0,D$4-核心参数输入!$B$16-1),0),0) -> 0 | E12: =IF(E$4<=核心参数输入!$B$9,IF(E$4-核心参数输入!$B$16>0,核心参数输入!$B$47*(1+核心参数输入!$B$48)^MAX(0,E$4-核心参数输入!$B$16-1),0),0) -> 0 | F12: =IF(F$4<=核心参数输入!$B$9,IF(F$4-核心参数输入!$B$16>0,核心参数输入!$B$47*(1+核心参数输入!$B$48)^MAX(0,F$4-核心参数输入!$B$16-1),0),0) -> 0 | G12: =IF(G$4<=核心参数输入!$B$9,IF(G$4-核心参数输入!$B$16>0,核心参数输入!$B$47*(1+核心参数输入!$B$48)^MAX(0,G$4-核心参数输入!$B$16-1),0),0) -> 0 | H12: =IF(H$4<=核心参数输入!$B$9,IF(H$4-核心参数输入!$B$16>0,核心参数输入!$B$47*(1+核心参数输入!$B$48)^MAX(0,H$4-核心参数输入!$B$16-1),0),0) -> 300 | I12: =IF(I$4<=核心参数输入!$B$9,IF(I$4-核心参数输入!$B$16>0,核心参数输入!$B$47*(1+核心参数输入!$B$48)^MAX(0,I$4-核心参数输入!$B$16-1),0),0) -> 306 | J12: =IF(J$4<=核心参数输入!$B$9,IF(J$4-核心参数输入!$B$16>0,核心参数输入!$B$47*(1+核心参数输入!$B$48)^MAX(0,J$4-核心参数输入!$B$16-1),0),0) -> 312.12 | K12: =IF(K$4<=核心参数输入!$B$9,IF(K$4-核心参数输入!$B$16>0,核心参数输入!$B$47*(1+核心参数输入!$B$48)^MAX(0,K$4-核心参数输入!$B$16-1),0),0) -> 318.3624 | ... AH12: =IF(AH$4<=核心参数输入!$B$9,IF(AH$4-核心参数输入!$B$16>0,核心参数输入!$B$47*(1+核心参数输入!$B$48)^MAX(0,AH$4-核心参数输入!$B$16-1),0),0) -> 0
A13: 持有变动运营成本 | B13: 万元 | D13: =IF(D$4<=核心参数输入!$B$9,销售与出租收入!D22*核心参数输入!$B$49,0) -> 0 | E13: =IF(E$4<=核心参数输入!$B$9,销售与出租收入!E22*核心参数输入!$B$49,0) -> 0 | F13: =IF(F$4<=核心参数输入!$B$9,销售与出租收入!F22*核心参数输入!$B$49,0) -> 0 | G13: =IF(G$4<=核心参数输入!$B$9,销售与出租收入!G22*核心参数输入!$B$49,0) -> 0 | H13: =IF(H$4<=核心参数输入!$B$9,销售与出租收入!H22*核心参数输入!$B$49,0) -> 87.766497 | I13: =IF(I$4<=核心参数输入!$B$9,销售与出租收入!I22*核心参数输入!$B$49,0) -> 154.41052 | J13: =IF(J$4<=核心参数输入!$B$9,销售与出租收入!J22*核心参数输入!$B$49,0) -> 195.90835 | K13: =IF(K$4<=核心参数输入!$B$9,销售与出租收入!K22*核心参数输入!$B$49,0) -> 217.20208 | ... AH13: =IF(AH$4<=核心参数输入!$B$9,销售与出租收入!AH22*核心参数输入!$B$49,0) -> 0
A14: 维护更新支出（当期费用化） | B14: 万元 | D14: =IF(D$4<=核心参数输入!$B$9,IF(D$4-核心参数输入!$B$16>0,核心参数输入!$B$50,0),0) -> 0 | E14: =IF(E$4<=核心参数输入!$B$9,IF(E$4-核心参数输入!$B$16>0,核心参数输入!$B$50,0),0) -> 0 | F14: =IF(F$4<=核心参数输入!$B$9,IF(F$4-核心参数输入!$B$16>0,核心参数输入!$B$50,0),0) -> 0 | G14: =IF(G$4<=核心参数输入!$B$9,IF(G$4-核心参数输入!$B$16>0,核心参数输入!$B$50,0),0) -> 0 | H14: =IF(H$4<=核心参数输入!$B$9,IF(H$4-核心参数输入!$B$16>0,核心参数输入!$B$50,0),0) -> 180 | I14: =IF(I$4<=核心参数输入!$B$9,IF(I$4-核心参数输入!$B$16>0,核心参数输入!$B$50,0),0) -> 180 | J14: =IF(J$4<=核心参数输入!$B$9,IF(J$4-核心参数输入!$B$16>0,核心参数输入!$B$50,0),0) -> 180 | K14: =IF(K$4<=核心参数输入!$B$9,IF(K$4-核心参数输入!$B$16>0,核心参数输入!$B$50,0),0) -> 180 | ... AH14: =IF(AH$4<=核心参数输入!$B$9,IF(AH$4-核心参数输入!$B$16>0,核心参数输入!$B$50,0),0) -> 0
A15: 运营相关税费 | B15: 万元 | D15: =IF(D$4<=核心参数输入!$B$9,销售与出租收入!D22*核心参数输入!$B$51,0) -> 0 | E15: =IF(E$4<=核心参数输入!$B$9,销售与出租收入!E22*核心参数输入!$B$51,0) -> 0 | F15: =IF(F$4<=核心参数输入!$B$9,销售与出租收入!F22*核心参数输入!$B$51,0) -> 0 | G15: =IF(G$4<=核心参数输入!$B$9,销售与出租收入!G22*核心参数输入!$B$51,0) -> 0 | H15: =IF(H$4<=核心参数输入!$B$9,销售与出租收入!H22*核心参数输入!$B$51,0) -> 43.883248 | I15: =IF(I$4<=核心参数输入!$B$9,销售与出租收入!I22*核心参数输入!$B$51,0) -> 77.205262 | J15: =IF(J$4<=核心参数输入!$B$9,销售与出租收入!J22*核心参数输入!$B$51,0) -> 97.954176 | K15: =IF(K$4<=核心参数输入!$B$9,销售与出租收入!K22*核心参数输入!$B$51,0) -> 108.60104 | ... AH15: =IF(AH$4<=核心参数输入!$B$9,销售与出租收入!AH22*核心参数输入!$B$51,0) -> 0
A16: 现金成本及经营税费合计 | B16: 万元 | D16: =IF(D$4<=核心参数输入!$B$9,SUM(D10:D15),0) -> 0 | E16: =IF(E$4<=核心参数输入!$B$9,SUM(E10:E15),0) -> 0 | F16: =IF(F$4<=核心参数输入!$B$9,SUM(F10:F15),0) -> 0 | G16: =IF(G$4<=核心参数输入!$B$9,SUM(G10:G15),0) -> 0 | H16: =IF(H$4<=核心参数输入!$B$9,SUM(H10:H15),0) -> 2131.9185 | I16: =IF(I$4<=核心参数输入!$B$9,SUM(I10:I15),0) -> 2744.6408 | J16: =IF(J$4<=核心参数输入!$B$9,SUM(J10:J15),0) -> 2306.2513 | K16: =IF(K$4<=核心参数输入!$B$9,SUM(K10:K15),0) -> 824.16552 | ... AH16: =IF(AH$4<=核心参数输入!$B$9,SUM(AH10:AH15),0) -> 0
A17: 销售成本结转（项目口径） | B17: 万元 | D17: =IF(D$4<=核心参数输入!$B$9,投资与资金安排!$B$19*建筑面积与开发计划!D21,0) -> 0 | E17: =IF(E$4<=核心参数输入!$B$9,投资与资金安排!$B$19*建筑面积与开发计划!E21,0) -> 0 | F17: =IF(F$4<=核心参数输入!$B$9,投资与资金安排!$B$19*建筑面积与开发计划!F21,0) -> 0 | G17: =IF(G$4<=核心参数输入!$B$9,投资与资金安排!$B$19*建筑面积与开发计划!G21,0) -> 0 | H17: =IF(H$4<=核心参数输入!$B$9,投资与资金安排!$B$19*建筑面积与开发计划!H21,0) -> 10051.8 | I17: =IF(I$4<=核心参数输入!$B$9,投资与资金安排!$B$19*建筑面积与开发计划!I21,0) -> 13402.4 | J17: =IF(J$4<=核心参数输入!$B$9,投资与资金安排!$B$19*建筑面积与开发计划!J21,0) -> 10051.8 | K17: =IF(K$4<=核心参数输入!$B$9,投资与资金安排!$B$19*建筑面积与开发计划!K21,0) -> 0 | ... AH17: =IF(AH$4<=核心参数输入!$B$9,投资与资金安排!$B$19*建筑面积与开发计划!AH21,0) -> 0
A18: 销售成本结转（融资口径） | B18: 万元 | D18: =IF(D$4<=核心参数输入!$B$9,投资与资金安排!$B$22*建筑面积与开发计划!D21,0) -> 0 | E18: =IF(E$4<=核心参数输入!$B$9,投资与资金安排!$B$22*建筑面积与开发计划!E21,0) -> 0 | F18: =IF(F$4<=核心参数输入!$B$9,投资与资金安排!$B$22*建筑面积与开发计划!F21,0) -> 0 | G18: =IF(G$4<=核心参数输入!$B$9,投资与资金安排!$B$22*建筑面积与开发计划!G21,0) -> 0 | H18: =IF(H$4<=核心参数输入!$B$9,投资与资金安排!$B$22*建筑面积与开发计划!H21,0) -> 10363.65 | I18: =IF(I$4<=核心参数输入!$B$9,投资与资金安排!$B$22*建筑面积与开发计划!I21,0) -> 13818.2 | J18: =IF(J$4<=核心参数输入!$B$9,投资与资金安排!$B$22*建筑面积与开发计划!J21,0) -> 10363.65 | K18: =IF(K$4<=核心参数输入!$B$9,投资与资金安排!$B$22*建筑面积与开发计划!K21,0) -> 0 | ... AH18: =IF(AH$4<=核心参数输入!$B$9,投资与资金安排!$B$22*建筑面积与开发计划!AH21,0) -> 0
A19: 持有建筑折旧（项目口径） | B19: 万元 | D19: =IF(D$4<=核心参数输入!$B$9,IF(AND(D$4-核心参数输入!$B$16>0,D$4-核心参数输入!$B$16<=核心参数输入!$B$53),投资与资金安排!$B$20*(1-核心参数输入!$B$54)/MAX(1,核心参数输入!$B$53),0),0) -> 0 | E19: =IF(E$4<=核心参数输入!$B$9,IF(AND(E$4-核心参数输入!$B$16>0,E$4-核心参数输入!$B$16<=核心参数输入!$B$53),投资与资金安排!$B$20*(1-核心参数输入!$B$54)/MAX(1,核心参数输入!$B$53),0),0) -> 0 | F19: =IF(F$4<=核心参数输入!$B$9,IF(AND(F$4-核心参数输入!$B$16>0,F$4-核心参数输入!$B$16<=核心参数输入!$B$53),投资与资金安排!$B$20*(1-核心参数输入!$B$54)/MAX(1,核心参数输入!$B$53),0),0) -> 0 | G19: =IF(G$4<=核心参数输入!$B$9,IF(AND(G$4-核心参数输入!$B$16>0,G$4-核心参数输入!$B$16<=核心参数输入!$B$53),投资与资金安排!$B$20*(1-核心参数输入!$B$54)/MAX(1,核心参数输入!$B$53),0),0) -> 0 | H19: =IF(H$4<=核心参数输入!$B$9,IF(AND(H$4-核心参数输入!$B$16>0,H$4-核心参数输入!$B$16<=核心参数输入!$B$53),投资与资金安排!$B$20*(1-核心参数输入!$B$54)/MAX(1,核心参数输入!$B$53),0),0) -> 754.11 | I19: =IF(I$4<=核心参数输入!$B$9,IF(AND(I$4-核心参数输入!$B$16>0,I$4-核心参数输入!$B$16<=核心参数输入!$B$53),投资与资金安排!$B$20*(1-核心参数输入!$B$54)/MAX(1,核心参数输入!$B$53),0),0) -> 754.11 | J19: =IF(J$4<=核心参数输入!$B$9,IF(AND(J$4-核心参数输入!$B$16>0,J$4-核心参数输入!$B$16<=核心参数输入!$B$53),投资与资金安排!$B$20*(1-核心参数输入!$B$54)/MAX(1,核心参数输入!$B$53),0),0) -> 754.11 | K19: =IF(K$4<=核心参数输入!$B$9,IF(AND(K$4-核心参数输入!$B$16>0,K$4-核心参数输入!$B$16<=核心参数输入!$B$53),投资与资金安排!$B$20*(1-核心参数输入!$B$54)/MAX(1,核心参数输入!$B$53),0),0) -> 754.11 | ... AH19: =IF(AH$4<=核心参数输入!$B$9,IF(AND(AH$4-核心参数输入!$B$16>0,AH$4-核心参数输入!$B$16<=核心参数输入!$B$53),投资与资金安排!$B$20*(1-核心参数输入!$B$54)/MAX(1,核心参数输入!$B$53),0),0) -> 0
A20: 持有建筑折旧（融资口径） | B20: 万元 | D20: =IF(D$4<=核心参数输入!$B$9,IF(AND(D$4-核心参数输入!$B$16>0,D$4-核心参数输入!$B$16<=核心参数输入!$B$53),投资与资金安排!$B$23*(1-核心参数输入!$B$54)/MAX(1,核心参数输入!$B$53),0),0) -> 0 | E20: =IF(E$4<=核心参数输入!$B$9,IF(AND(E$4-核心参数输入!$B$16>0,E$4-核心参数输入!$B$16<=核心参数输入!$B$53),投资与资金安排!$B$23*(1-核心参数输入!$B$54)/MAX(1,核心参数输入!$B$53),0),0) -> 0 | F20: =IF(F$4<=核心参数输入!$B$9,IF(AND(F$4-核心参数输入!$B$16>0,F$4-核心参数输入!$B$16<=核心参数输入!$B$53),投资与资金安排!$B$23*(1-核心参数输入!$B$54)/MAX(1,核心参数输入!$B$53),0),0) -> 0 | G20: =IF(G$4<=核心参数输入!$B$9,IF(AND(G$4-核心参数输入!$B$16>0,G$4-核心参数输入!$B$16<=核心参数输入!$B$53),投资与资金安排!$B$23*(1-核心参数输入!$B$54)/MAX(1,核心参数输入!$B$53),0),0) -> 0 | H20: =IF(H$4<=核心参数输入!$B$9,IF(AND(H$4-核心参数输入!$B$16>0,H$4-核心参数输入!$B$16<=核心参数输入!$B$53),投资与资金安排!$B$23*(1-核心参数输入!$B$54)/MAX(1,核心参数输入!$B$53),0),0) -> 781.0425 | I20: =IF(I$4<=核心参数输入!$B$9,IF(AND(I$4-核心参数输入!$B$16>0,I$4-核心参数输入!$B$16<=核心参数输入!$B$53),投资与资金安排!$B$23*(1-核心参数输入!$B$54)/MAX(1,核心参数输入!$B$53),0),0) -> 781.0425 | J20: =IF(J$4<=核心参数输入!$B$9,IF(AND(J$4-核心参数输入!$B$16>0,J$4-核心参数输入!$B$16<=核心参数输入!$B$53),投资与资金安排!$B$23*(1-核心参数输入!$B$54)/MAX(1,核心参数输入!$B$53),0),0) -> 781.0425 | K20: =IF(K$4<=核心参数输入!$B$9,IF(AND(K$4-核心参数输入!$B$16>0,K$4-核心参数输入!$B$16<=核心参数输入!$B$53),投资与资金安排!$B$23*(1-核心参数输入!$B$54)/MAX(1,核心参数输入!$B$53),0),0) -> 781.0425 | ... AH20: =IF(AH$4<=核心参数输入!$B$9,IF(AND(AH$4-核心参数输入!$B$16>0,AH$4-核心参数输入!$B$16<=核心参数输入!$B$53),投资与资金安排!$B$23*(1-核心参数输入!$B$54)/MAX(1,核心参数输入!$B$53),0),0) -> 0
A21: 持有处置前账面净值（项目） | B21: 万元 | D21: =IF(D$4<=核心参数输入!$B$9,(SUM(投资与资金安排!$D$28:D28)+SUM(投资与资金安排!$D$29:D29))*核心参数输入!$B$15-SUM($D19:D19),0) -> 3600 | E21: =IF(E$4<=核心参数输入!$B$9,(SUM(投资与资金安排!$D$28:E28)+SUM(投资与资金安排!$D$29:E29))*核心参数输入!$B$15-SUM($D19:E19),0) -> 10744.2 | F21: =IF(F$4<=核心参数输入!$B$9,(SUM(投资与资金安排!$D$28:F28)+SUM(投资与资金安排!$D$29:F29))*核心参数输入!$B$15-SUM($D19:F19),0) -> 20269.8 | G21: =IF(G$4<=核心参数输入!$B$9,(SUM(投资与资金安排!$D$28:G28)+SUM(投资与资金安排!$D$29:G29))*核心参数输入!$B$15-SUM($D19:G19),0) -> 27414 | H21: =IF(H$4<=核心参数输入!$B$9,(SUM(投资与资金安排!$D$28:H28)+SUM(投资与资金安排!$D$29:H29))*核心参数输入!$B$15-SUM($D19:H19),0) -> 26659.89 | I21: =IF(I$4<=核心参数输入!$B$9,(SUM(投资与资金安排!$D$28:I28)+SUM(投资与资金安排!$D$29:I29))*核心参数输入!$B$15-SUM($D19:I19),0) -> 25905.78 | J21: =IF(J$4<=核心参数输入!$B$9,(SUM(投资与资金安排!$D$28:J28)+SUM(投资与资金安排!$D$29:J29))*核心参数输入!$B$15-SUM($D19:J19),0) -> 25151.67 | K21: =IF(K$4<=核心参数输入!$B$9,(SUM(投资与资金安排!$D$28:K28)+SUM(投资与资金安排!$D$29:K29))*核心参数输入!$B$15-SUM($D19:K19),0) -> 24397.56 | ... AH21: =IF(AH$4<=核心参数输入!$B$9,(SUM(投资与资金安排!$D$28:AH28)+SUM(投资与资金安排!$D$29:AH29))*核心参数输入!$B$15-SUM($D19:AH19),0) -> 0
A22: 持有处置前账面净值（融资） | B22: 万元 | D22: =IF(D$4<=核心参数输入!$B$9,(SUM(投资与资金安排!$D$28:D28)+SUM(投资与资金安排!$D$29:D29)+SUM(融资与还本付息!$D$16:D16))*核心参数输入!$B$15-SUM($D20:D20),0) -> 3600 | E22: =IF(E$4<=核心参数输入!$B$9,(SUM(投资与资金安排!$D$28:E28)+SUM(投资与资金安排!$D$29:E29)+SUM(融资与还本付息!$D$16:E16))*核心参数输入!$B$15-SUM($D20:E20),0) -> 10829.25 | F22: =IF(F$4<=核心参数输入!$B$9,(SUM(投资与资金安排!$D$28:F28)+SUM(投资与资金安排!$D$29:F29)+SUM(融资与还本付息!$D$16:F16))*核心参数输入!$B$15-SUM($D20:F20),0) -> 20638.35 | G22: =IF(G$4<=核心参数输入!$B$9,(SUM(投资与资金安排!$D$28:G28)+SUM(投资与资金安排!$D$29:G29)+SUM(融资与还本付息!$D$16:G16))*核心参数输入!$B$15-SUM($D20:G20),0) -> 28264.5 | H22: =IF(H$4<=核心参数输入!$B$9,(SUM(投资与资金安排!$D$28:H28)+SUM(投资与资金安排!$D$29:H29)+SUM(融资与还本付息!$D$16:H16))*核心参数输入!$B$15-SUM($D20:H20),0) -> 27483.457 | I22: =IF(I$4<=核心参数输入!$B$9,(SUM(投资与资金安排!$D$28:I28)+SUM(投资与资金安排!$D$29:I29)+SUM(融资与还本付息!$D$16:I16))*核心参数输入!$B$15-SUM($D20:I20),0) -> 26702.415 | J22: =IF(J$4<=核心参数输入!$B$9,(SUM(投资与资金安排!$D$28:J28)+SUM(投资与资金安排!$D$29:J29)+SUM(融资与还本付息!$D$16:J16))*核心参数输入!$B$15-SUM($D20:J20),0) -> 25921.372 | K22: =IF(K$4<=核心参数输入!$B$9,(SUM(投资与资金安排!$D$28:K28)+SUM(投资与资金安排!$D$29:K29)+SUM(融资与还本付息!$D$16:K16))*核心参数输入!$B$15-SUM($D20:K20),0) -> 25140.33 | ... AH22: =IF(AH$4<=核心参数输入!$B$9,(SUM(投资与资金安排!$D$28:AH28)+SUM(投资与资金安排!$D$29:AH29)+SUM(融资与还本付息!$D$16:AH16))*核心参数输入!$B$15-SUM($D20:AH20),0) -> 0
A23: 期末未售开发存货（融资） | B23: 万元 | D23: =IF(D$4<=核心参数输入!$B$9,(SUM(投资与资金安排!$D$28:D28)+SUM(投资与资金安排!$D$29:D29)+SUM(融资与还本付息!$D$16:D16))*核心参数输入!$B$14-SUM($D18:D18),0) -> 4400 | E23: =IF(E$4<=核心参数输入!$B$9,(SUM(投资与资金安排!$D$28:E28)+SUM(投资与资金安排!$D$29:E29)+SUM(融资与还本付息!$D$16:E16))*核心参数输入!$B$14-SUM($D18:E18),0) -> 13235.75 | F23: =IF(F$4<=核心参数输入!$B$9,(SUM(投资与资金安排!$D$28:F28)+SUM(投资与资金安排!$D$29:F29)+SUM(融资与还本付息!$D$16:F16))*核心参数输入!$B$14-SUM($D18:F18),0) -> 25224.65 | G23: =IF(G$4<=核心参数输入!$B$9,(SUM(投资与资金安排!$D$28:G28)+SUM(投资与资金安排!$D$29:G29)+SUM(融资与还本付息!$D$16:G16))*核心参数输入!$B$14-SUM($D18:G18),0) -> 34545.5 | H23: =IF(H$4<=核心参数输入!$B$9,(SUM(投资与资金安排!$D$28:H28)+SUM(投资与资金安排!$D$29:H29)+SUM(融资与还本付息!$D$16:H16))*核心参数输入!$B$14-SUM($D18:H18),0) -> 24181.85 | I23: =IF(I$4<=核心参数输入!$B$9,(SUM(投资与资金安排!$D$28:I28)+SUM(投资与资金安排!$D$29:I29)+SUM(融资与还本付息!$D$16:I16))*核心参数输入!$B$14-SUM($D18:I18),0) -> 10363.65 | J23: =IF(J$4<=核心参数输入!$B$9,(SUM(投资与资金安排!$D$28:J28)+SUM(投资与资金安排!$D$29:J29)+SUM(融资与还本付息!$D$16:J16))*核心参数输入!$B$14-SUM($D18:J18),0) -> 0 | K23: =IF(K$4<=核心参数输入!$B$9,(SUM(投资与资金安排!$D$28:K28)+SUM(投资与资金安排!$D$29:K29)+SUM(融资与还本付息!$D$16:K16))*核心参数输入!$B$14-SUM($D18:K18),0) -> 0 | ... AH23: =IF(AH$4<=核心参数输入!$B$9,(SUM(投资与资金安排!$D$28:AH28)+SUM(投资与资金安排!$D$29:AH29)+SUM(融资与还本付息!$D$16:AH16))*核心参数输入!$B$14-SUM($D18:AH18),0) -> 0
A24: 期末处置损益（项目口径） | B24: 万元 | D24: =IF(D$4<=核心参数输入!$B$9,IF(AND(核心参数输入!$B$64=1,D$4=核心参数输入!$B$9),销售与出租收入!D26-D21,0),0) -> 0 | E24: =IF(E$4<=核心参数输入!$B$9,IF(AND(核心参数输入!$B$64=1,E$4=核心参数输入!$B$9),销售与出租收入!E26-E21,0),0) -> 0 | F24: =IF(F$4<=核心参数输入!$B$9,IF(AND(核心参数输入!$B$64=1,F$4=核心参数输入!$B$9),销售与出租收入!F26-F21,0),0) -> 0 | G24: =IF(G$4<=核心参数输入!$B$9,IF(AND(核心参数输入!$B$64=1,G$4=核心参数输入!$B$9),销售与出租收入!G26-G21,0),0) -> 0 | H24: =IF(H$4<=核心参数输入!$B$9,IF(AND(核心参数输入!$B$64=1,H$4=核心参数输入!$B$9),销售与出租收入!H26-H21,0),0) -> 0 | I24: =IF(I$4<=核心参数输入!$B$9,IF(AND(核心参数输入!$B$64=1,I$4=核心参数输入!$B$9),销售与出租收入!I26-I21,0),0) -> 0 | J24: =IF(J$4<=核心参数输入!$B$9,IF(AND(核心参数输入!$B$64=1,J$4=核心参数输入!$B$9),销售与出租收入!J26-J21,0),0) -> 0 | K24: =IF(K$4<=核心参数输入!$B$9,IF(AND(核心参数输入!$B$64=1,K$4=核心参数输入!$B$9),销售与出租收入!K26-K21,0),0) -> 0 | ... AH24: =IF(AH$4<=核心参数输入!$B$9,IF(AND(核心参数输入!$B$64=1,AH$4=核心参数输入!$B$9),销售与出租收入!AH26-AH21,0),0) -> 0
A25: 期末处置损益（融资口径） | B25: 万元 | D25: =IF(D$4<=核心参数输入!$B$9,IF(AND(核心参数输入!$B$64=1,D$4=核心参数输入!$B$9),销售与出租收入!D26-D22,0),0) -> 0 | E25: =IF(E$4<=核心参数输入!$B$9,IF(AND(核心参数输入!$B$64=1,E$4=核心参数输入!$B$9),销售与出租收入!E26-E22,0),0) -> 0 | F25: =IF(F$4<=核心参数输入!$B$9,IF(AND(核心参数输入!$B$64=1,F$4=核心参数输入!$B$9),销售与出租收入!F26-F22,0),0) -> 0 | G25: =IF(G$4<=核心参数输入!$B$9,IF(AND(核心参数输入!$B$64=1,G$4=核心参数输入!$B$9),销售与出租收入!G26-G22,0),0) -> 0 | H25: =IF(H$4<=核心参数输入!$B$9,IF(AND(核心参数输入!$B$64=1,H$4=核心参数输入!$B$9),销售与出租收入!H26-H22,0),0) -> 0 | I25: =IF(I$4<=核心参数输入!$B$9,IF(AND(核心参数输入!$B$64=1,I$4=核心参数输入!$B$9),销售与出租收入!I26-I22,0),0) -> 0 | J25: =IF(J$4<=核心参数输入!$B$9,IF(AND(核心参数输入!$B$64=1,J$4=核心参数输入!$B$9),销售与出租收入!J26-J22,0),0) -> 0 | K25: =IF(K$4<=核心参数输入!$B$9,IF(AND(核心参数输入!$B$64=1,K$4=核心参数输入!$B$9),销售与出租收入!K26-K22,0),0) -> 0 | ... AH25: =IF(AH$4<=核心参数输入!$B$9,IF(AND(核心参数输入!$B$64=1,AH$4=核心参数输入!$B$9),销售与出租收入!AH26-AH22,0),0) -> 0
