Workbook
Name V3ChartCash: 决策看板!$D$81:INDEX(决策看板!$D$81:$D$111,核心参数输入!$B$9+1)
Name V3ChartCFADS: 决策看板!$B$81:INDEX(决策看板!$B$81:$B$111,核心参数输入!$B$9+1)
Name V3ChartDistribution: 决策看板!$G$81:INDEX(决策看板!$G$81:$G$111,核心参数输入!$B$9+1)
Name V3ChartEquity: 决策看板!$F$81:INDEX(决策看板!$F$81:$F$111,核心参数输入!$B$9+1)
Name V3ChartGap: 决策看板!$E$81:INDEX(决策看板!$E$81:$E$111,核心参数输入!$B$9+1)
Name V3ChartService: 决策看板!$C$81:INDEX(决策看板!$C$81:$C$111,核心参数输入!$B$9+1)
Name V3ChartYear: 决策看板!$A$81:INDEX(决策看板!$A$81:$A$111,核心参数输入!$B$9+1)

Sheet 决策看板
A2: 决策看板 · V3模拟测算
A4: =IF(OR(指标与情景!B49=0,AND(核心参数输入!$B$82=1,指标与情景!E49=0)),"待判断：输入或计划条件无效",IF(AND(指标与情景!B50=1,OR(核心参数输入!$B$82=0,指标与情景!E50=1)),IF(核心参数输入!$B$97=1,"已纳入模型的财务条件达标","财务条件达标；新增假设待项目核对"),"已纳入模型的财务条件未全部达标")) -> 已纳入模型的财务条件未全部达标
A7: 项目名称 | B7: =核心参数输入!$B$7 -> 模拟产业园 · 租售结合 | E7: 经营模式 | F7: =核心参数输入!$B$149 -> 租售结合
A8: 当前期末口径 | B8: =IF(核心参数输入!$B$64=1,"期末出售持有物业","持续持有观察期") -> 持续持有观察期 | E8: 测算期限（年） | F8: =核心参数输入!$B$9 -> 20
A9: 总投资（万元） | B9: =指标与情景!B16 -> 63310 | E9: 既定贷款（万元） | F9: =核心参数输入!$B$57 -> 30000
A10: 所需累计资本金（万元） | B10: =指标与情景!B13 -> 32810 | E10: 资本金额度（万元） | F10: =核心参数输入!$B$61 -> 33000
A11: 最大未落实缺口（万元） | B11: =指标与情景!B14 -> 0 | E11: 缺口发生季度 | F11: =指标与情景!B31 -> 无未落实缺口
A12: 融资前峰值需要（万元） | B12: =指标与情景!B29 -> 62810 | E12: 峰值发生季度 | F12: =指标与情景!B30 -> 2029Q4
A13: 理论最大留存现金（万元） | B13: =指标与情景!B47 -> 15161.955 | E13: 收益口径 | F13: =指标与情景!B27 -> 完整出资、留存后分配口径
A15: =核心参数输入!$B$152&"；季度计算、年度汇总；"&指标与情景!B54 -> 综合税费率（沿用V2）；季度计算、年度汇总；新增假设待项目核对
A17: 指标／资金约束 | B17: 基准 | C17: 单位 | D17: 阈值 | E17: 压力 | F17: 基准状态 | G17: 压力状态
A18: 项目税后IRR（年化） | B18: =指标与情景!B6 -> -0.014445335 | C18: =指标与情景!C6 -> % | D18: =指标与情景!D6 -> 0.08 | E18: =指标与情景!E6 -> -0.049549603 | F18: =指标与情景!F6 -> 未通过 | G18: =指标与情景!G6 -> 未通过
A19: 资本金IRR（年化） | B19: =指标与情景!B7 -> -0.040676665 | C19: =指标与情景!C7 -> % | D19: =指标与情景!D7 -> 0.1 | E19: =指标与情景!E7 -> -0.087463531 | F19: =指标与情景!F7 -> 未通过 | G19: =指标与情景!G7 -> 未通过
A20: 项目NPV | B20: =指标与情景!B8 -> -20406.095 | C20: =指标与情景!C8 -> 万元 | D20: =指标与情景!D8 -> 0 | E20: =指标与情景!E8 -> -28525.14 | F20: =指标与情景!F8 -> 未通过 | G20: =指标与情景!G8 -> 未通过
A21: 资本金NPV | B21: =指标与情景!B9 -> -18467.837 | C21: =指标与情景!C9 -> 万元 | D21: =指标与情景!D9 -> 0 | E21: =指标与情景!E9 -> -27195.962 | F21: =指标与情景!F9 -> 未通过 | G21: =指标与情景!G9 -> 未通过
A22: 静态投资回收期 | B22: =指标与情景!B10 -> 测算期内未回收 | C22: =指标与情景!C10 -> 年 | D22: =指标与情景!D10 -> 15 | E22: =指标与情景!E10 -> 测算期内未回收 | F22: =指标与情景!F10 -> 未通过 | G22: =指标与情景!G10 -> 未通过
A23: 动态投资回收期 | B23: =指标与情景!B11 -> 测算期内未回收 | C23: =指标与情景!C11 -> 年 | D23: =指标与情景!D11 -> 20 | E23: =指标与情景!E11 -> 测算期内未回收 | F23: =指标与情景!F11 -> 未通过 | G23: =指标与情景!G11 -> 未通过
A24: 最低年度经营DSCR | B24: =指标与情景!B12 -> 0.21197153 | C24: =指标与情景!C12 -> 倍 | D24: =指标与情景!D12 -> 1.2 | E24: =指标与情景!E12 -> 0.14850575 | F24: =指标与情景!F12 -> 未通过 | G24: =指标与情景!G12 -> 未通过
A25: 所需累计资本金 | B25: =指标与情景!B13 -> 32810 | C25: =指标与情景!C13 -> 万元 | D25: =指标与情景!D13 -> 33000 | E25: =指标与情景!E13 -> 38102 | F25: =指标与情景!F13 -> 通过 | G25: =指标与情景!G13 -> 未通过
A26: 最大未落实资金缺口 | B26: =指标与情景!B14 -> 0 | C26: =指标与情景!C14 -> 万元 | D26: =指标与情景!D14 -> 0 | E26: =指标与情景!E14 -> 5102 | F26: =指标与情景!F14 -> 通过 | G26: =指标与情景!G14 -> 未通过
A27: 到期计划本金余额 | B27: =指标与情景!B15 -> 0 | C27: =指标与情景!C15 -> 万元 | D27: =指标与情景!D15 -> 0 | E27: =指标与情景!E15 -> 0 | F27: =指标与情景!F15 -> 通过 | G27: =指标与情景!G15 -> 通过
A29: 持续持有与期末出售（同一经营、融资假设）
A30: 指标 | B30: 持续持有 | D30: 期末出售 | F30: 说明
A31: 项目IRR | B31: =指标与情景!B38 -> -0.014445335 | D31: =指标与情景!B39 -> 0.033744637 | F31: %
A32: 项目NPV | B32: =指标与情景!B40 -> -20406.095 | D32: =指标与情景!B41 -> -14899.172 | F32: 万元
A33: 资本金IRR | B33: =指标与情景!B42 -> -0.040676665 | D33: =指标与情景!B43 -> 0.030390403 | F33: %
A35: 最低经营DSCR发生年度 | B35: =指标与情景!B48 -> 2034 | E35: 稳定经营现金保本出租率 | F35: =指标与情景!B22 -> 0.29842494
A36: 期末销售应收（万元） | B36: =指标与情景!B34 -> 0 | E36: 持续持有账面净值（万元） | F36: =指标与情景!B45 -> 13762.777
A37: 累计净利润（万元） | B37: =指标与情景!B35 -> 4193.6056 | E37: 精确边界刷新状态 | F37: =敏感性与边界!B66 -> 与当前参数一致
A39: ="经营DSCR衡量当年经营现金；前期销售留存另行支持偿债。"&IF(指标与情景!B14>0.01," 存在未落实缺口，当前计划不能视为已执行。","")&" "&指标与情景!B25 -> 经营DSCR衡量当年经营现金；前期销售留存另行支持偿债。 单次变号或无变号
A41: ="所选季度月内最大缺口（万元）："&TEXT(关键月份核对!B33,"#,##0.00")&IF(关键月份核对!B35=1,"；该季度月度安排通过","；月度安排需调整") -> 所选季度月内最大缺口（万元）：0.00；该季度月度安排通过
A80: 项目年 | B80: 经营CFADS | C80: 合同本息 | D80: 年末留存 | E80: 未落实缺口 | F80: 所需股东出资 | G80: 股东分配 | H80: 累计项目现金
A81: =IF(0<=核心参数输入!$B$9,0,"") -> 0 | B81: =IF(0<=核心参数输入!$B$9,年度汇总!D22,"") -> 0 | C81: =IF(0<=核心参数输入!$B$9,年度汇总!D23,"") -> 0 | D81: =IF(0<=核心参数输入!$B$9,年度汇总!D29,"") -> 0 | E81: =IF(0<=核心参数输入!$B$9,年度汇总!D30,"") -> 0 | F81: =IF(0<=核心参数输入!$B$9,年度汇总!D27,"") -> 8000 | G81: =IF(0<=核心参数输入!$B$9,年度汇总!D28,"") -> 0 | H81: =IF(0<=核心参数输入!$B$9,年度汇总!D33,"") -> -8000
A82: =IF(1<=核心参数输入!$B$9,1,"") -> 1 | B82: =IF(1<=核心参数输入!$B$9,年度汇总!E22,"") -> 0 | C82: =IF(1<=核心参数输入!$B$9,年度汇总!E23,"") -> 177.1875 | D82: =IF(1<=核心参数输入!$B$9,年度汇总!E29,"") -> 0 | E82: =IF(1<=核心参数输入!$B$9,年度汇总!E30,"") -> 0 | F82: =IF(1<=核心参数输入!$B$9,年度汇总!E27,"") -> 7065 | G82: =IF(1<=核心参数输入!$B$9,年度汇总!E28,"") -> 0 | H82: =IF(1<=核心参数输入!$B$9,年度汇总!E33,"") -> -23876
A83: =IF(2<=核心参数输入!$B$9,2,"") -> 2 | B83: =IF(2<=核心参数输入!$B$9,年度汇总!F22,"") -> 0 | C83: =IF(2<=核心参数输入!$B$9,年度汇总!F23,"") -> 630 | D83: =IF(2<=核心参数输入!$B$9,年度汇总!F29,"") -> 0 | E83: =IF(2<=核心参数输入!$B$9,年度汇总!F30,"") -> 0 | F83: =IF(2<=核心参数输入!$B$9,年度汇总!F27,"") -> 9798 | G83: =IF(2<=核心参数输入!$B$9,年度汇总!F28,"") -> 0 | H83: =IF(2<=核心参数输入!$B$9,年度汇总!F33,"") -> -45044
A84: =IF(3<=核心参数输入!$B$9,3,"") -> 3 | B84: =IF(3<=核心参数输入!$B$9,年度汇总!G22,"") -> 0 | C84: =IF(3<=核心参数输入!$B$9,年度汇总!G23,"") -> 1071 | D84: =IF(3<=核心参数输入!$B$9,年度汇总!G29,"") -> 0 | E84: =IF(3<=核心参数输入!$B$9,年度汇总!G30,"") -> 0 | F84: =IF(3<=核心参数输入!$B$9,年度汇总!G27,"") -> 7947 | G84: =IF(3<=核心参数输入!$B$9,年度汇总!G28,"") -> 0 | H84: =IF(3<=核心参数输入!$B$9,年度汇总!G33,"") -> -60920
A85: =IF(4<=核心参数输入!$B$9,4,"") -> 4 | B85: =IF(4<=核心参数输入!$B$9,年度汇总!H22,"") -> 11554.939 | C85: =IF(4<=核心参数输入!$B$9,年度汇总!H23,"") -> 5523.2143 | D85: =IF(4<=核心参数输入!$B$9,年度汇总!H29,"") -> 0 | E85: =IF(4<=核心参数输入!$B$9,年度汇总!H30,"") -> 0 | F85: =IF(4<=核心参数输入!$B$9,年度汇总!H27,"") -> 0 | G85: =IF(4<=核心参数输入!$B$9,年度汇总!H28,"") -> 5531.7249 | H85: =IF(4<=核心参数输入!$B$9,年度汇总!H33,"") -> -50259.131
A86: =IF(5<=核心参数输入!$B$9,5,"") -> 5 | B86: =IF(5<=核心参数输入!$B$9,年度汇总!I22,"") -> 16821.455 | C86: =IF(5<=核心参数输入!$B$9,年度汇总!I23,"") -> 5343.2143 | D86: =IF(5<=核心参数输入!$B$9,年度汇总!I29,"") -> 5240.8689 | E86: =IF(5<=核心参数输入!$B$9,年度汇总!I30,"") -> 0 | F86: =IF(5<=核心参数输入!$B$9,年度汇总!I27,"") -> 0 | G86: =IF(5<=核心参数输入!$B$9,年度汇总!I28,"") -> 6237.3722 | H86: =IF(5<=核心参数输入!$B$9,年度汇总!I33,"") -> -33812.734
A87: =IF(6<=核心参数输入!$B$9,6,"") -> 6 | B87: =IF(6<=核心参数输入!$B$9,年度汇总!J22,"") -> 13643.414 | C87: =IF(6<=核心参数输入!$B$9,年度汇总!J23,"") -> 5163.2143 | D87: =IF(6<=核心参数输入!$B$9,年度汇总!J29,"") -> 13721.069 | E87: =IF(6<=核心参数输入!$B$9,年度汇总!J30,"") -> 0 | F87: =IF(6<=核心参数输入!$B$9,年度汇总!J27,"") -> 0 | G87: =IF(6<=核心参数输入!$B$9,年度汇总!J28,"") -> 0 | H87: =IF(6<=核心参数输入!$B$9,年度汇总!J33,"") -> -20473.391
A88: =IF(7<=核心参数输入!$B$9,7,"") -> 7 | B88: =IF(7<=核心参数输入!$B$9,年度汇总!K22,"") -> 2022.6792 | C88: =IF(7<=核心参数输入!$B$9,年度汇总!K23,"") -> 4983.2143 | D88: =IF(7<=核心参数输入!$B$9,年度汇总!K29,"") -> 10760.534 | E88: =IF(7<=核心参数输入!$B$9,年度汇总!K30,"") -> 0 | F88: =IF(7<=核心参数输入!$B$9,年度汇总!K27,"") -> 0 | G88: =IF(7<=核心参数输入!$B$9,年度汇总!K28,"") -> 0 | H88: =IF(7<=核心参数输入!$B$9,年度汇总!K33,"") -> -18478.377
...

Sheet 核心参数输入
A2: 核心参数输入 · V3模拟测算
A5: 参数 | B5: 输入值 | C5: 单位 | D5: 口径、来源与状态
A6: 基础与建筑参数
A7: 项目名称 | B7: 模拟产业园 · 租售结合 | C7: 文本 | D7: 全部数据为虚构模拟数据 | L7: V2保存参数
A8: 测算起始年份 | B8: 2026 | C8: 年 | D8: 第0年的日历年份；年度支出采用年末时点 | L8: V2保存参数
A9: 测算期限 | B9: 20 | C9: 年 | D9: 实际范围第0年至第N年，预留至30年；须覆盖贷款到期 | L9: V2保存参数
A10: 土地面积 | B10: 100000 | C10: 平方米 | D10: 地上面积＝土地面积×容积率 | L10: V2保存参数
A11: 容积率 | B11: 1.5 | C11: 倍 | D11: 地上总建筑面积口径 | L11: V2保存参数
A12: 地上可经营面积占比 | B12: 0.9 | C12: % | D12: 其余为公共及非经营空间；共同成本仍计入 | L12: V2保存参数
A13: 地下建筑面积 | B13: 15000 | C13: 平方米 | D13: 地下空间不独立产生收入 | L13: V2保存参数
A14: 可经营面积销售占比 | B14: 0.55 | C14: % | D14: 混合模式使用；纯出售／纯持有由B95切换，原55%示意值保留 | L14: V2保存参数
A15: 实际出租占比（模式后） | B15: =核心参数输入!$B$143 -> 0.45 | C15: % | D15: 自动＝1－销售占比 | L15: V2保存参数
A16: 建设年限 | B16: 3 | C16: 年 | D16: 第1年至第K年；土地在第0年支付 | L16: V2保存参数
A17: 销售开始年份 | B17: 4 | C17: 项目第几年 | D17: 必须晚于建设完成年；年度销售比例在下方输入 | L17: V2保存参数
A18: 出租开始年份 | B18: 4 | C18: 项目第几年 | D18: 必须晚于建设完成年；运营固定成本从K+1年开始 | L18: V2保存参数
A20: 投资参数
A21: 土地单价 | B21: 800 | C21: 元/平方米 | D21: 仅土地取得价款；不计入建筑折旧 | L21: V2保存参数
A22: 地上单方建安成本 | B22: 2400 | C22: 元/平方米 | D22: 不含下列配套、前期、管理费用 | L22: V2保存参数
A23: 地下单方建安成本 | B23: 3000 | C23: 元/平方米 | D23: 地下工程；不与地上重复 | L23: V2保存参数
A24: 园区配套工程费用 | B24: 4500 | C24: 万元 | D24: 园区道路、管网、公共配套；不含建安主体 | L24: V2保存参数
A25: 勘察设计咨询前期费用 | B25: 1800 | C25: 万元 | D25: 不含建安及管理费用 | L25: V2保存参数
A26: 管理及其他建设费用 | B26: 2200 | C26: 万元 | D26: 建设管理等；不含融资利息和运营成本 | L26: V2保存参数
A27: 预备费比例 | B27: 0.08 | C27: % | D27: 基数＝全部非土地建设费用（建安、配套、前期、管理） | L27: V2保存参数
A28: 初始运营周转资金 | B28: 500 | C28: 万元 | D28: K+1年投入，期末全额回收；不计入费用及折旧 | L28: V2保存参数
A30: 销售参数
A31: 销售均价 | B31: 6500 | C31: 元/平方米 | D31: 简化含税成交/实收口径；销售当年全额收款 | L31: V2保存参数
A32: 销售费用率 | B32: 0.025 | C32: % | D32: 销售回款×费用率 | L32: V2保存参数
A33: 简化销售相关税费率 | B33: 0.08 | C33: % | D33: 含税回款×综合率；不另行建立增值税抵扣 | L33: V2保存参数
A35: 出租参数
A36: 初始月租金 | B36: 26 | C36: 元/平方米/月 | D36: 出租首年价格；按12个月换算后除10000为万元 | L36: V2保存参数
A37: 年租金增长率 | B37: 0.015 | C37: % | D37: 从出租开始年递增 | L37: V2保存参数
A38: 出租第1年出租率 | B38: 0.5 | C38: % | D38: 第1个出租年度年末目标；V3按季内入驻位置形成平均面积 | L38: V2保存参数
A39: 出租第2年出租率 | B39: 0.7 | C39: % | D39: 第2个出租年度年末目标 | L39: V2保存参数
A40: 出租第3年出租率 | B40: 0.85 | C40: % | D40: 第3个出租年度年末目标 | L40: V2保存参数
A41: 第4年起稳定出租率 | B41: 0.9 | C41: % | D41: 第4出租年末及以后目标；不模拟租户更替 | L41: V2保存参数
A42: 新增出租面积平均免租月数 | B42: 3 | C42: 月 | D42: 0—12月；同一面积不重复免租 | L42: V2保存参数
A43: 租金收缴率 | B43: 0.98 | C43: % | D43: 实收租金，同时作为简化收入确认口径 | L43: V2保存参数
A44: 其他经营收入比例 | B44: 0.05 | C44: % | D44: 实收租金×比例；属于持有经营收入 | L44: V2保存参数
A46: 运营与税费
A47: 运营首年固定成本 | B47: 300 | C47: 万元/年 | D47: 仅持有部分：人员、管理、保险等；K+1年即承担 | L47: V2保存参数
...

Sheet 指标与情景
A2: 指标与情景 · V3模拟测算
A4: 指标 | B4: 基准 | C4: 单位 | D4: 阈值 | E4: 组合压力 | F4: 基准状态 | G4: 压力状态
A6: 项目税后IRR（年化） | B6: =IF(AND(COUNTIFS(季度现金流!$D$45:INDEX(季度现金流!$D$45:$DT$45,1,核心参数输入!$B$9*4+1),"<0")>0,COUNTIFS(季度现金流!$D$45:INDEX(季度现金流!$D$45:$DT$45,1,核心参数输入!$B$9*4+1),">0")>0),IFERROR((1+IRR(季度现金流!$D$45:INDEX(季度现金流!$D$45:$DT$45,1,核心参数输入!$B$9*4+1)))^4-1,"无法计算"),"无法计算") -> -0.014445335 | C6: % | D6: =核心参数输入!$B$69 -> 0.08 | E6: =IF(AND(COUNTIFS(季度现金流!$D$155:INDEX(季度现金流!$D$155:$DT$155,1,核心参数输入!$B$9*4+1),"<0")>0,COUNTIFS(季度现金流!$D$155:INDEX(季度现金流!$D$155:$DT$155,1,核心参数输入!$B$9*4+1),">0")>0),IFERROR((1+IRR(季度现金流!$D$155:INDEX(季度现金流!$D$155:$DT$155,1,核心参数输入!$B$9*4+1)))^4-1,"无法计算"),"无法计算") -> -0.049549603 | F6: =IF(B6="不适用","未通过",IF(NOT(ISNUMBER(B6)),IF(B6="无法计算","待判断","未通过"),IF(B6>=D6,"通过","未通过"))) -> 未通过 | G6: =IF(E6="不适用","未通过",IF(NOT(ISNUMBER(E6)),IF(E6="无法计算","待判断","未通过"),IF(E6>=D6,"通过","未通过"))) -> 未通过 | H6: 季度IRR按(1+r)^4－1年化；只取第0季至第N年末
A7: 资本金IRR（年化） | B7: =IF(AND(COUNTIFS(季度现金流!$D$47:INDEX(季度现金流!$D$47:$DT$47,1,核心参数输入!$B$9*4+1),"<0")>0,COUNTIFS(季度现金流!$D$47:INDEX(季度现金流!$D$47:$DT$47,1,核心参数输入!$B$9*4+1),">0")>0),IFERROR((1+IRR(季度现金流!$D$47:INDEX(季度现金流!$D$47:$DT$47,1,核心参数输入!$B$9*4+1)))^4-1,"无法计算"),"无法计算") -> -0.040676665 | C7: % | D7: =核心参数输入!$B$70 -> 0.1 | E7: =IF(AND(COUNTIFS(季度现金流!$D$157:INDEX(季度现金流!$D$157:$DT$157,1,核心参数输入!$B$9*4+1),"<0")>0,COUNTIFS(季度现金流!$D$157:INDEX(季度现金流!$D$157:$DT$157,1,核心参数输入!$B$9*4+1),">0")>0),IFERROR((1+IRR(季度现金流!$D$157:INDEX(季度现金流!$D$157:$DT$157,1,核心参数输入!$B$9*4+1)))^4-1,"无法计算"),"无法计算") -> -0.087463531 | F7: =IF(B7="不适用","未通过",IF(NOT(ISNUMBER(B7)),IF(B7="无法计算","待判断","未通过"),IF(B7>=D7,"通过","未通过"))) -> 未通过 | G7: =IF(E7="不适用","未通过",IF(NOT(ISNUMBER(E7)),IF(E7="无法计算","待判断","未通过"),IF(E7>=D7,"通过","未通过"))) -> 未通过 | H7: 完整出资并预留后续资金后的分配；不代表未落实资金已到位
A8: 项目NPV | B8: =NPV((1+核心参数输入!$B$71)^(1/4)-1,季度现金流!$E$45:INDEX(季度现金流!$D$45:$DT$45,1,核心参数输入!$B$9*4+1))+季度现金流!D45 -> -20406.095 | C8: 万元 | D8: =0 -> 0 | E8: =NPV((1+核心参数输入!$B$71)^(1/4)-1,季度现金流!$E$155:INDEX(季度现金流!$D$155:$DT$155,1,核心参数输入!$B$9*4+1))+季度现金流!D155 -> -28525.14 | F8: =IF(B8="不适用","未通过",IF(NOT(ISNUMBER(B8)),IF(B8="无法计算","待判断","未通过"),IF(B8>=D8,"通过","未通过"))) -> 未通过 | G8: =IF(E8="不适用","未通过",IF(NOT(ISNUMBER(E8)),IF(E8="无法计算","待判断","未通过"),IF(E8>=D8,"通过","未通过"))) -> 未通过 | H8: 按年折现率换算季度有效利率，第0季不折现
A9: 资本金NPV | B9: =NPV((1+核心参数输入!$B$72)^(1/4)-1,季度现金流!$E$47:INDEX(季度现金流!$D$47:$DT$47,1,核心参数输入!$B$9*4+1))+季度现金流!D47 -> -18467.837 | C9: 万元 | D9: =0 -> 0 | E9: =NPV((1+核心参数输入!$B$72)^(1/4)-1,季度现金流!$E$157:INDEX(季度现金流!$D$157:$DT$157,1,核心参数输入!$B$9*4+1))+季度现金流!D157 -> -27195.962 | F9: =IF(B9="不适用","未通过",IF(NOT(ISNUMBER(B9)),IF(B9="无法计算","待判断","未通过"),IF(B9>=D9,"通过","未通过"))) -> 未通过 | G9: =IF(E9="不适用","未通过",IF(NOT(ISNUMBER(E9)),IF(E9="无法计算","待判断","未通过"),IF(E9>=D9,"通过","未通过"))) -> 未通过
A10: 静态投资回收期 | B10: =IF(COUNTIFS(季度现金流!$D$45:INDEX(季度现金流!$D$45:$DT$45,1,核心参数输入!$B$9*4+1),"<0")=0,"不适用",IF(COUNTIFS(季度现金流!$D$71:INDEX(季度现金流!$D$71:$DT$71,1,核心参数输入!$B$9*4+1),1)=0,"测算期内未回收",(MATCH(1,季度现金流!$D$71:INDEX(季度现金流!$D$71:$DT$71,1,核心参数输入!$B$9*4+1),0)-2-INDEX(季度现金流!$D$68:$DT$68,1,MAX(1,MATCH(1,季度现金流!$D$71:INDEX(季度现金流!$D$71:$DT$71,1,核心参数输入!$B$9*4+1),0)-1))/INDEX(季度现金流!$D$45:$DT$45,1,MATCH(1,季度现金流!$D$71:INDEX(季度现金流!$D$71:$DT$71,1,核心参数输入!$B$9*4+1),0)))/4)) -> 测算期内未回收 | C10: 年 | D10: =核心参数输入!$B$73 -> 15 | E10: =IF(COUNTIFS(季度现金流!$D$155:INDEX(季度现金流!$D$155:$DT$155,1,核心参数输入!$B$9*4+1),"<0")=0,"不适用",IF(COUNTIFS(季度现金流!$D$181:INDEX(季度现金流!$D$181:$DT$181,1,核心参数输入!$B$9*4+1),1)=0,"测算期内未回收",(MATCH(1,季度现金流!$D$181:INDEX(季度现金流!$D$181:$DT$181,1,核心参数输入!$B$9*4+1),0)-2-INDEX(季度现金流!$D$178:$DT$178,1,MAX(1,MATCH(1,季度现金流!$D$181:INDEX(季度现金流!$D$181:$DT$181,1,核心参数输入!$B$9*4+1),0)-1))/INDEX(季度现金流!$D$155:$DT$155,1,MATCH(1,季度现金流!$D$181:INDEX(季度现金流!$D$181:$DT$181,1,核心参数输入!$B$9*4+1),0)))/4)) -> 测算期内未回收 | F10: =IF(B10="不适用","未通过",IF(NOT(ISNUMBER(B10)),IF(B10="无法计算","待判断","未通过"),IF(B10<=D10,"通过","未通过"))) -> 未通过 | G10: =IF(E10="不适用","未通过",IF(NOT(ISNUMBER(E10)),IF(E10="无法计算","待判断","未通过"),IF(E10<=D10,"通过","未通过"))) -> 未通过 | H10: 首次跨零、季内线性插值；若以后再次转负需另审视
A11: 动态投资回收期 | B11: =IF(COUNTIFS(季度现金流!$D$69:INDEX(季度现金流!$D$69:$DT$69,1,核心参数输入!$B$9*4+1),"<0")=0,"不适用",IF(COUNTIFS(季度现金流!$D$72:INDEX(季度现金流!$D$72:$DT$72,1,核心参数输入!$B$9*4+1),1)=0,"测算期内未回收",(MATCH(1,季度现金流!$D$72:INDEX(季度现金流!$D$72:$DT$72,1,核心参数输入!$B$9*4+1),0)-2-INDEX(季度现金流!$D$70:$DT$70,1,MAX(1,MATCH(1,季度现金流!$D$72:INDEX(季度现金流!$D$72:$DT$72,1,核心参数输入!$B$9*4+1),0)-1))/INDEX(季度现金流!$D$69:$DT$69,1,MATCH(1,季度现金流!$D$72:INDEX(季度现金流!$D$72:$DT$72,1,核心参数输入!$B$9*4+1),0)))/4)) -> 测算期内未回收 | C11: 年 | D11: =核心参数输入!$B$74 -> 20 | E11: =IF(COUNTIFS(季度现金流!$D$179:INDEX(季度现金流!$D$179:$DT$179,1,核心参数输入!$B$9*4+1),"<0")=0,"不适用",IF(COUNTIFS(季度现金流!$D$182:INDEX(季度现金流!$D$182:$DT$182,1,核心参数输入!$B$9*4+1),1)=0,"测算期内未回收",(MATCH(1,季度现金流!$D$182:INDEX(季度现金流!$D$182:$DT$182,1,核心参数输入!$B$9*4+1),0)-2-INDEX(季度现金流!$D$180:$DT$180,1,MAX(1,MATCH(1,季度现金流!$D$182:INDEX(季度现金流!$D$182:$DT$182,1,核心参数输入!$B$9*4+1),0)-1))/INDEX(季度现金流!$D$179:$DT$179,1,MATCH(1,季度现金流!$D$182:INDEX(季度现金流!$D$182:$DT$182,1,核心参数输入!$B$9*4+1),0)))/4)) -> 测算期内未回收 | F11: =IF(B11="不适用","未通过",IF(NOT(ISNUMBER(B11)),IF(B11="无法计算","待判断","未通过"),IF(B11<=D11,"通过","未通过"))) -> 未通过 | G11: =IF(E11="不适用","未通过",IF(NOT(ISNUMBER(E11)),IF(E11="无法计算","待判断","未通过"),IF(E11<=D11,"通过","未通过"))) -> 未通过
A12: 最低年度经营DSCR | B12: =IF(核心参数输入!$B$57=0,"不适用",IF(COUNT(年度汇总!$D$24:$AH$24)=0,"无法计算",MIN(年度汇总!$D$42:$AH$42))) -> 0.21197153 | C12: 倍 | D12: =核心参数输入!$B$75 -> 1.2 | E12: =IF(核心参数输入!$B$57=0,"不适用",IF(COUNT(年度汇总!$D$84:$AH$84)=0,"无法计算",MIN(年度汇总!$D$102:$AH$102))) -> 0.14850575 | F12: =IF(B12="不适用","通过",IF(NOT(ISNUMBER(B12)),IF(B12="无法计算","待判断","未通过"),IF(B12>=D12,"通过","未通过"))) -> 未通过 | G12: =IF(E12="不适用","通过",IF(NOT(ISNUMBER(E12)),IF(E12="无法计算","待判断","未通过"),IF(E12>=D12,"通过","未通过"))) -> 未通过 | H12: 按年度CFADS／年度合同本息；季度覆盖另见现金流表
A13: 所需累计资本金 | B13: =SUM(季度现金流!$D$49:INDEX(季度现金流!$D$49:$DT$49,1,核心参数输入!$B$9*4+1)) -> 32810 | C13: 万元 | D13: =核心参数输入!$B$61 -> 33000 | E13: =SUM(季度现金流!$D$159:INDEX(季度现金流!$D$159:$DT$159,1,核心参数输入!$B$9*4+1)) -> 38102 | F13: =IF(B13="不适用","未通过",IF(NOT(ISNUMBER(B13)),IF(B13="无法计算","待判断","未通过"),IF(B13<=D13+0.01,"通过","未通过"))) -> 通过 | G13: =IF(E13="不适用","未通过",IF(NOT(ISNUMBER(E13)),IF(E13="无法计算","待判断","未通过"),IF(E13<=D13+0.01,"通过","未通过"))) -> 未通过
A14: 最大未落实资金缺口 | B14: =MAX(季度现金流!$D$58:INDEX(季度现金流!$D$58:$DT$58,1,核心参数输入!$B$9*4+1)) -> 0 | C14: 万元 | D14: =0 -> 0 | E14: =MAX(季度现金流!$D$168:INDEX(季度现金流!$D$168:$DT$168,1,核心参数输入!$B$9*4+1)) -> 5102 | F14: =IF(B14="不适用","未通过",IF(NOT(ISNUMBER(B14)),IF(B14="无法计算","待判断","未通过"),IF(ABS(B14)<=0.01,"通过","未通过"))) -> 通过 | G14: =IF(E14="不适用","未通过",IF(NOT(ISNUMBER(E14)),IF(E14="无法计算","待判断","未通过"),IF(ABS(E14)<=0.01,"通过","未通过"))) -> 未通过
A15: 到期计划本金余额 | B15: =IF(核心参数输入!$B$57=0,0,IF(季度投融资!$B$29>核心参数输入!$B$9*4,"无法计算",INDEX(季度投融资!$D$43:$DT$43,1,MIN(121,季度投融资!$B$29+1)))) -> 0 | C15: 万元 | D15: =0 -> 0 | E15: =IF(核心参数输入!$B$57=0,0,IF(季度投融资!$E$29>核心参数输入!$B$9*4,"无法计算",INDEX(季度投融资!$D$153:$DT$153,1,MIN(121,季度投融资!$E$29+1)))) -> 0 | F15: =IF(B15="不适用","未通过",IF(NOT(ISNUMBER(B15)),IF(B15="无法计算","待判断","未通过"),IF(ABS(B15)<=0.01,"通过","未通过"))) -> 通过 | G15: =IF(E15="不适用","未通过",IF(NOT(ISNUMBER(E15)),IF(E15="无法计算","待判断","未通过"),IF(ABS(E15)<=0.01,"通过","未通过"))) -> 通过 | H15: 合同计划还款后的余额，不等于实际已经偿还
A16: 总投资含建设期融资费用 | B16: =季度投融资!$B$21 -> 63310 | C16: 万元 | E16: =季度投融资!$E$21 -> 68602
A17: 既定贷款额度 | B17: =核心参数输入!$B$57 -> 30000 | C17: 万元 | E17: =核心参数输入!$B$57 -> 30000
A18: 可投入资本金额度 | B18: =核心参数输入!$B$61 -> 33000 | C18: 万元 | E18: =核心参数输入!$B$61 -> 33000
A19: 测算期销售交付比例 | B19: =SUM(季度计划!$D$15:INDEX(季度计划!$D$15:$DT$15,1,核心参数输入!$B$9*4+1)) -> 1 | C19: % | E19: =SUM(季度计划!$D$125:INDEX(季度计划!$D$125:$DT$125,1,核心参数输入!$B$9*4+1)) -> 1
A20: 销售交付完成时间 | B20: =IF(核心参数输入!$B$142=0,"不适用",IF(B19<0.999999,"期内未完成",INDEX(季度计划!$D$5:$DT$5,1,MATCH(1,指标与情景!$D$90:$DT$90,0)))) -> 2032Q4 | C20: 说明 | E20: =IF(核心参数输入!$B$142=0,"不适用",IF(E19<0.999999,"期内未完成",INDEX(季度计划!$D$5:$DT$5,1,MATCH(1,指标与情景!$D$200:$DT$200,0)))) -> 2032Q4
A21: 持有出租面积 | B21: =(核心参数输入!$B$10*核心参数输入!$B$11*核心参数输入!$B$12*核心参数输入!$B$143) -> 60750 | C21: 平方米 | E21: =(核心参数输入!$B$10*核心参数输入!$B$11*核心参数输入!$B$12*核心参数输入!$B$143) -> 60750
A22: 稳定运营现金保本出租率 | B22: =IF(OR((核心参数输入!$B$10*核心参数输入!$B$11*核心参数输入!$B$12*核心参数输入!$B$143)=0,核心参数输入!$B$9<核心参数输入!$B$18+3+INT((核心参数输入!$B$148)/4)),"不适用",IF(((核心参数输入!$B$10*核心参数输入!$B$11*核心参数输入!$B$12*核心参数输入!$B$143)*INDEX(季度经营税费!$D$20:$DT$20,1,MIN(核心参数输入!$B$9*4,(核心参数输入!$B$18+3)*4+核心参数输入!$B$148)+1)*12/10000)*(核心参数输入!$B$43*(1+核心参数输入!$B$44)*(1-核心参数输入!$B$49)/(1+IF(核心参数输入!$B$96=2,核心参数输入!$B$119,0))-(1+核心参数输入!$B$43*核心参数输入!$B$44)*IF(核心参数输入!$B$96=1,核心参数输入!$B$51,核心参数输入!$B$122))<=0,"无法计算",(INDEX(季度经营税费!$D$37:$DT$37,1,MIN(核心参数输入!$B$9*4,(核心参数输入!$B$18+3)*4+核心参数输入!$B$148)+1)*4+核心参数输入!$B$50*(核心参数输入!$B$10*核心参数输入!$B$11*核心参数输入!$B$12*核心参数输入!$B$143)/MAX(1,核心参数输入!$B$108))/(((核心参数输入!$B$10*核心参数输入!$B$11*核心参数输入!$B$12*核心参数输入!$B$143)*INDEX(季度经营税费!$D$20:$DT$20,1,MIN(核心参数输入!$B$9*4,(核心参数输入!$B$18+3)*4+核心参数输入!$B$148)+1)*12/10000)*(核心参数输入!$B$43*(1+核心参数输入!$B$44)*(1-核心参数输入!$B$49)/(1+IF(核心参数输入!$B$96=2,核心参数输入!$B$119,0))-(1+核心参数输入!$B$43*核心参数输入!$B$44)*IF(核心参数输入!$B$96=1,核心参数输入!$B$51,核心参数输入!$B$122))))) -> 0.29842494 | C22: % | E22: =IF(OR((核心参数输入!$B$10*核心参数输入!$B$11*核心参数输入!$B$12*核心参数输入!$B$143)=0,核心参数输入!$B$9<核心参数输入!$B$18+3+INT((核心参数输入!$B$148+核心参数输入!$B$124)/4)),"不适用",IF(((核心参数输入!$B$10*核心参数输入!$B$11*核心参数输入!$B$12*核心参数输入!$B$143)*INDEX(季度经营税费!$D$130:$DT$130,1,MIN(核心参数输入!$B$9*4,(核心参数输入!$B$18+3)*4+核心参数输入!$B$148+核心参数输入!$B$124)+1)*12/10000)*(核心参数输入!$B$43*(1+核心参数输入!$B$44)*(1-核心参数输入!$B$49)/(1+IF(核心参数输入!$B$96=2,核心参数输入!$B$119,0))-(1+核心参数输入!$B$43*核心参数输入!$B$44)*IF(核心参数输入!$B$96=1,核心参数输入!$B$51,核心参数输入!$B$122))<=0,"无法计算",(INDEX(季度经营税费!$D$147:$DT$147,1,MIN(核心参数输入!$B$9*4,(核心参数输入!$B$18+3)*4+核心参数输入!$B$148+核心参数输入!$B$124)+1)*4+核心参数输入!$B$50*(核心参数输入!$B$10*核心参数输入!$B$11*核心参数输入!$B$12*核心参数输入!$B$143)/MAX(1,核心参数输入!$B$108))/(((核心参数输入!$B$10*核心参数输入!$B$11*核心参数输入!$B$12*核心参数输入!$B$143)*INDEX(季度经营税费!$D$130:$DT$130,1,MIN(核心参数输入!$B$9*4,(核心参数输入!$B$18+3)*4+核心参数输入!$B$148+核心参数输入!$B$124)+1)*12/10000)*(核心参数输入!$B$43*(1+核心参数输入!$B$44)*(1-核心参数输入!$B$49)/(1+IF(核心参数输入!$B$96=2,核心参数输入!$B$119,0))-(1+核心参数输入!$B$43*核心参数输入!$B$44)*IF(核心参数输入!$B$96=1,核心参数输入!$B$51,核心参数输入!$B$122))))) -> 0.33158327 | H22: 仅稳定运营现金保本，不含所得税、折旧、本息和投资回收；无新增免租
A23: 持有稳定NOI收益率 | B23: =IF(OR((核心参数输入!$B$10*核心参数输入!$B$11*核心参数输入!$B$12*核心参数输入!$B$143)=0,季度投融资!$B$27=0,核心参数输入!$B$9<核心参数输入!$B$18+3+INT((核心参数输入!$B$148)/4)),"不适用",INDEX(季度经营税费!$D$70:$DT$70,1,MIN(核心参数输入!$B$9*4,(核心参数输入!$B$18+3)*4+核心参数输入!$B$148)+1)*4/季度投融资!$B$27) -> 0.033836975 | C23: % | E23: =IF(OR((核心参数输入!$B$10*核心参数输入!$B$11*核心参数输入!$B$12*核心参数输入!$B$143)=0,季度投融资!$E$27=0,核心参数输入!$B$9<核心参数输入!$B$18+3+INT((核心参数输入!$B$148+核心参数输入!$B$124)/4)),"不适用",INDEX(季度经营税费!$D$180:$DT$180,1,MIN(核心参数输入!$B$9*4,(核心参数输入!$B$18+3)*4+核心参数输入!$B$148+核心参数输入!$B$124)+1)*4/季度投融资!$E$27) -> 0.02169914 | H23: 稳定观察季度NOI×4／持有分摊总投资；非IRR
A24: 期末净处置占现金流入 | B24: =IF(SUM(季度经营税费!$D$68:INDEX(季度经营税费!$D$68:$DT$68,1,核心参数输入!$B$9*4+1))+SUM(季度经营税费!$D$59:INDEX(季度经营税费!$D$59:$DT$59,1,核心参数输入!$B$9*4+1))=0,"不适用",IF(核心参数输入!$B$64=1,SUM(季度经营税费!$D$59:INDEX(季度经营税费!$D$59:$DT$59,1,核心参数输入!$B$9*4+1))/(SUM(季度经营税费!$D$68:INDEX(季度经营税费!$D$68:$DT$68,1,核心参数输入!$B$9*4+1))+SUM(季度经营税费!$D$59:INDEX(季度经营税费!$D$59:$DT$59,1,核心参数输入!$B$9*4+1))),0)) -> 0 | C24: % | E24: =IF(SUM(季度经营税费!$D$178:INDEX(季度经营税费!$D$178:$DT$178,1,核心参数输入!$B$9*4+1))+SUM(季度经营税费!$D$169:INDEX(季度经营税费!$D$169:$DT$169,1,核心参数输入!$B$9*4+1))=0,"不适用",IF(核心参数输入!$B$64=1,SUM(季度经营税费!$D$169:INDEX(季度经营税费!$D$169:$DT$169,1,核心参数输入!$B$9*4+1))/(SUM(季度经营税费!$D$178:INDEX(季度经营税费!$D$178:$DT$178,1,核心参数输入!$B$9*4+1))+SUM(季度经营税费!$D$169:INDEX(季度经营税费!$D$169:$DT$169,1,核心参数输入!$B$9*4+1))),0)) -> 0
A25: 项目IRR变号提示 | B25: =IF(SUM(季度现金流!$D$64:INDEX(季度现金流!$D$64:$DT$64,1,核心参数输入!$B$9*4+1))>1,"多次变号，IRR需结合NPV审视","单次变号或无变号") -> 单次变号或无变号 | C25: 说明 | E25: =IF(SUM(季度现金流!$D$174:INDEX(季度现金流!$D$174:$DT$174,1,核心参数输入!$B$9*4+1))>1,"多次变号，IRR需结合NPV审视","单次变号或无变号") -> 单次变号或无变号
A26: 资本金IRR变号提示 | B26: =IF(SUM(季度现金流!$D$75:INDEX(季度现金流!$D$75:$DT$75,1,核心参数输入!$B$9*4+1))>1,"多次变号，IRR需结合NPV审视","单次变号或无变号") -> 单次变号或无变号 | C26: 说明 | E26: =IF(SUM(季度现金流!$D$185:INDEX(季度现金流!$D$185:$DT$185,1,核心参数输入!$B$9*4+1))>1,"多次变号，IRR需结合NPV审视","单次变号或无变号") -> 单次变号或无变号
A27: 资本金收益可执行性 | B27: =IF(B14>0.01,"理论收益，资金尚未落实","完整出资、留存后分配口径") -> 完整出资、留存后分配口径 | C27: 说明 | E27: =IF(E14>0.01,"理论收益，资金尚未落实","完整出资、留存后分配口径") -> 理论收益，资金尚未落实
A28: 稳定观察项目年度 | B28: =IF(核心参数输入!$B$9>=核心参数输入!$B$18+3+INT((核心参数输入!$B$148)/4),核心参数输入!$B$18+3+INT((核心参数输入!$B$148)/4),"未覆盖稳定观察年") -> 7 | C28: 年 | E28: =IF(核心参数输入!$B$9>=核心参数输入!$B$18+3+INT((核心参数输入!$B$148+核心参数输入!$B$124)/4),核心参数输入!$B$18+3+INT((核心参数输入!$B$148+核心参数输入!$B$124)/4),"未覆盖稳定观察年") -> 7
A29: 融资前峰值资金需要 | B29: =MAX(季度现金流!$D$77:INDEX(季度现金流!$D$77:$DT$77,1,核心参数输入!$B$9*4+1)) -> 62810 | C29: 万元 | E29: =MAX(季度现金流!$D$187:INDEX(季度现金流!$D$187:$DT$187,1,核心参数输入!$B$9*4+1)) -> 68102 | H29: 排除贷款和股东流入及本金偿还，包含融资利息和手续费
A30: 融资前峰值发生季度 | B30: =INDEX(季度计划!$D$5:$DT$5,1,MATCH(MAX(季度现金流!$D$77:INDEX(季度现金流!$D$77:$DT$77,1,核心参数输入!$B$9*4+1)),季度现金流!$D$77:INDEX(季度现金流!$D$77:$DT$77,1,核心参数输入!$B$9*4+1),0)) -> 2029Q4 | C30: 说明 | E30: =INDEX(季度计划!$D$5:$DT$5,1,MATCH(MAX(季度现金流!$D$187:INDEX(季度现金流!$D$187:$DT$187,1,核心参数输入!$B$9*4+1)),季度现金流!$D$187:INDEX(季度现金流!$D$187:$DT$187,1,核心参数输入!$B$9*4+1),0)) -> 2029Q4
A31: 未落实缺口高峰季度 | B31: =IF(B14<=0.01,"无未落实缺口",INDEX(季度计划!$D$5:$DT$5,1,MATCH(MAX(季度现金流!$D$58:INDEX(季度现金流!$D$58:$DT$58,1,核心参数输入!$B$9*4+1)),季度现金流!$D$58:INDEX(季度现金流!$D$58:$DT$58,1,核心参数输入!$B$9*4+1),0))) -> 无未落实缺口 | C31: 说明 | E31: =IF(E14<=0.01,"无未落实缺口",INDEX(季度计划!$D$5:$DT$5,1,MATCH(MAX(季度现金流!$D$168:INDEX(季度现金流!$D$168:$DT$168,1,核心参数输入!$B$9*4+1)),季度现金流!$D$168:INDEX(季度现金流!$D$168:$DT$168,1,核心参数输入!$B$9*4+1),0))) -> 2029Q4
A32: 累计资本金投入高峰季度 | B32: =INDEX(季度计划!$D$5:$DT$5,1,MATCH(MAX(季度现金流!$D$79:INDEX(季度现金流!$D$79:$DT$79,1,核心参数输入!$B$9*4+1)),季度现金流!$D$79:INDEX(季度现金流!$D$79:$DT$79,1,核心参数输入!$B$9*4+1),0)) -> 2029Q4 | C32: 说明 | E32: =INDEX(季度计划!$D$5:$DT$5,1,MATCH(MAX(季度现金流!$D$189:INDEX(季度现金流!$D$189:$DT$189,1,核心参数输入!$B$9*4+1)),季度现金流!$D$189:INDEX(季度现金流!$D$189:$DT$189,1,核心参数输入!$B$9*4+1),0)) -> 2029Q4
A33: 最低额度内期末现金 | B33: =MIN(季度现金流!$D$57:INDEX(季度现金流!$D$57:$DT$57,1,核心参数输入!$B$9*4+1)) -> 0 | C33: 万元 | E33: =MIN(季度现金流!$D$167:INDEX(季度现金流!$D$167:$DT$167,1,核心参数输入!$B$9*4+1)) -> 0
A34: 期末销售应收余额 | B34: =INDEX(季度经营税费!$D$13:$DT$13,1,核心参数输入!$B$9*4+1) -> 0 | C34: 万元 | E34: =INDEX(季度经营税费!$D$123:$DT$123,1,核心参数输入!$B$9*4+1) -> 0
A35: 累计净利润 | B35: =SUM(年度汇总!$D$17:$AH$17) -> 4193.6056 | C35: 万元 | E35: =SUM(年度汇总!$D$77:$AH$77) -> -8045.9068
A36: 流转税口径 | B36: =核心参数输入!$B$152 -> 综合税费率（沿用V2） | C36: 说明 | E36: =核心参数输入!$B$152 -> 综合税费率（沿用V2）
A37: 贷款合同到期时间 | B37: =IF(核心参数输入!$B$57=0,"无贷款",INDEX(季度计划!$D$5:$DT$5,1,MAX(1,MIN(121,季度投融资!$B$29+1)))) -> 2036Q4 | C37: 说明 | E37: =IF(核心参数输入!$B$57=0,"无贷款",INDEX(季度计划!$D$5:$DT$5,1,MAX(1,MIN(121,季度投融资!$E$29+1)))) -> 2036Q4
A38: 持续持有项目IRR | B38: =IF(AND(COUNTIFS(季度现金流!$D$18:INDEX(季度现金流!$D$18:$DT$18,1,核心参数输入!$B$9*4+1),"<0")>0,COUNTIFS(季度现金流!$D$18:INDEX(季度现金流!$D$18:$DT$18,1,核心参数输入!$B$9*4+1),">0")>0),IFERROR((1+IRR(季度现金流!$D$18:INDEX(季度现金流!$D$18:$DT$18,1,核心参数输入!$B$9*4+1)))^4-1,"无法计算"),"无法计算") -> -0.014445335 | C38: % | E38: =IF(AND(COUNTIFS(季度现金流!$D$128:INDEX(季度现金流!$D$128:$DT$128,1,核心参数输入!$B$9*4+1),"<0")>0,COUNTIFS(季度现金流!$D$128:INDEX(季度现金流!$D$128:$DT$128,1,核心参数输入!$B$9*4+1),">0")>0),IFERROR((1+IRR(季度现金流!$D$128:INDEX(季度现金流!$D$128:$DT$128,1,核心参数输入!$B$9*4+1)))^4-1,"无法计算"),"无法计算") -> -0.049549603 | H38: 持续持有不将物业、存货或应收自动变现；周转按B109
A39: 期末出售项目IRR | B39: =IF(AND(COUNTIFS(季度现金流!$D$19:INDEX(季度现金流!$D$19:$DT$19,1,核心参数输入!$B$9*4+1),"<0")>0,COUNTIFS(季度现金流!$D$19:INDEX(季度现金流!$D$19:$DT$19,1,核心参数输入!$B$9*4+1),">0")>0),IFERROR((1+IRR(季度现金流!$D$19:INDEX(季度现金流!$D$19:$DT$19,1,核心参数输入!$B$9*4+1)))^4-1,"无法计算"),"无法计算") -> 0.033744637 | C39: % | E39: =IF(AND(COUNTIFS(季度现金流!$D$129:INDEX(季度现金流!$D$129:$DT$129,1,核心参数输入!$B$9*4+1),"<0")>0,COUNTIFS(季度现金流!$D$129:INDEX(季度现金流!$D$129:$DT$129,1,核心参数输入!$B$9*4+1),">0")>0),IFERROR((1+IRR(季度现金流!$D$129:INDEX(季度现金流!$D$129:$DT$129,1,核心参数输入!$B$9*4+1)))^4-1,"无法计算"),"无法计算") -> 0.014103066 | H39: 仅出售持有物业，扣费用与所得税，周转按B110
A40: 持续持有项目NPV | B40: =NPV((1+核心参数输入!$B$71)^(1/4)-1,季度现金流!$E$18:INDEX(季度现金流!$D$18:$DT$18,1,核心参数输入!$B$9*4+1))+季度现金流!D18 -> -20406.095 | C40: 万元 | E40: =NPV((1+核心参数输入!$B$71)^(1/4)-1,季度现金流!$E$128:INDEX(季度现金流!$D$128:$DT$128,1,核心参数输入!$B$9*4+1))+季度现金流!D128 -> -28525.14
A41: 期末出售项目NPV | B41: =NPV((1+核心参数输入!$B$71)^(1/4)-1,季度现金流!$E$19:INDEX(季度现金流!$D$19:$DT$19,1,核心参数输入!$B$9*4+1))+季度现金流!D19 -> -14899.172 | C41: 万元 | E41: =NPV((1+核心参数输入!$B$71)^(1/4)-1,季度现金流!$E$129:INDEX(季度现金流!$D$129:$DT$129,1,核心参数输入!$B$9*4+1))+季度现金流!D129 -> -22937.558
A42: 持续持有资本金IRR | B42: =IF(AND(COUNTIFS(季度现金流!$D$31:INDEX(季度现金流!$D$31:$DT$31,1,核心参数输入!$B$9*4+1),"<0")>0,COUNTIFS(季度现金流!$D$31:INDEX(季度现金流!$D$31:$DT$31,1,核心参数输入!$B$9*4+1),">0")>0),IFERROR((1+IRR(季度现金流!$D$31:INDEX(季度现金流!$D$31:$DT$31,1,核心参数输入!$B$9*4+1)))^4-1,"无法计算"),"无法计算") -> -0.040676665 | C42: % | E42: =IF(AND(COUNTIFS(季度现金流!$D$141:INDEX(季度现金流!$D$141:$DT$141,1,核心参数输入!$B$9*4+1),"<0")>0,COUNTIFS(季度现金流!$D$141:INDEX(季度现金流!$D$141:$DT$141,1,核心参数输入!$B$9*4+1),">0")>0),IFERROR((1+IRR(季度现金流!$D$141:INDEX(季度现金流!$D$141:$DT$141,1,核心参数输入!$B$9*4+1)))^4-1,"无法计算"),"无法计算") -> -0.087463531
A43: 期末出售资本金IRR | B43: =IF(AND(COUNTIFS(季度现金流!$D$41:INDEX(季度现金流!$D$41:$DT$41,1,核心参数输入!$B$9*4+1),"<0")>0,COUNTIFS(季度现金流!$D$41:INDEX(季度现金流!$D$41:$DT$41,1,核心参数输入!$B$9*4+1),">0")>0),IFERROR((1+IRR(季度现金流!$D$41:INDEX(季度现金流!$D$41:$DT$41,1,核心参数输入!$B$9*4+1)))^4-1,"无法计算"),"无法计算") -> 0.030390403 | C43: % | E43: =IF(AND(COUNTIFS(季度现金流!$D$151:INDEX(季度现金流!$D$151:$DT$151,1,核心参数输入!$B$9*4+1),"<0")>0,COUNTIFS(季度现金流!$D$151:INDEX(季度现金流!$D$151:$DT$151,1,核心参数输入!$B$9*4+1),">0")>0),IFERROR((1+IRR(季度现金流!$D$151:INDEX(季度现金流!$D$151:$DT$151,1,核心参数输入!$B$9*4+1)))^4-1,"无法计算"),"无法计算") -> 0.0046828705
...

Sheet 年度汇总
A2: 年度汇总 · V3模拟测算
A4: 项目年度 | D4: 0 | E4: 1 | F4: 2 | G4: 3 | H4: 4 | I4: 5 | J4: 6 | K4: 7 | L4: 8 | M4: 9 | N4: 10 | O4: 11 | P4: 12 | Q4: 13 | R4: 14 | S4: 15 | T4: 16 | U4: 17 | V4: 18 | W4: 19 | X4: 20 | Y4: 21 | Z4: 22 | AA4: 23 | AB4: 24 | AC4: 25 | AD4: 26 | AE4: 27 | AF4: 28 | AG4: 29 | AH4: 30
A5: 日历年份 | D5: =核心参数输入!$B$8+D$4 -> 2026 | E5: =核心参数输入!$B$8+E$4 -> 2027 | F5: =核心参数输入!$B$8+F$4 -> 2028 | G5: =核心参数输入!$B$8+G$4 -> 2029 | H5: =核心参数输入!$B$8+H$4 -> 2030 | I5: =核心参数输入!$B$8+I$4 -> 2031 | J5: =核心参数输入!$B$8+J$4 -> 2032 | K5: =核心参数输入!$B$8+K$4 -> 2033 | ... AH5: =核心参数输入!$B$8+AH$4 -> 2056
A8: 基准 · 年度汇总
A10: 销售收入（利润口径） | B10: 万元 | D10: =IF(0<=核心参数输入!$B$9,SUMIFS(季度经营税费!$D$32:$DT$32,季度经营税费!$D$6:$DT$6,0),0) -> 0 | E10: =IF(1<=核心参数输入!$B$9,SUMIFS(季度经营税费!$D$32:$DT$32,季度经营税费!$D$6:$DT$6,1),0) -> 0 | F10: =IF(2<=核心参数输入!$B$9,SUMIFS(季度经营税费!$D$32:$DT$32,季度经营税费!$D$6:$DT$6,2),0) -> 0 | G10: =IF(3<=核心参数输入!$B$9,SUMIFS(季度经营税费!$D$32:$DT$32,季度经营税费!$D$6:$DT$6,3),0) -> 0 | H10: =IF(4<=核心参数输入!$B$9,SUMIFS(季度经营税费!$D$32:$DT$32,季度经营税费!$D$6:$DT$6,4),0) -> 14478.75 | I10: =IF(5<=核心参数输入!$B$9,SUMIFS(季度经营税费!$D$32:$DT$32,季度经营税费!$D$6:$DT$6,5),0) -> 19305 | J10: =IF(6<=核心参数输入!$B$9,SUMIFS(季度经营税费!$D$32:$DT$32,季度经营税费!$D$6:$DT$6,6),0) -> 14478.75 | K10: =IF(7<=核心参数输入!$B$9,SUMIFS(季度经营税费!$D$32:$DT$32,季度经营税费!$D$6:$DT$6,7),0) -> 0 | L10: =IF(8<=核心参数输入!$B$9,SUMIFS(季度经营税费!$D$32:$DT$32,季度经营税费!$D$6:$DT$6,8),0) -> 0 | M10: =IF(9<=核心参数输入!$B$9,SUMIFS(季度经营税费!$D$32:$DT$32,季度经营税费!$D$6:$DT$6,9),0) -> 0 | N10: =IF(10<=核心参数输入!$B$9,SUMIFS(季度经营税费!$D$32:$DT$32,季度经营税费!$D$6:$DT$6,10),0) -> 0 | O10: =IF(11<=核心参数输入!$B$9,SUMIFS(季度经营税费!$D$32:$DT$32,季度经营税费!$D$6:$DT$6,11),0) -> 0 | P10: =IF(12<=核心参数输入!$B$9,SUMIFS(季度经营税费!$D$32:$DT$32,季度经营税费!$D$6:$DT$6,12),0) -> 0 | Q10: =IF(13<=核心参数输入!$B$9,SUMIFS(季度经营税费!$D$32:$DT$32,季度经营税费!$D$6:$DT$6,13),0) -> 0 | R10: =IF(14<=核心参数输入!$B$9,SUMIFS(季度经营税费!$D$32:$DT$32,季度经营税费!$D$6:$DT$6,14),0) -> 0 | S10: =IF(15<=核心参数输入!$B$9,SUMIFS(季度经营税费!$D$32:$DT$32,季度经营税费!$D$6:$DT$6,15),0) -> 0 | T10: =IF(16<=核心参数输入!$B$9,SUMIFS(季度经营税费!$D$32:$DT$32,季度经营税费!$D$6:$DT$6,16),0) -> 0 | U10: =IF(17<=核心参数输入!$B$9,SUMIFS(季度经营税费!$D$32:$DT$32,季度经营税费!$D$6:$DT$6,17),0) -> 0 | V10: =IF(18<=核心参数输入!$B$9,SUMIFS(季度经营税费!$D$32:$DT$32,季度经营税费!$D$6:$DT$6,18),0) -> 0 | W10: =IF(19<=核心参数输入!$B$9,SUMIFS(季度经营税费!$D$32:$DT$32,季度经营税费!$D$6:$DT$6,19),0) -> 0 | X10: =IF(20<=核心参数输入!$B$9,SUMIFS(季度经营税费!$D$32:$DT$32,季度经营税费!$D$6:$DT$6,20),0) -> 0 | Y10: =IF(21<=核心参数输入!$B$9,SUMIFS(季度经营税费!$D$32:$DT$32,季度经营税费!$D$6:$DT$6,21),0) -> 0 | Z10: =IF(22<=核心参数输入!$B$9,SUMIFS(季度经营税费!$D$32:$DT$32,季度经营税费!$D$6:$DT$6,22),0) -> 0 | AA10: =IF(23<=核心参数输入!$B$9,SUMIFS(季度经营税费!$D$32:$DT$32,季度经营税费!$D$6:$DT$6,23),0) -> 0 | AB10: =IF(24<=核心参数输入!$B$9,SUMIFS(季度经营税费!$D$32:$DT$32,季度经营税费!$D$6:$DT$6,24),0) -> 0 | AC10: =IF(25<=核心参数输入!$B$9,SUMIFS(季度经营税费!$D$32:$DT$32,季度经营税费!$D$6:$DT$6,25),0) -> 0 | AD10: =IF(26<=核心参数输入!$B$9,SUMIFS(季度经营税费!$D$32:$DT$32,季度经营税费!$D$6:$DT$6,26),0) -> 0 | AE10: =IF(27<=核心参数输入!$B$9,SUMIFS(季度经营税费!$D$32:$DT$32,季度经营税费!$D$6:$DT$6,27),0) -> 0 | AF10: =IF(28<=核心参数输入!$B$9,SUMIFS(季度经营税费!$D$32:$DT$32,季度经营税费!$D$6:$DT$6,28),0) -> 0 | AG10: =IF(29<=核心参数输入!$B$9,SUMIFS(季度经营税费!$D$32:$DT$32,季度经营税费!$D$6:$DT$6,29),0) -> 0 | AH10: =IF(30<=核心参数输入!$B$9,SUMIFS(季度经营税费!$D$32:$DT$32,季度经营税费!$D$6:$DT$6,30),0) -> 0
A11: 持有收入（利润口径） | B11: 万元 | D11: =IF(0<=核心参数输入!$B$9,SUMIFS(季度经营税费!$D$33:$DT$33,季度经营税费!$D$6:$DT$6,0),0) -> 0 | E11: =IF(1<=核心参数输入!$B$9,SUMIFS(季度经营税费!$D$33:$DT$33,季度经营税费!$D$6:$DT$6,1),0) -> 0 | F11: =IF(2<=核心参数输入!$B$9,SUMIFS(季度经营税费!$D$33:$DT$33,季度经营税费!$D$6:$DT$6,2),0) -> 0 | G11: =IF(3<=核心参数输入!$B$9,SUMIFS(季度经营税费!$D$33:$DT$33,季度经营税费!$D$6:$DT$6,3),0) -> 0 | H11: =IF(4<=核心参数输入!$B$9,SUMIFS(季度经营税费!$D$33:$DT$33,季度经营税费!$D$6:$DT$6,4),0) -> 279.60112 | I11: =IF(5<=核心参数输入!$B$9,SUMIFS(季度经营税费!$D$33:$DT$33,季度经营税费!$D$6:$DT$6,5),0) -> 1091.0346 | J11: =IF(6<=核心参数输入!$B$9,SUMIFS(季度经营税费!$D$33:$DT$33,季度经营税费!$D$6:$DT$6,6),0) -> 1507.4724 | K11: =IF(7<=核心参数输入!$B$9,SUMIFS(季度经营税费!$D$33:$DT$33,季度经营税费!$D$6:$DT$6,7),0) -> 1786.7229 | L11: =IF(8<=核心参数输入!$B$9,SUMIFS(季度经营税费!$D$33:$DT$33,季度经营税费!$D$6:$DT$6,8),0) -> 1895.9567 | M11: =IF(9<=核心参数输入!$B$9,SUMIFS(季度经营税费!$D$33:$DT$33,季度经营税费!$D$6:$DT$6,9),0) -> 1927.7428 | N11: =IF(10<=核心参数输入!$B$9,SUMIFS(季度经营税费!$D$33:$DT$33,季度经营税费!$D$6:$DT$6,10),0) -> 1956.6589 | O11: =IF(11<=核心参数输入!$B$9,SUMIFS(季度经营税费!$D$33:$DT$33,季度经营税费!$D$6:$DT$6,11),0) -> 1986.0088 | P11: =IF(12<=核心参数输入!$B$9,SUMIFS(季度经营税费!$D$33:$DT$33,季度经营税费!$D$6:$DT$6,12),0) -> 2015.7989 | Q11: =IF(13<=核心参数输入!$B$9,SUMIFS(季度经营税费!$D$33:$DT$33,季度经营税费!$D$6:$DT$6,13),0) -> 2046.0359 | R11: =IF(14<=核心参数输入!$B$9,SUMIFS(季度经营税费!$D$33:$DT$33,季度经营税费!$D$6:$DT$6,14),0) -> 2076.7265 | S11: =IF(15<=核心参数输入!$B$9,SUMIFS(季度经营税费!$D$33:$DT$33,季度经营税费!$D$6:$DT$6,15),0) -> 2107.8774 | T11: =IF(16<=核心参数输入!$B$9,SUMIFS(季度经营税费!$D$33:$DT$33,季度经营税费!$D$6:$DT$6,16),0) -> 2139.4955 | U11: =IF(17<=核心参数输入!$B$9,SUMIFS(季度经营税费!$D$33:$DT$33,季度经营税费!$D$6:$DT$6,17),0) -> 2171.588 | V11: =IF(18<=核心参数输入!$B$9,SUMIFS(季度经营税费!$D$33:$DT$33,季度经营税费!$D$6:$DT$6,18),0) -> 2204.1618 | W11: =IF(19<=核心参数输入!$B$9,SUMIFS(季度经营税费!$D$33:$DT$33,季度经营税费!$D$6:$DT$6,19),0) -> 2237.2242 | X11: =IF(20<=核心参数输入!$B$9,SUMIFS(季度经营税费!$D$33:$DT$33,季度经营税费!$D$6:$DT$6,20),0) -> 2270.7826 | Y11: =IF(21<=核心参数输入!$B$9,SUMIFS(季度经营税费!$D$33:$DT$33,季度经营税费!$D$6:$DT$6,21),0) -> 0 | Z11: =IF(22<=核心参数输入!$B$9,SUMIFS(季度经营税费!$D$33:$DT$33,季度经营税费!$D$6:$DT$6,22),0) -> 0 | AA11: =IF(23<=核心参数输入!$B$9,SUMIFS(季度经营税费!$D$33:$DT$33,季度经营税费!$D$6:$DT$6,23),0) -> 0 | AB11: =IF(24<=核心参数输入!$B$9,SUMIFS(季度经营税费!$D$33:$DT$33,季度经营税费!$D$6:$DT$6,24),0) -> 0 | AC11: =IF(25<=核心参数输入!$B$9,SUMIFS(季度经营税费!$D$33:$DT$33,季度经营税费!$D$6:$DT$6,25),0) -> 0 | AD11: =IF(26<=核心参数输入!$B$9,SUMIFS(季度经营税费!$D$33:$DT$33,季度经营税费!$D$6:$DT$6,26),0) -> 0 | AE11: =IF(27<=核心参数输入!$B$9,SUMIFS(季度经营税费!$D$33:$DT$33,季度经营税费!$D$6:$DT$6,27),0) -> 0 | AF11: =IF(28<=核心参数输入!$B$9,SUMIFS(季度经营税费!$D$33:$DT$33,季度经营税费!$D$6:$DT$6,28),0) -> 0 | AG11: =IF(29<=核心参数输入!$B$9,SUMIFS(季度经营税费!$D$33:$DT$33,季度经营税费!$D$6:$DT$6,29),0) -> 0 | AH11: =IF(30<=核心参数输入!$B$9,SUMIFS(季度经营税费!$D$33:$DT$33,季度经营税费!$D$6:$DT$6,30),0) -> 0
A12: 销售实收现金 | B12: 万元 | D12: =IF(0<=核心参数输入!$B$9,SUMIFS(季度经营税费!$D$12:$DT$12,季度经营税费!$D$6:$DT$6,0),0) -> 0 | E12: =IF(1<=核心参数输入!$B$9,SUMIFS(季度经营税费!$D$12:$DT$12,季度经营税费!$D$6:$DT$6,1),0) -> 0 | F12: =IF(2<=核心参数输入!$B$9,SUMIFS(季度经营税费!$D$12:$DT$12,季度经营税费!$D$6:$DT$6,2),0) -> 0 | G12: =IF(3<=核心参数输入!$B$9,SUMIFS(季度经营税费!$D$12:$DT$12,季度经营税费!$D$6:$DT$6,3),0) -> 0 | H12: =IF(4<=核心参数输入!$B$9,SUMIFS(季度经营税费!$D$12:$DT$12,季度经营税费!$D$6:$DT$6,4),0) -> 13392.844 | I12: =IF(5<=核心参数输入!$B$9,SUMIFS(季度经营税费!$D$12:$DT$12,季度经营税费!$D$6:$DT$6,5),0) -> 18943.031 | J12: =IF(6<=核心参数输入!$B$9,SUMIFS(季度经营税费!$D$12:$DT$12,季度经营税费!$D$6:$DT$6,6),0) -> 14840.719 | K12: =IF(7<=核心参数输入!$B$9,SUMIFS(季度经营税费!$D$12:$DT$12,季度经营税费!$D$6:$DT$6,7),0) -> 1085.9063 | L12: =IF(8<=核心参数输入!$B$9,SUMIFS(季度经营税费!$D$12:$DT$12,季度经营税费!$D$6:$DT$6,8),0) -> 0 | M12: =IF(9<=核心参数输入!$B$9,SUMIFS(季度经营税费!$D$12:$DT$12,季度经营税费!$D$6:$DT$6,9),0) -> 0 | N12: =IF(10<=核心参数输入!$B$9,SUMIFS(季度经营税费!$D$12:$DT$12,季度经营税费!$D$6:$DT$6,10),0) -> 0 | O12: =IF(11<=核心参数输入!$B$9,SUMIFS(季度经营税费!$D$12:$DT$12,季度经营税费!$D$6:$DT$6,11),0) -> 0 | P12: =IF(12<=核心参数输入!$B$9,SUMIFS(季度经营税费!$D$12:$DT$12,季度经营税费!$D$6:$DT$6,12),0) -> 0 | Q12: =IF(13<=核心参数输入!$B$9,SUMIFS(季度经营税费!$D$12:$DT$12,季度经营税费!$D$6:$DT$6,13),0) -> 0 | R12: =IF(14<=核心参数输入!$B$9,SUMIFS(季度经营税费!$D$12:$DT$12,季度经营税费!$D$6:$DT$6,14),0) -> 0 | S12: =IF(15<=核心参数输入!$B$9,SUMIFS(季度经营税费!$D$12:$DT$12,季度经营税费!$D$6:$DT$6,15),0) -> 0 | T12: =IF(16<=核心参数输入!$B$9,SUMIFS(季度经营税费!$D$12:$DT$12,季度经营税费!$D$6:$DT$6,16),0) -> 0 | U12: =IF(17<=核心参数输入!$B$9,SUMIFS(季度经营税费!$D$12:$DT$12,季度经营税费!$D$6:$DT$6,17),0) -> 0 | V12: =IF(18<=核心参数输入!$B$9,SUMIFS(季度经营税费!$D$12:$DT$12,季度经营税费!$D$6:$DT$6,18),0) -> 0 | W12: =IF(19<=核心参数输入!$B$9,SUMIFS(季度经营税费!$D$12:$DT$12,季度经营税费!$D$6:$DT$6,19),0) -> 0 | X12: =IF(20<=核心参数输入!$B$9,SUMIFS(季度经营税费!$D$12:$DT$12,季度经营税费!$D$6:$DT$6,20),0) -> 0 | Y12: =IF(21<=核心参数输入!$B$9,SUMIFS(季度经营税费!$D$12:$DT$12,季度经营税费!$D$6:$DT$6,21),0) -> 0 | Z12: =IF(22<=核心参数输入!$B$9,SUMIFS(季度经营税费!$D$12:$DT$12,季度经营税费!$D$6:$DT$6,22),0) -> 0 | AA12: =IF(23<=核心参数输入!$B$9,SUMIFS(季度经营税费!$D$12:$DT$12,季度经营税费!$D$6:$DT$6,23),0) -> 0 | AB12: =IF(24<=核心参数输入!$B$9,SUMIFS(季度经营税费!$D$12:$DT$12,季度经营税费!$D$6:$DT$6,24),0) -> 0 | AC12: =IF(25<=核心参数输入!$B$9,SUMIFS(季度经营税费!$D$12:$DT$12,季度经营税费!$D$6:$DT$6,25),0) -> 0 | AD12: =IF(26<=核心参数输入!$B$9,SUMIFS(季度经营税费!$D$12:$DT$12,季度经营税费!$D$6:$DT$6,26),0) -> 0 | AE12: =IF(27<=核心参数输入!$B$9,SUMIFS(季度经营税费!$D$12:$DT$12,季度经营税费!$D$6:$DT$6,27),0) -> 0 | AF12: =IF(28<=核心参数输入!$B$9,SUMIFS(季度经营税费!$D$12:$DT$12,季度经营税费!$D$6:$DT$6,28),0) -> 0 | AG12: =IF(29<=核心参数输入!$B$9,SUMIFS(季度经营税费!$D$12:$DT$12,季度经营税费!$D$6:$DT$6,29),0) -> 0 | AH12: =IF(30<=核心参数输入!$B$9,SUMIFS(季度经营税费!$D$12:$DT$12,季度经营税费!$D$6:$DT$6,30),0) -> 0
A13: 租金实收现金 | B13: 万元 | D13: =IF(0<=核心参数输入!$B$9,SUMIFS(季度经营税费!$D$26:$DT$26,季度经营税费!$D$6:$DT$6,0),0) -> 0 | E13: =IF(1<=核心参数输入!$B$9,SUMIFS(季度经营税费!$D$26:$DT$26,季度经营税费!$D$6:$DT$6,1),0) -> 0 | F13: =IF(2<=核心参数输入!$B$9,SUMIFS(季度经营税费!$D$26:$DT$26,季度经营税费!$D$6:$DT$6,2),0) -> 0 | G13: =IF(3<=核心参数输入!$B$9,SUMIFS(季度经营税费!$D$26:$DT$26,季度经营税费!$D$6:$DT$6,3),0) -> 0 | H13: =IF(4<=核心参数输入!$B$9,SUMIFS(季度经营税费!$D$26:$DT$26,季度经营税费!$D$6:$DT$6,4),0) -> 261.20981 | I13: =IF(5<=核心参数输入!$B$9,SUMIFS(季度经营税费!$D$26:$DT$26,季度经营税费!$D$6:$DT$6,5),0) -> 1019.2697 | J13: =IF(6<=核心参数输入!$B$9,SUMIFS(季度经营税费!$D$26:$DT$26,季度经营税费!$D$6:$DT$6,6),0) -> 1408.3155 | K13: =IF(7<=核心参数输入!$B$9,SUMIFS(季度经营税费!$D$26:$DT$26,季度经营税费!$D$6:$DT$6,7),0) -> 1669.1978 | L13: =IF(8<=核心参数输入!$B$9,SUMIFS(季度经营税费!$D$26:$DT$26,季度经营税费!$D$6:$DT$6,8),0) -> 1771.2464 | M13: =IF(9<=核心参数输入!$B$9,SUMIFS(季度经营税费!$D$26:$DT$26,季度经营税费!$D$6:$DT$6,9),0) -> 1800.9418 | N13: =IF(10<=核心参数输入!$B$9,SUMIFS(季度经营税费!$D$26:$DT$26,季度经营税费!$D$6:$DT$6,10),0) -> 1827.9559 | O13: =IF(11<=核心参数输入!$B$9,SUMIFS(季度经营税费!$D$26:$DT$26,季度经营税费!$D$6:$DT$6,11),0) -> 1855.3752 | P13: =IF(12<=核心参数输入!$B$9,SUMIFS(季度经营税费!$D$26:$DT$26,季度经营税费!$D$6:$DT$6,12),0) -> 1883.2059 | Q13: =IF(13<=核心参数输入!$B$9,SUMIFS(季度经营税费!$D$26:$DT$26,季度经营税费!$D$6:$DT$6,13),0) -> 1911.454 | R13: =IF(14<=核心参数输入!$B$9,SUMIFS(季度经营税费!$D$26:$DT$26,季度经营税费!$D$6:$DT$6,14),0) -> 1940.1258 | S13: =IF(15<=核心参数输入!$B$9,SUMIFS(季度经营税费!$D$26:$DT$26,季度经营税费!$D$6:$DT$6,15),0) -> 1969.2277 | T13: =IF(16<=核心参数输入!$B$9,SUMIFS(季度经营税费!$D$26:$DT$26,季度经营税费!$D$6:$DT$6,16),0) -> 1998.7661 | U13: =IF(17<=核心参数输入!$B$9,SUMIFS(季度经营税费!$D$26:$DT$26,季度经营税费!$D$6:$DT$6,17),0) -> 2028.7476 | V13: =IF(18<=核心参数输入!$B$9,SUMIFS(季度经营税费!$D$26:$DT$26,季度经营税费!$D$6:$DT$6,18),0) -> 2059.1788 | W13: =IF(19<=核心参数输入!$B$9,SUMIFS(季度经营税费!$D$26:$DT$26,季度经营税费!$D$6:$DT$6,19),0) -> 2090.0665 | X13: =IF(20<=核心参数输入!$B$9,SUMIFS(季度经营税费!$D$26:$DT$26,季度经营税费!$D$6:$DT$6,20),0) -> 2121.4175 | Y13: =IF(21<=核心参数输入!$B$9,SUMIFS(季度经营税费!$D$26:$DT$26,季度经营税费!$D$6:$DT$6,21),0) -> 0 | Z13: =IF(22<=核心参数输入!$B$9,SUMIFS(季度经营税费!$D$26:$DT$26,季度经营税费!$D$6:$DT$6,22),0) -> 0 | AA13: =IF(23<=核心参数输入!$B$9,SUMIFS(季度经营税费!$D$26:$DT$26,季度经营税费!$D$6:$DT$6,23),0) -> 0 | AB13: =IF(24<=核心参数输入!$B$9,SUMIFS(季度经营税费!$D$26:$DT$26,季度经营税费!$D$6:$DT$6,24),0) -> 0 | AC13: =IF(25<=核心参数输入!$B$9,SUMIFS(季度经营税费!$D$26:$DT$26,季度经营税费!$D$6:$DT$6,25),0) -> 0 | AD13: =IF(26<=核心参数输入!$B$9,SUMIFS(季度经营税费!$D$26:$DT$26,季度经营税费!$D$6:$DT$6,26),0) -> 0 | AE13: =IF(27<=核心参数输入!$B$9,SUMIFS(季度经营税费!$D$26:$DT$26,季度经营税费!$D$6:$DT$6,27),0) -> 0 | AF13: =IF(28<=核心参数输入!$B$9,SUMIFS(季度经营税费!$D$26:$DT$26,季度经营税费!$D$6:$DT$6,28),0) -> 0 | AG13: =IF(29<=核心参数输入!$B$9,SUMIFS(季度经营税费!$D$26:$DT$26,季度经营税费!$D$6:$DT$6,29),0) -> 0 | AH13: =IF(30<=核心参数输入!$B$9,SUMIFS(季度经营税费!$D$26:$DT$26,季度经营税费!$D$6:$DT$6,30),0) -> 0
A14: 其他经营实收现金 | B14: 万元 | D14: =IF(0<=核心参数输入!$B$9,SUMIFS(季度经营税费!$D$28:$DT$28,季度经营税费!$D$6:$DT$6,0),0) -> 0 | E14: =IF(1<=核心参数输入!$B$9,SUMIFS(季度经营税费!$D$28:$DT$28,季度经营税费!$D$6:$DT$6,1),0) -> 0 | F14: =IF(2<=核心参数输入!$B$9,SUMIFS(季度经营税费!$D$28:$DT$28,季度经营税费!$D$6:$DT$6,2),0) -> 0 | G14: =IF(3<=核心参数输入!$B$9,SUMIFS(季度经营税费!$D$28:$DT$28,季度经营税费!$D$6:$DT$6,3),0) -> 0 | H14: =IF(4<=核心参数输入!$B$9,SUMIFS(季度经营税费!$D$28:$DT$28,季度经营税费!$D$6:$DT$6,4),0) -> 13.060491 | I14: =IF(5<=核心参数输入!$B$9,SUMIFS(季度经营税费!$D$28:$DT$28,季度经营税费!$D$6:$DT$6,5),0) -> 50.963486 | J14: =IF(6<=核心参数输入!$B$9,SUMIFS(季度经营税费!$D$28:$DT$28,季度经营税费!$D$6:$DT$6,6),0) -> 70.415777 | K14: =IF(7<=核心参数输入!$B$9,SUMIFS(季度经营税费!$D$28:$DT$28,季度经营税费!$D$6:$DT$6,7),0) -> 83.459888 | L14: =IF(8<=核心参数输入!$B$9,SUMIFS(季度经营税费!$D$28:$DT$28,季度经营税费!$D$6:$DT$6,8),0) -> 88.562322 | M14: =IF(9<=核心参数输入!$B$9,SUMIFS(季度经营税费!$D$28:$DT$28,季度经营税费!$D$6:$DT$6,9),0) -> 90.047089 | N14: =IF(10<=核心参数输入!$B$9,SUMIFS(季度经营税费!$D$28:$DT$28,季度经营税费!$D$6:$DT$6,10),0) -> 91.397795 | O14: =IF(11<=核心参数输入!$B$9,SUMIFS(季度经营税费!$D$28:$DT$28,季度经营税费!$D$6:$DT$6,11),0) -> 92.768762 | P14: =IF(12<=核心参数输入!$B$9,SUMIFS(季度经营税费!$D$28:$DT$28,季度经营税费!$D$6:$DT$6,12),0) -> 94.160294 | Q14: =IF(13<=核心参数输入!$B$9,SUMIFS(季度经营税费!$D$28:$DT$28,季度经营税费!$D$6:$DT$6,13),0) -> 95.572698 | R14: =IF(14<=核心参数输入!$B$9,SUMIFS(季度经营税费!$D$28:$DT$28,季度经营税费!$D$6:$DT$6,14),0) -> 97.006288 | S14: =IF(15<=核心参数输入!$B$9,SUMIFS(季度经营税费!$D$28:$DT$28,季度经营税费!$D$6:$DT$6,15),0) -> 98.461383 | T14: =IF(16<=核心参数输入!$B$9,SUMIFS(季度经营税费!$D$28:$DT$28,季度经营税费!$D$6:$DT$6,16),0) -> 99.938303 | U14: =IF(17<=核心参数输入!$B$9,SUMIFS(季度经营税费!$D$28:$DT$28,季度经营税费!$D$6:$DT$6,17),0) -> 101.43738 | V14: =IF(18<=核心参数输入!$B$9,SUMIFS(季度经营税费!$D$28:$DT$28,季度经营税费!$D$6:$DT$6,18),0) -> 102.95894 | W14: =IF(19<=核心参数输入!$B$9,SUMIFS(季度经营税费!$D$28:$DT$28,季度经营税费!$D$6:$DT$6,19),0) -> 104.50332 | X14: =IF(20<=核心参数输入!$B$9,SUMIFS(季度经营税费!$D$28:$DT$28,季度经营税费!$D$6:$DT$6,20),0) -> 106.07087 | Y14: =IF(21<=核心参数输入!$B$9,SUMIFS(季度经营税费!$D$28:$DT$28,季度经营税费!$D$6:$DT$6,21),0) -> 0 | Z14: =IF(22<=核心参数输入!$B$9,SUMIFS(季度经营税费!$D$28:$DT$28,季度经营税费!$D$6:$DT$6,22),0) -> 0 | AA14: =IF(23<=核心参数输入!$B$9,SUMIFS(季度经营税费!$D$28:$DT$28,季度经营税费!$D$6:$DT$6,23),0) -> 0 | AB14: =IF(24<=核心参数输入!$B$9,SUMIFS(季度经营税费!$D$28:$DT$28,季度经营税费!$D$6:$DT$6,24),0) -> 0 | AC14: =IF(25<=核心参数输入!$B$9,SUMIFS(季度经营税费!$D$28:$DT$28,季度经营税费!$D$6:$DT$6,25),0) -> 0 | AD14: =IF(26<=核心参数输入!$B$9,SUMIFS(季度经营税费!$D$28:$DT$28,季度经营税费!$D$6:$DT$6,26),0) -> 0 | AE14: =IF(27<=核心参数输入!$B$9,SUMIFS(季度经营税费!$D$28:$DT$28,季度经营税费!$D$6:$DT$6,27),0) -> 0 | AF14: =IF(28<=核心参数输入!$B$9,SUMIFS(季度经营税费!$D$28:$DT$28,季度经营税费!$D$6:$DT$6,28),0) -> 0 | AG14: =IF(29<=核心参数输入!$B$9,SUMIFS(季度经营税费!$D$28:$DT$28,季度经营税费!$D$6:$DT$6,29),0) -> 0 | AH14: =IF(30<=核心参数输入!$B$9,SUMIFS(季度经营税费!$D$28:$DT$28,季度经营税费!$D$6:$DT$6,30),0) -> 0
A15: 现金成本及流转税 | B15: 万元 | D15: =IF(0<=核心参数输入!$B$9,SUMIFS(季度经营税费!$D$69:$DT$69,季度经营税费!$D$6:$DT$6,0),0) -> 0 | E15: =IF(1<=核心参数输入!$B$9,SUMIFS(季度经营税费!$D$69:$DT$69,季度经营税费!$D$6:$DT$6,1),0) -> 0 | F15: =IF(2<=核心参数输入!$B$9,SUMIFS(季度经营税费!$D$69:$DT$69,季度经营税费!$D$6:$DT$6,2),0) -> 0 | G15: =IF(3<=核心参数输入!$B$9,SUMIFS(季度经营税费!$D$69:$DT$69,季度经营税费!$D$6:$DT$6,3),0) -> 0 | H15: =IF(4<=核心参数输入!$B$9,SUMIFS(季度经营税费!$D$69:$DT$69,季度经营税费!$D$6:$DT$6,4),0) -> 2049.9573 | I15: =IF(5<=核心参数输入!$B$9,SUMIFS(季度经营税费!$D$69:$DT$69,季度经营税费!$D$6:$DT$6,5),0) -> 2706.9151 | J15: =IF(6<=核心参数输入!$B$9,SUMIFS(季度经营税费!$D$69:$DT$69,季度经营税费!$D$6:$DT$6,6),0) -> 2280.2849 | K15: =IF(7<=核心参数输入!$B$9,SUMIFS(季度经营税费!$D$69:$DT$69,季度经营税费!$D$6:$DT$6,7),0) -> 815.88469 | L15: =IF(8<=核心参数输入!$B$9,SUMIFS(季度经营税费!$D$69:$DT$69,季度经营税费!$D$6:$DT$6,8),0) -> 841.6641 | M15: =IF(9<=核心参数输入!$B$9,SUMIFS(季度经营税费!$D$69:$DT$69,季度经营税费!$D$6:$DT$6,9),0) -> 853.80747 | N15: =IF(10<=核心参数输入!$B$9,SUMIFS(季度经营税费!$D$69:$DT$69,季度经营税费!$D$6:$DT$6,10),0) -> 865.5707 | O15: =IF(11<=核心参数输入!$B$9,SUMIFS(季度经营税费!$D$69:$DT$69,季度经营税费!$D$6:$DT$6,11),0) -> 877.54351 | P15: =IF(12<=核心参数输入!$B$9,SUMIFS(季度经营税费!$D$69:$DT$69,季度经营税费!$D$6:$DT$6,12),0) -> 889.72969 | Q15: =IF(13<=核心参数输入!$B$9,SUMIFS(季度经营税费!$D$69:$DT$69,季度经营税费!$D$6:$DT$6,13),0) -> 902.13312 | R15: =IF(14<=核心参数输入!$B$9,SUMIFS(季度经营税费!$D$69:$DT$69,季度经营税费!$D$6:$DT$6,14),0) -> 914.75776 | S15: =IF(15<=核心参数输入!$B$9,SUMIFS(季度经营税费!$D$69:$DT$69,季度经营税费!$D$6:$DT$6,15),0) -> 927.60762 | T15: =IF(16<=核心参数输入!$B$9,SUMIFS(季度经营税费!$D$69:$DT$69,季度经营税费!$D$6:$DT$6,16),0) -> 940.68679 | U15: =IF(17<=核心参数输入!$B$9,SUMIFS(季度经营税费!$D$69:$DT$69,季度经营税费!$D$6:$DT$6,17),0) -> 953.99946 | V15: =IF(18<=核心参数输入!$B$9,SUMIFS(季度经营税费!$D$69:$DT$69,季度经营税费!$D$6:$DT$6,18),0) -> 967.54986 | W15: =IF(19<=核心参数输入!$B$9,SUMIFS(季度经营税费!$D$69:$DT$69,季度经营税费!$D$6:$DT$6,19),0) -> 981.34233 | X15: =IF(20<=核心参数输入!$B$9,SUMIFS(季度经营税费!$D$69:$DT$69,季度经营税费!$D$6:$DT$6,20),0) -> 995.38126 | Y15: =IF(21<=核心参数输入!$B$9,SUMIFS(季度经营税费!$D$69:$DT$69,季度经营税费!$D$6:$DT$6,21),0) -> 0 | Z15: =IF(22<=核心参数输入!$B$9,SUMIFS(季度经营税费!$D$69:$DT$69,季度经营税费!$D$6:$DT$6,22),0) -> 0 | AA15: =IF(23<=核心参数输入!$B$9,SUMIFS(季度经营税费!$D$69:$DT$69,季度经营税费!$D$6:$DT$6,23),0) -> 0 | AB15: =IF(24<=核心参数输入!$B$9,SUMIFS(季度经营税费!$D$69:$DT$69,季度经营税费!$D$6:$DT$6,24),0) -> 0 | AC15: =IF(25<=核心参数输入!$B$9,SUMIFS(季度经营税费!$D$69:$DT$69,季度经营税费!$D$6:$DT$6,25),0) -> 0 | AD15: =IF(26<=核心参数输入!$B$9,SUMIFS(季度经营税费!$D$69:$DT$69,季度经营税费!$D$6:$DT$6,26),0) -> 0 | AE15: =IF(27<=核心参数输入!$B$9,SUMIFS(季度经营税费!$D$69:$DT$69,季度经营税费!$D$6:$DT$6,27),0) -> 0 | AF15: =IF(28<=核心参数输入!$B$9,SUMIFS(季度经营税费!$D$69:$DT$69,季度经营税费!$D$6:$DT$6,28),0) -> 0 | AG15: =IF(29<=核心参数输入!$B$9,SUMIFS(季度经营税费!$D$69:$DT$69,季度经营税费!$D$6:$DT$6,29),0) -> 0 | AH15: =IF(30<=核心参数输入!$B$9,SUMIFS(季度经营税费!$D$69:$DT$69,季度经营税费!$D$6:$DT$6,30),0) -> 0
A16: 融资所得税现金 | B16: 万元 | D16: =IF(0<=核心参数输入!$B$9,IF(核心参数输入!$B$64=1,SUMIFS(季度经营税费!$D$65:$DT$65,季度经营税费!$D$6:$DT$6,0),SUMIFS(季度经营税费!$D$64:$DT$64,季度经营税费!$D$6:$DT$6,0)),0) -> 0 | E16: =IF(1<=核心参数输入!$B$9,IF(核心参数输入!$B$64=1,SUMIFS(季度经营税费!$D$65:$DT$65,季度经营税费!$D$6:$DT$6,1),SUMIFS(季度经营税费!$D$64:$DT$64,季度经营税费!$D$6:$DT$6,1)),0) -> 0 | F16: =IF(2<=核心参数输入!$B$9,IF(核心参数输入!$B$64=1,SUMIFS(季度经营税费!$D$65:$DT$65,季度经营税费!$D$6:$DT$6,2),SUMIFS(季度经营税费!$D$64:$DT$64,季度经营税费!$D$6:$DT$6,2)),0) -> 0 | G16: =IF(3<=核心参数输入!$B$9,IF(核心参数输入!$B$64=1,SUMIFS(季度经营税费!$D$65:$DT$65,季度经营税费!$D$6:$DT$6,3),SUMIFS(季度经营税费!$D$64:$DT$64,季度经营税费!$D$6:$DT$6,3)),0) -> 0 | H16: =IF(4<=核心参数输入!$B$9,IF(核心参数输入!$B$64=1,SUMIFS(季度经营税费!$D$65:$DT$65,季度经营税费!$D$6:$DT$6,4),SUMIFS(季度经营税费!$D$64:$DT$64,季度经营税费!$D$6:$DT$6,4)),0) -> 62.217637 | I16: =IF(5<=核心参数输入!$B$9,IF(核心参数输入!$B$64=1,SUMIFS(季度经营税费!$D$65:$DT$65,季度经营税费!$D$6:$DT$6,5),SUMIFS(季度经营税费!$D$64:$DT$64,季度经营税费!$D$6:$DT$6,5)),0) -> 484.89391 | J16: =IF(6<=核心参数输入!$B$9,IF(核心参数输入!$B$64=1,SUMIFS(季度经营税费!$D$65:$DT$65,季度经营税费!$D$6:$DT$6,6),SUMIFS(季度经营税费!$D$64:$DT$64,季度经营税费!$D$6:$DT$6,6)),0) -> 395.75099 | K16: =IF(7<=核心参数输入!$B$9,IF(核心参数输入!$B$64=1,SUMIFS(季度经营税费!$D$65:$DT$65,季度经营税费!$D$6:$DT$6,7),SUMIFS(季度经营税费!$D$64:$DT$64,季度经营税费!$D$6:$DT$6,7)),0) -> 0 | L16: =IF(8<=核心参数输入!$B$9,IF(核心参数输入!$B$64=1,SUMIFS(季度经营税费!$D$65:$DT$65,季度经营税费!$D$6:$DT$6,8),SUMIFS(季度经营税费!$D$64:$DT$64,季度经营税费!$D$6:$DT$6,8)),0) -> 0 | M16: =IF(9<=核心参数输入!$B$9,IF(核心参数输入!$B$64=1,SUMIFS(季度经营税费!$D$65:$DT$65,季度经营税费!$D$6:$DT$6,9),SUMIFS(季度经营税费!$D$64:$DT$64,季度经营税费!$D$6:$DT$6,9)),0) -> 0 | N16: =IF(10<=核心参数输入!$B$9,IF(核心参数输入!$B$64=1,SUMIFS(季度经营税费!$D$65:$DT$65,季度经营税费!$D$6:$DT$6,10),SUMIFS(季度经营税费!$D$64:$DT$64,季度经营税费!$D$6:$DT$6,10)),0) -> 0 | O16: =IF(11<=核心参数输入!$B$9,IF(核心参数输入!$B$64=1,SUMIFS(季度经营税费!$D$65:$DT$65,季度经营税费!$D$6:$DT$6,11),SUMIFS(季度经营税费!$D$64:$DT$64,季度经营税费!$D$6:$DT$6,11)),0) -> 0 | P16: =IF(12<=核心参数输入!$B$9,IF(核心参数输入!$B$64=1,SUMIFS(季度经营税费!$D$65:$DT$65,季度经营税费!$D$6:$DT$6,12),SUMIFS(季度经营税费!$D$64:$DT$64,季度经营税费!$D$6:$DT$6,12)),0) -> 0 | Q16: =IF(13<=核心参数输入!$B$9,IF(核心参数输入!$B$64=1,SUMIFS(季度经营税费!$D$65:$DT$65,季度经营税费!$D$6:$DT$6,13),SUMIFS(季度经营税费!$D$64:$DT$64,季度经营税费!$D$6:$DT$6,13)),0) -> 0 | R16: =IF(14<=核心参数输入!$B$9,IF(核心参数输入!$B$64=1,SUMIFS(季度经营税费!$D$65:$DT$65,季度经营税费!$D$6:$DT$6,14),SUMIFS(季度经营税费!$D$64:$DT$64,季度经营税费!$D$6:$DT$6,14)),0) -> 28.992673 | S16: =IF(15<=核心参数输入!$B$9,IF(核心参数输入!$B$64=1,SUMIFS(季度经营税费!$D$65:$DT$65,季度经营税费!$D$6:$DT$6,15),SUMIFS(季度经营税费!$D$64:$DT$64,季度经营税费!$D$6:$DT$6,15)),0) -> 71.75973 | T16: =IF(16<=核心参数输入!$B$9,IF(核心参数输入!$B$64=1,SUMIFS(季度经营税费!$D$65:$DT$65,季度经营税费!$D$6:$DT$6,16),SUMIFS(季度经营税费!$D$64:$DT$64,季度经营税费!$D$6:$DT$6,16)),0) -> 76.24377 | U16: =IF(17<=核心参数输入!$B$9,IF(核心参数输入!$B$64=1,SUMIFS(季度经营税费!$D$65:$DT$65,季度经营税费!$D$6:$DT$6,17),SUMIFS(季度经营税费!$D$64:$DT$64,季度经营税费!$D$6:$DT$6,17)),0) -> 80.785745 | V16: =IF(18<=核心参数输入!$B$9,IF(核心参数输入!$B$64=1,SUMIFS(季度经营税费!$D$65:$DT$65,季度经营税费!$D$6:$DT$6,18),SUMIFS(季度经营税费!$D$64:$DT$64,季度经营税费!$D$6:$DT$6,18)),0) -> 85.386338 | W16: =IF(19<=核心参数输入!$B$9,IF(核心参数输入!$B$64=1,SUMIFS(季度经营税费!$D$65:$DT$65,季度经营税费!$D$6:$DT$6,19),SUMIFS(季度经营税费!$D$64:$DT$64,季度经营税费!$D$6:$DT$6,19)),0) -> 90.046238 | X16: =IF(20<=核心参数输入!$B$9,IF(核心参数输入!$B$64=1,SUMIFS(季度经营税费!$D$65:$DT$65,季度经营税费!$D$6:$DT$6,20),SUMIFS(季度经营税费!$D$64:$DT$64,季度经营税费!$D$6:$DT$6,20)),0) -> 94.76614 | Y16: =IF(21<=核心参数输入!$B$9,IF(核心参数输入!$B$64=1,SUMIFS(季度经营税费!$D$65:$DT$65,季度经营税费!$D$6:$DT$6,21),SUMIFS(季度经营税费!$D$64:$DT$64,季度经营税费!$D$6:$DT$6,21)),0) -> 0 | Z16: =IF(22<=核心参数输入!$B$9,IF(核心参数输入!$B$64=1,SUMIFS(季度经营税费!$D$65:$DT$65,季度经营税费!$D$6:$DT$6,22),SUMIFS(季度经营税费!$D$64:$DT$64,季度经营税费!$D$6:$DT$6,22)),0) -> 0 | AA16: =IF(23<=核心参数输入!$B$9,IF(核心参数输入!$B$64=1,SUMIFS(季度经营税费!$D$65:$DT$65,季度经营税费!$D$6:$DT$6,23),SUMIFS(季度经营税费!$D$64:$DT$64,季度经营税费!$D$6:$DT$6,23)),0) -> 0 | AB16: =IF(24<=核心参数输入!$B$9,IF(核心参数输入!$B$64=1,SUMIFS(季度经营税费!$D$65:$DT$65,季度经营税费!$D$6:$DT$6,24),SUMIFS(季度经营税费!$D$64:$DT$64,季度经营税费!$D$6:$DT$6,24)),0) -> 0 | AC16: =IF(25<=核心参数输入!$B$9,IF(核心参数输入!$B$64=1,SUMIFS(季度经营税费!$D$65:$DT$65,季度经营税费!$D$6:$DT$6,25),SUMIFS(季度经营税费!$D$64:$DT$64,季度经营税费!$D$6:$DT$6,25)),0) -> 0 | AD16: =IF(26<=核心参数输入!$B$9,IF(核心参数输入!$B$64=1,SUMIFS(季度经营税费!$D$65:$DT$65,季度经营税费!$D$6:$DT$6,26),SUMIFS(季度经营税费!$D$64:$DT$64,季度经营税费!$D$6:$DT$6,26)),0) -> 0 | AE16: =IF(27<=核心参数输入!$B$9,IF(核心参数输入!$B$64=1,SUMIFS(季度经营税费!$D$65:$DT$65,季度经营税费!$D$6:$DT$6,27),SUMIFS(季度经营税费!$D$64:$DT$64,季度经营税费!$D$6:$DT$6,27)),0) -> 0 | AF16: =IF(28<=核心参数输入!$B$9,IF(核心参数输入!$B$64=1,SUMIFS(季度经营税费!$D$65:$DT$65,季度经营税费!$D$6:$DT$6,28),SUMIFS(季度经营税费!$D$64:$DT$64,季度经营税费!$D$6:$DT$6,28)),0) -> 0 | AG16: =IF(29<=核心参数输入!$B$9,IF(核心参数输入!$B$64=1,SUMIFS(季度经营税费!$D$65:$DT$65,季度经营税费!$D$6:$DT$6,29),SUMIFS(季度经营税费!$D$64:$DT$64,季度经营税费!$D$6:$DT$6,29)),0) -> 0 | AH16: =IF(30<=核心参数输入!$B$9,IF(核心参数输入!$B$64=1,SUMIFS(季度经营税费!$D$65:$DT$65,季度经营税费!$D$6:$DT$6,30),SUMIFS(季度经营税费!$D$64:$DT$64,季度经营税费!$D$6:$DT$6,30)),0) -> 0
A17: 净利润 | B17: 万元 | D17: =IF(0<=核心参数输入!$B$9,IF(核心参数输入!$B$64=1,SUMIFS(季度经营税费!$D$67:$DT$67,季度经营税费!$D$6:$DT$6,0),SUMIFS(季度经营税费!$D$66:$DT$66,季度经营税费!$D$6:$DT$6,0)),0) -> 0 | E17: =IF(1<=核心参数输入!$B$9,IF(核心参数输入!$B$64=1,SUMIFS(季度经营税费!$D$67:$DT$67,季度经营税费!$D$6:$DT$6,1),SUMIFS(季度经营税费!$D$66:$DT$66,季度经营税费!$D$6:$DT$6,1)),0) -> 0 | F17: =IF(2<=核心参数输入!$B$9,IF(核心参数输入!$B$64=1,SUMIFS(季度经营税费!$D$67:$DT$67,季度经营税费!$D$6:$DT$6,2),SUMIFS(季度经营税费!$D$66:$DT$66,季度经营税费!$D$6:$DT$6,2)),0) -> 0 | G17: =IF(3<=核心参数输入!$B$9,IF(核心参数输入!$B$64=1,SUMIFS(季度经营税费!$D$67:$DT$67,季度经营税费!$D$6:$DT$6,3),SUMIFS(季度经营税费!$D$66:$DT$66,季度经营税费!$D$6:$DT$6,3)),0) -> 0 | H17: =IF(4<=核心参数输入!$B$9,IF(核心参数输入!$B$64=1,SUMIFS(季度经营税费!$D$67:$DT$67,季度经营税费!$D$6:$DT$6,4),SUMIFS(季度经营税费!$D$66:$DT$66,季度经营税费!$D$6:$DT$6,4)),0) -> 186.65291 | I17: =IF(5<=核心参数输入!$B$9,IF(核心参数输入!$B$64=1,SUMIFS(季度经营税费!$D$67:$DT$67,季度经营税费!$D$6:$DT$6,5),SUMIFS(季度经营税费!$D$66:$DT$66,季度经营税费!$D$6:$DT$6,5)),0) -> 1454.6817 | J17: =IF(6<=核心参数输入!$B$9,IF(核心参数输入!$B$64=1,SUMIFS(季度经营税费!$D$67:$DT$67,季度经营税费!$D$6:$DT$6,6),SUMIFS(季度经营税费!$D$66:$DT$66,季度经营税费!$D$6:$DT$6,6)),0) -> 1187.253 | K17: =IF(7<=核心参数输入!$B$9,IF(核心参数输入!$B$64=1,SUMIFS(季度经营税费!$D$67:$DT$67,季度经营税费!$D$6:$DT$6,7),SUMIFS(季度经营税费!$D$66:$DT$66,季度经营税费!$D$6:$DT$6,7)),0) -> -613.76954 | L17: =IF(8<=核心参数输入!$B$9,IF(核心参数输入!$B$64=1,SUMIFS(季度经营税费!$D$67:$DT$67,季度经营税费!$D$6:$DT$6,8),SUMIFS(季度经营税费!$D$66:$DT$66,季度经营税费!$D$6:$DT$6,8)),0) -> -352.39783 | M17: =IF(9<=核心参数输入!$B$9,IF(核心参数输入!$B$64=1,SUMIFS(季度经营税费!$D$67:$DT$67,季度经营税费!$D$6:$DT$6,9),SUMIFS(季度经营税费!$D$66:$DT$66,季度经营税费!$D$6:$DT$6,9)),0) -> -153.36111 | N17: =IF(10<=核心参数输入!$B$9,IF(核心参数输入!$B$64=1,SUMIFS(季度经营税费!$D$67:$DT$67,季度经营税费!$D$6:$DT$6,10),SUMIFS(季度经营税费!$D$66:$DT$66,季度经营税费!$D$6:$DT$6,10)),0) -> 43.240494 | O17: =IF(11<=核心参数输入!$B$9,IF(核心参数输入!$B$64=1,SUMIFS(季度经营税费!$D$67:$DT$67,季度经营税费!$D$6:$DT$6,11),SUMIFS(季度经营税费!$D$66:$DT$66,季度经营税费!$D$6:$DT$6,11)),0) -> 217.558 | P17: =IF(12<=核心参数输入!$B$9,IF(核心参数输入!$B$64=1,SUMIFS(季度经营税费!$D$67:$DT$67,季度经营税费!$D$6:$DT$6,12),SUMIFS(季度经营税费!$D$66:$DT$66,季度经营税费!$D$6:$DT$6,12)),0) -> 234.59397 | Q17: =IF(13<=核心参数输入!$B$9,IF(核心参数输入!$B$64=1,SUMIFS(季度经营税费!$D$67:$DT$67,季度经营税费!$D$6:$DT$6,13),SUMIFS(季度经营税费!$D$66:$DT$66,季度经营税费!$D$6:$DT$6,13)),0) -> 251.85103 | R17: =IF(14<=核心参数输入!$B$9,IF(核心参数输入!$B$64=1,SUMIFS(季度经营税费!$D$67:$DT$67,季度经营税费!$D$6:$DT$6,14),SUMIFS(季度经营税费!$D$66:$DT$66,季度经营税费!$D$6:$DT$6,14)),0) -> 240.33912 | S17: =IF(15<=核心参数输入!$B$9,IF(核心参数输入!$B$64=1,SUMIFS(季度经营税费!$D$67:$DT$67,季度经营税费!$D$6:$DT$6,15),SUMIFS(季度经营税费!$D$66:$DT$66,季度经营税费!$D$6:$DT$6,15)),0) -> 215.27919 | T17: =IF(16<=核心参数输入!$B$9,IF(核心参数输入!$B$64=1,SUMIFS(季度经营税费!$D$67:$DT$67,季度经营税费!$D$6:$DT$6,16),SUMIFS(季度经营税费!$D$66:$DT$66,季度经营税费!$D$6:$DT$6,16)),0) -> 228.73131 | U17: =IF(17<=核心参数输入!$B$9,IF(核心参数输入!$B$64=1,SUMIFS(季度经营税费!$D$67:$DT$67,季度经营税费!$D$6:$DT$6,17),SUMIFS(季度经营税费!$D$66:$DT$66,季度经营税费!$D$6:$DT$6,17)),0) -> 242.35723 | V17: =IF(18<=核心参数输入!$B$9,IF(核心参数输入!$B$64=1,SUMIFS(季度经营税费!$D$67:$DT$67,季度经营税费!$D$6:$DT$6,18),SUMIFS(季度经营税费!$D$66:$DT$66,季度经营税费!$D$6:$DT$6,18)),0) -> 256.15901 | W17: =IF(19<=核心参数输入!$B$9,IF(核心参数输入!$B$64=1,SUMIFS(季度经营税费!$D$67:$DT$67,季度经营税费!$D$6:$DT$6,19),SUMIFS(季度经营税费!$D$66:$DT$66,季度经营税费!$D$6:$DT$6,19)),0) -> 270.13871 | X17: =IF(20<=核心参数输入!$B$9,IF(核心参数输入!$B$64=1,SUMIFS(季度经营税费!$D$67:$DT$67,季度经营税费!$D$6:$DT$6,20),SUMIFS(季度经营税费!$D$66:$DT$66,季度经营税费!$D$6:$DT$6,20)),0) -> 284.29842 | Y17: =IF(21<=核心参数输入!$B$9,IF(核心参数输入!$B$64=1,SUMIFS(季度经营税费!$D$67:$DT$67,季度经营税费!$D$6:$DT$6,21),SUMIFS(季度经营税费!$D$66:$DT$66,季度经营税费!$D$6:$DT$6,21)),0) -> 0 | Z17: =IF(22<=核心参数输入!$B$9,IF(核心参数输入!$B$64=1,SUMIFS(季度经营税费!$D$67:$DT$67,季度经营税费!$D$6:$DT$6,22),SUMIFS(季度经营税费!$D$66:$DT$66,季度经营税费!$D$6:$DT$6,22)),0) -> 0 | AA17: =IF(23<=核心参数输入!$B$9,IF(核心参数输入!$B$64=1,SUMIFS(季度经营税费!$D$67:$DT$67,季度经营税费!$D$6:$DT$6,23),SUMIFS(季度经营税费!$D$66:$DT$66,季度经营税费!$D$6:$DT$6,23)),0) -> 0 | AB17: =IF(24<=核心参数输入!$B$9,IF(核心参数输入!$B$64=1,SUMIFS(季度经营税费!$D$67:$DT$67,季度经营税费!$D$6:$DT$6,24),SUMIFS(季度经营税费!$D$66:$DT$66,季度经营税费!$D$6:$DT$6,24)),0) -> 0 | AC17: =IF(25<=核心参数输入!$B$9,IF(核心参数输入!$B$64=1,SUMIFS(季度经营税费!$D$67:$DT$67,季度经营税费!$D$6:$DT$6,25),SUMIFS(季度经营税费!$D$66:$DT$66,季度经营税费!$D$6:$DT$6,25)),0) -> 0 | AD17: =IF(26<=核心参数输入!$B$9,IF(核心参数输入!$B$64=1,SUMIFS(季度经营税费!$D$67:$DT$67,季度经营税费!$D$6:$DT$6,26),SUMIFS(季度经营税费!$D$66:$DT$66,季度经营税费!$D$6:$DT$6,26)),0) -> 0 | AE17: =IF(27<=核心参数输入!$B$9,IF(核心参数输入!$B$64=1,SUMIFS(季度经营税费!$D$67:$DT$67,季度经营税费!$D$6:$DT$6,27),SUMIFS(季度经营税费!$D$66:$DT$66,季度经营税费!$D$6:$DT$6,27)),0) -> 0 | AF17: =IF(28<=核心参数输入!$B$9,IF(核心参数输入!$B$64=1,SUMIFS(季度经营税费!$D$67:$DT$67,季度经营税费!$D$6:$DT$6,28),SUMIFS(季度经营税费!$D$66:$DT$66,季度经营税费!$D$6:$DT$6,28)),0) -> 0 | AG17: =IF(29<=核心参数输入!$B$9,IF(核心参数输入!$B$64=1,SUMIFS(季度经营税费!$D$67:$DT$67,季度经营税费!$D$6:$DT$6,29),SUMIFS(季度经营税费!$D$66:$DT$66,季度经营税费!$D$6:$DT$6,29)),0) -> 0 | AH17: =IF(30<=核心参数输入!$B$9,IF(核心参数输入!$B$64=1,SUMIFS(季度经营税费!$D$67:$DT$67,季度经营税费!$D$6:$DT$6,30),SUMIFS(季度经营税费!$D$66:$DT$66,季度经营税费!$D$6:$DT$6,30)),0) -> 0
A18: 投资支付含资本化融资费用 | B18: 万元 | D18: =IF(0<=核心参数输入!$B$9,SUMIFS(季度投融资!$D$48:$DT$48,季度投融资!$D$6:$DT$6,0),0) -> 8000 | E18: =IF(1<=核心参数输入!$B$9,SUMIFS(季度投融资!$D$48:$DT$48,季度投融资!$D$6:$DT$6,1),0) -> 12084.188 | F18: =IF(2<=核心参数输入!$B$9,SUMIFS(季度投融资!$D$48:$DT$48,季度投融资!$D$6:$DT$6,2),0) -> 21798 | G18: =IF(3<=核心参数输入!$B$9,SUMIFS(季度投融资!$D$48:$DT$48,季度投融资!$D$6:$DT$6,3),0) -> 16947 | H18: =IF(4<=核心参数输入!$B$9,SUMIFS(季度投融资!$D$48:$DT$48,季度投融资!$D$6:$DT$6,4),0) -> 500 | I18: =IF(5<=核心参数输入!$B$9,SUMIFS(季度投融资!$D$48:$DT$48,季度投融资!$D$6:$DT$6,5),0) -> 0 | J18: =IF(6<=核心参数输入!$B$9,SUMIFS(季度投融资!$D$48:$DT$48,季度投融资!$D$6:$DT$6,6),0) -> 0 | K18: =IF(7<=核心参数输入!$B$9,SUMIFS(季度投融资!$D$48:$DT$48,季度投融资!$D$6:$DT$6,7),0) -> 0 | L18: =IF(8<=核心参数输入!$B$9,SUMIFS(季度投融资!$D$48:$DT$48,季度投融资!$D$6:$DT$6,8),0) -> 0 | M18: =IF(9<=核心参数输入!$B$9,SUMIFS(季度投融资!$D$48:$DT$48,季度投融资!$D$6:$DT$6,9),0) -> 0 | N18: =IF(10<=核心参数输入!$B$9,SUMIFS(季度投融资!$D$48:$DT$48,季度投融资!$D$6:$DT$6,10),0) -> 0 | O18: =IF(11<=核心参数输入!$B$9,SUMIFS(季度投融资!$D$48:$DT$48,季度投融资!$D$6:$DT$6,11),0) -> 0 | P18: =IF(12<=核心参数输入!$B$9,SUMIFS(季度投融资!$D$48:$DT$48,季度投融资!$D$6:$DT$6,12),0) -> 0 | Q18: =IF(13<=核心参数输入!$B$9,SUMIFS(季度投融资!$D$48:$DT$48,季度投融资!$D$6:$DT$6,13),0) -> 0 | R18: =IF(14<=核心参数输入!$B$9,SUMIFS(季度投融资!$D$48:$DT$48,季度投融资!$D$6:$DT$6,14),0) -> 0 | S18: =IF(15<=核心参数输入!$B$9,SUMIFS(季度投融资!$D$48:$DT$48,季度投融资!$D$6:$DT$6,15),0) -> 0 | T18: =IF(16<=核心参数输入!$B$9,SUMIFS(季度投融资!$D$48:$DT$48,季度投融资!$D$6:$DT$6,16),0) -> 0 | U18: =IF(17<=核心参数输入!$B$9,SUMIFS(季度投融资!$D$48:$DT$48,季度投融资!$D$6:$DT$6,17),0) -> 0 | V18: =IF(18<=核心参数输入!$B$9,SUMIFS(季度投融资!$D$48:$DT$48,季度投融资!$D$6:$DT$6,18),0) -> 0 | W18: =IF(19<=核心参数输入!$B$9,SUMIFS(季度投融资!$D$48:$DT$48,季度投融资!$D$6:$DT$6,19),0) -> 0 | X18: =IF(20<=核心参数输入!$B$9,SUMIFS(季度投融资!$D$48:$DT$48,季度投融资!$D$6:$DT$6,20),0) -> 0 | Y18: =IF(21<=核心参数输入!$B$9,SUMIFS(季度投融资!$D$48:$DT$48,季度投融资!$D$6:$DT$6,21),0) -> 0 | Z18: =IF(22<=核心参数输入!$B$9,SUMIFS(季度投融资!$D$48:$DT$48,季度投融资!$D$6:$DT$6,22),0) -> 0 | AA18: =IF(23<=核心参数输入!$B$9,SUMIFS(季度投融资!$D$48:$DT$48,季度投融资!$D$6:$DT$6,23),0) -> 0 | AB18: =IF(24<=核心参数输入!$B$9,SUMIFS(季度投融资!$D$48:$DT$48,季度投融资!$D$6:$DT$6,24),0) -> 0 | AC18: =IF(25<=核心参数输入!$B$9,SUMIFS(季度投融资!$D$48:$DT$48,季度投融资!$D$6:$DT$6,25),0) -> 0 | AD18: =IF(26<=核心参数输入!$B$9,SUMIFS(季度投融资!$D$48:$DT$48,季度投融资!$D$6:$DT$6,26),0) -> 0 | AE18: =IF(27<=核心参数输入!$B$9,SUMIFS(季度投融资!$D$48:$DT$48,季度投融资!$D$6:$DT$6,27),0) -> 0 | AF18: =IF(28<=核心参数输入!$B$9,SUMIFS(季度投融资!$D$48:$DT$48,季度投融资!$D$6:$DT$6,28),0) -> 0 | AG18: =IF(29<=核心参数输入!$B$9,SUMIFS(季度投融资!$D$48:$DT$48,季度投融资!$D$6:$DT$6,29),0) -> 0 | AH18: =IF(30<=核心参数输入!$B$9,SUMIFS(季度投融资!$D$48:$DT$48,季度投融资!$D$6:$DT$6,30),0) -> 0
A19: 贷款提款 | B19: 万元 | D19: =IF(0<=核心参数输入!$B$9,SUMIFS(季度投融资!$D$39:$DT$39,季度投融资!$D$6:$DT$6,0),0) -> 0 | E19: =IF(1<=核心参数输入!$B$9,SUMIFS(季度投融资!$D$39:$DT$39,季度投融资!$D$6:$DT$6,1),0) -> 6750 | F19: =IF(2<=核心参数输入!$B$9,SUMIFS(季度投融资!$D$39:$DT$39,季度投融资!$D$6:$DT$6,2),0) -> 12000 | G19: =IF(3<=核心参数输入!$B$9,SUMIFS(季度投融资!$D$39:$DT$39,季度投融资!$D$6:$DT$6,3),0) -> 9000 | H19: =IF(4<=核心参数输入!$B$9,SUMIFS(季度投融资!$D$39:$DT$39,季度投融资!$D$6:$DT$6,4),0) -> 0 | I19: =IF(5<=核心参数输入!$B$9,SUMIFS(季度投融资!$D$39:$DT$39,季度投融资!$D$6:$DT$6,5),0) -> 0 | J19: =IF(6<=核心参数输入!$B$9,SUMIFS(季度投融资!$D$39:$DT$39,季度投融资!$D$6:$DT$6,6),0) -> 0 | K19: =IF(7<=核心参数输入!$B$9,SUMIFS(季度投融资!$D$39:$DT$39,季度投融资!$D$6:$DT$6,7),0) -> 0 | L19: =IF(8<=核心参数输入!$B$9,SUMIFS(季度投融资!$D$39:$DT$39,季度投融资!$D$6:$DT$6,8),0) -> 0 | M19: =IF(9<=核心参数输入!$B$9,SUMIFS(季度投融资!$D$39:$DT$39,季度投融资!$D$6:$DT$6,9),0) -> 0 | N19: =IF(10<=核心参数输入!$B$9,SUMIFS(季度投融资!$D$39:$DT$39,季度投融资!$D$6:$DT$6,10),0) -> 0 | O19: =IF(11<=核心参数输入!$B$9,SUMIFS(季度投融资!$D$39:$DT$39,季度投融资!$D$6:$DT$6,11),0) -> 0 | P19: =IF(12<=核心参数输入!$B$9,SUMIFS(季度投融资!$D$39:$DT$39,季度投融资!$D$6:$DT$6,12),0) -> 0 | Q19: =IF(13<=核心参数输入!$B$9,SUMIFS(季度投融资!$D$39:$DT$39,季度投融资!$D$6:$DT$6,13),0) -> 0 | R19: =IF(14<=核心参数输入!$B$9,SUMIFS(季度投融资!$D$39:$DT$39,季度投融资!$D$6:$DT$6,14),0) -> 0 | S19: =IF(15<=核心参数输入!$B$9,SUMIFS(季度投融资!$D$39:$DT$39,季度投融资!$D$6:$DT$6,15),0) -> 0 | T19: =IF(16<=核心参数输入!$B$9,SUMIFS(季度投融资!$D$39:$DT$39,季度投融资!$D$6:$DT$6,16),0) -> 0 | U19: =IF(17<=核心参数输入!$B$9,SUMIFS(季度投融资!$D$39:$DT$39,季度投融资!$D$6:$DT$6,17),0) -> 0 | V19: =IF(18<=核心参数输入!$B$9,SUMIFS(季度投融资!$D$39:$DT$39,季度投融资!$D$6:$DT$6,18),0) -> 0 | W19: =IF(19<=核心参数输入!$B$9,SUMIFS(季度投融资!$D$39:$DT$39,季度投融资!$D$6:$DT$6,19),0) -> 0 | X19: =IF(20<=核心参数输入!$B$9,SUMIFS(季度投融资!$D$39:$DT$39,季度投融资!$D$6:$DT$6,20),0) -> 0 | Y19: =IF(21<=核心参数输入!$B$9,SUMIFS(季度投融资!$D$39:$DT$39,季度投融资!$D$6:$DT$6,21),0) -> 0 | Z19: =IF(22<=核心参数输入!$B$9,SUMIFS(季度投融资!$D$39:$DT$39,季度投融资!$D$6:$DT$6,22),0) -> 0 | AA19: =IF(23<=核心参数输入!$B$9,SUMIFS(季度投融资!$D$39:$DT$39,季度投融资!$D$6:$DT$6,23),0) -> 0 | AB19: =IF(24<=核心参数输入!$B$9,SUMIFS(季度投融资!$D$39:$DT$39,季度投融资!$D$6:$DT$6,24),0) -> 0 | AC19: =IF(25<=核心参数输入!$B$9,SUMIFS(季度投融资!$D$39:$DT$39,季度投融资!$D$6:$DT$6,25),0) -> 0 | AD19: =IF(26<=核心参数输入!$B$9,SUMIFS(季度投融资!$D$39:$DT$39,季度投融资!$D$6:$DT$6,26),0) -> 0 | AE19: =IF(27<=核心参数输入!$B$9,SUMIFS(季度投融资!$D$39:$DT$39,季度投融资!$D$6:$DT$6,27),0) -> 0 | AF19: =IF(28<=核心参数输入!$B$9,SUMIFS(季度投融资!$D$39:$DT$39,季度投融资!$D$6:$DT$6,28),0) -> 0 | AG19: =IF(29<=核心参数输入!$B$9,SUMIFS(季度投融资!$D$39:$DT$39,季度投融资!$D$6:$DT$6,29),0) -> 0 | AH19: =IF(30<=核心参数输入!$B$9,SUMIFS(季度投融资!$D$39:$DT$39,季度投融资!$D$6:$DT$6,30),0) -> 0
